Workbook
Name _1_0CUADRO_N__4.: [1]Afiliados!#REF!
Name _2_0GRÁFICO_N_10.2: [1]Afiliados!#REF!
Name _COL1: #REF!
Name _COL2: #REF!
Name _COL3: #REF!
Name _COL4: #REF!
Name _COL5: #REF!
Name _COL6: #REF!
Name _COL7: #REF!
Name _COL8: #REF!
Name _COL9: #REF!
Name A: #REF!
Name A_impresión_IM: #REF!
Name adf: '[3]dep pre'!#REF!
Name af: '[4]sist. financiero_san Luis'!#REF!
Name AMPO5: "Gráfico 8"
Name asd: '[5]graf 1'!$A$3:$C$28
Name asdf: '[3]dep pre'!#REF!
Name Base_datos_IM: '[4]sist. financiero_san Luis'!#REF!
Name BORRA_CUADROS: [7]!BORRA_CUADROS
Name cacho: [8]GRAFPROM!#REF!
Name carajo: #REF!
Name Cobertura_del_Plan_Jefes_as_de_Hogar__por_municipio___Junio_2002: #REF!
Name Criterios_IM: '[4]sist. financiero_san Luis'!#REF!
Name CUADRO_10.3.1: '[9]fondo promedio'!$A$36:$L$74
Name CUADRO_N__4.1.3: #REF!
Name culo: '[5]graf 1'!$A$1:$IV$2
Name datos: #REF!
Name dobleclick: #REF!
Name Extracción_IM: '[2]dep pre'!#REF!
Name FECHA: #REF!
Name feo: #REF!
Name GRÁFICO_10.3.1.: '[9]GRÁFICO DE FONDO POR AFILIADO'!$A$3:$H$35
Name GRÁFICO_10.3.2: '[9]GRÁFICO DE FONDO POR AFILIADO'!$A$36:$H$68
Name GRÁFICO_10.3.3: '[9]GRÁFICO DE FONDO POR AFILIADO'!$A$69:$H$101
Name GRÁFICO_10.3.4.: '[9]GRÁFICO DE FONDO POR AFILIADO'!$A$103:$H$135
Name GRÁFICO_N_10.2.4.: #REF!
Name hp9pk: '[4]sist. financiero_san Luis'!#REF!
Name iupg: '[3]dep pre'!#REF!
Name MUJERES: [10]Mujeres!$B$77:$V$109
Name npppppnj: '[3]dep pre'!#REF!
Name PIJIS: #REF!
Name Print_Area_MI: #REF!
Name PRINT_TITLES_MI: #REF!
Name promgraf: [8]GRAFPROM!#REF!
Name puto: #REF!
Name SOPA: #REF!
Name sopapita: #REF!
Name Títulos_a_imprimir_IM: #REF!
Name TRANSFERENCIA: [7]!TRANSFERENCIA
Name v: #REF!
Name VARONES: [10]Varones!$B$77:$V$109
Name YO: [8]GRAFPROM!#REF!

Sheet Empleo Población
A1: Mercado de trabajo - EPH
A2: Población ocupada según sexo, grupos de edad, posición en el hogar, nivel educativo, categoría ocupacional, rama de actividad, tamaño del establecimiento, calificación de la tarea, horas trabajadas y quintil de ingreso per cápita familiar
A3: Total aglomerados relevados (en miles de personas)
B4: 3° Trim 03 | C4: 4° Trim 03 | D4: 1° Trim 04 | E4: 2° Trim 04 | F4: 3° Trim 04 | G4: 4° Trim 04 | H4: 1° Trim 05 | I4: 2° Trim 05 | J4: 3° Trim 05 | K4: 4° Trim 05 | L4: 1° Trim 06 | M4: 2° Trim 06 | N4: 3° Trim 06 | O4: 4° Trim 06 | P4: 1° Trim 07 | Q4: 2° Trim 07 1 | R4: 3° Trim 07 1 2 | S4: 4° Trim 07 1 | T4: 1° Trim 08 1 | U4: 2° Trim 08 1 | V4: 3° Trim 08 1 | W4: 4° Trim 08 1 | X4: 1° Trim 09 1 | Y4: 2° Trim 09 1 | Z4: 3° Trim 09 1 | AA4: 4° Trim 09 1 | AB4: 1° Trim 10 1 | AC4: 2° Trim 10 1 | AD4: 3° Trim 10 1 | AE4: 4° Trim 10 1 | AF4: 1° Trim 11 1 | AG4: 2° Trim 11 1 | AH4: 3° Trim 11 1 | AI4: 4° Trim 11 1 | AJ4: 1° Trim 12 1 | AK4: 2° Trim 12 1 | AL4: 3° Trim 12 1 | AM4: 4° Trim 12 1 | AN4: 1° Trim 13 1 | AO4: 2° Trim 13 1 | AP4: 3° Trim 13 1 | AQ4: 4° Trim 13 1 | AR4: 1° Trim 14 13 | AS4: 2° Trim 14 1 | AT4: 3° Trim 14 1 | AU4: 4° Trim 14 1 | AV4: 1° Trim 15 1 | AW4: 2° Trim 15 1 | AX4: 3° Trim 15 1 4 | AY4: 4° Trim 15 1 4 | AZ4: 1° Trim 16 4 | BA4: 2° Trim 16 | BB4: 3° Trim 16 | BC4: 4° Trim 16 | BD4: 1° Trim 17 | BE4: 2° Trim 17 | BF4: 3° Trim 17 | BG4: 4° Trim 17 | BH4: 1° Trim 18 | BI4: 2° Trim 18 | BJ4: 3° Trim 18 | BK4: 4° Trim 18 | BL4: 1° Trim 19 | BM4: 2° Trim 19 | BN4: 3° Trim 19 | BO4: 4° Trim 19 | BP4: 1° Trim 20 | BQ4: 2° Trim 20 | BR4: 3° Trim 20 | BS4: 4° Trim 20
A5: Total | B5: 9023.3103 | C5: 9250.3634 | D5: 9258.5241 | E5: 9365.311 | F5: 9556.035 | G5: 9670.535 | H5: 9520.224 | I5: 9636.5742 | J5: 9911.3403 | K5: 10014.904 | L5: 9900.267 | M5: 10158.198 | N5: 10160.374 | O5: 10297.908 | P5: 10242.187 | Q5: 10387.811 | R5: … | S5: 10374.442 | T5: 10364.329 | U5: 10438 | V5: 10426.222 | W5: 10668.664 | X5: 10648.121 | Y5: 10591.756 | Z5: 10526.053 | AA5: 10690.039 | AB5: 10684.617 | AC5: 10770.537 | AD5: 10809.292 | AE5: 10827.061 | AF5: 10838.575 | AG5: 11096.689 | AH5: 11171.289 | AI5: 11105.987 | AJ5: 10960.882 | AK5: 11137.764 | AL5: 11285.731 | AM5: 11269.876 | AN5: 11074.706 | AO5: 11336.763 | AP5: 11330.52 | AQ5: 11304.58 | AR5: 11095.742 | AS5: 11010.906 | AT5: 11022.403 | AU5: 11252.957 | AV5: 11102.217 | AW5: 11151.034 | AX5: … | AY5: … | AZ5: … | BA5: 11472.399 | BB5: 11614.218 | BC5: 11596.75 | BD5: 11460.822 | BE5: 11511.048 | BF5: 11810.801 | BG5: 12011.328 | BH5: 11866.382 | BI5: 11757.599 | BJ5: 11937.88 | BK5: 11908.972 | BL5: 11947.317 | BM5: 12073.393 | BN5: 12109.032 | BO5: 12240.119 | BP5: 12045.2 | BQ5: 9546.08 | BR5: 10657.849 | BS5: 11523.649
A6: Sexo
A7: Varones | B7: 5135.2389 | C7: 5394.0338 | D7: 5403.0579 | E7: 5383.7909 | F7: 5548.9665 | G7: 5610.593 | H7: 5560.3442 | I7: 5609.4134 | J7: 5789.6793 | K7: 5784.6284 | L7: 5745.7995 | M7: 5883.2255 | N7: 5898.8803 | O7: 5971.0729 | P7: 5990.551 | Q7: 6057.1517 | R7: … | S7: 6102.6723 | T7: 6044.7334 | U7: 6083.6736 | V7: 6126.3386 | W7: 6202.0993 | X7: 6144.8857 | Y7: 6103.3295 | Z7: 6079.6275 | AA7: 6173.5961 | AB7: 6234.759 | AC7: 6275.9027 | AD7: 6278.7673 | AE7: 6370.0104 | AF7: 6423.2775 | AG7: 6480.1128 | AH7: 6528.5025 | AI7: 6544.2299 | AJ7: 6380.9726 | AK7: 6433.338 | AL7: 6628.3901 | AM7: 6651.3486 | AN7: 6495.2501 | AO7: 6617.6713 | AP7: 6655.0342 | AQ7: 6572.7013 | AR7: 6504.1078 | AS7: 6449.8318 | AT7: 6427.321 | AU7: 6492.6719 | AV7: 6479.793 | AW7: 6552.2666 | AX7: … | AY7: … | AZ7: … | BA7: 6627.7188 | BB7: 6602.8005 | BC7: 6650.0018 | BD7: 6638.3581 | BE7: 6569.2255 | BF7: 6752.571 | BG7: 6883.9742 | BH7: 6745.8991 | BI7: 6629.8551 | BJ7: 6677.727 | BK7: 6634.676 | BL7: 6791.666 | BM7: 6769.037 | BN7: 6893.2304 | BO7: 6857.376 | BP7: 6720.605 | BQ7: 5379.639 | BR7: 6041.602 | BS7: 6478.577
A8: Mujeres | B8: 3888.0714 | C8: 3856.3296 | D8: 3855.4662 | E8: 3981.5201 | F8: 4007.0685 | G8: 4059.942 | H8: 3959.8798 | I8: 4027.1608 | J8: 4121.661 | K8: 4230.2756 | L8: 4154.4675 | M8: 4274.9721 | N8: 4261.4942 | O8: 4326.8351 | P8: 4251.6356 | Q8: 4330.6589 | R8: … | S8: 4271.7696 | T8: 4319.5953 | U8: 4354.3262 | V8: 4299.8839 | W8: 4466.5651 | X8: 4503.235 | Y8: 4488.4263 | Z8: 4446.425 | AA8: 4516.4424 | AB8: 4449.8583 | AC8: 4494.6345 | AD8: 4530.5245 | AE8: 4457.0508 | AF8: 4415.297 | AG8: 4616.576 | AH8: 4642.7869 | AI8: 4561.7571 | AJ8: 4579.9092 | AK8: 4704.4265 | AL8: 4657.3413 | AM8: 4618.5275 | AN8: 4579.4562 | AO8: 4719.0916 | AP8: 4675.4854 | AQ8: 4731.8791 | AR8: 4591.6342 | AS8: 4561.0745 | AT8: 4595.0821 | AU8: 4760.2846 | AV8: 4622.4237 | AW8: 4598.7678 | AX8: … | AY8: … | AZ8: … | BA8: 4844.6801 | BB8: 5011.4174 | BC8: 4946.7486 | BD8: 4822.4641 | BE8: 4941.8226 | BF8: 5058.2303 | BG8: 5127.3539 | BH8: 5120.4828 | BI8: 5127.744 | BJ8: 5144.297 | BK8: 5158.721 | BL8: 5155.651 | BM8: 5304.356 | BN8: 5215.8019 | BO8: 5382.743 | BP8: 5324.595 | BQ8: 4166.441 | BR8: 4616.247 | BS8: 5045.072
A9: Grupos de edad
A10: Hasta 24 años | B10: 1383.4756 | C10: 1423.0527 | D10: 1449.6653 | E10: 1418.643 | F10: 1454.9737 | G10: 1480.2902 | H10: 1395.6569 | I10: 1428.5174 | J10: 1503.9976 | K10: 1489.3644 | L10: 1458.4175 | M10: 1512.6604 | N10: 1498.7001 | O10: 1557.752 | P10: 1549.8781 | Q10: 1477.2783 | R10: … | S10: 1611.2307 | T10: 1480.1298 | U10: 1488.449 | V10: 1535.7079 | W10: 1574.4632 | X10: 1513.7006 | Y10: 1452.4175 | Z10: 1433.418 | AA10: 1450.1719 | AB10: 1450.7407 | AC10: 1476.6984 | AD10: 1430.1146 | AE10: 1479.6159 | AF10: 1434.3793 | AG10: 1535.3315 | AH10: 1445.6571 | AI10: 1440.8246 | AJ10: 1414.4365 | AK10: 1517.855 | AL10: 1565.9984 | AM10: 1466.1186 | AN10: 1465.0555 | AO10: 1495.3964 | AP10: 1444.3577 | AQ10: 1476.4805 | AR10: 1470.2934 | AS10: 1423.8301 | AT10: 1401.4293 | AU10: 1521.9077 | AV10: 1390.7917 | AW10: 1364.8912 | AX10: … | AY10: … | AZ10: … | BA10: 1374.8625 | BB10: 1390.194 | BC10: 1353.5579 | BD10: 1362.3813 | BE10: 1412.1232 | BF10: 1438.1349 | BG10: 1490.9913 | BH10: 1427.8532 | BI10: 1355.1606 | BJ10: 1357.231 | BK10: 1432.678 | BL10: 1329.231 | BM10: 1318.921 | BN10: 1282.2613 | BO10: 1337.947 | BP10: 1326.04 | BQ10: 788.987 | BR10: 946.807 | BS10: 1240.836
A11: Entre 25 y 34 años | B11: 2311.0995 | C11: 2432.5046 | D11: 2399.5002 | E11: 2487.8013 | F11: 2561.1566 | G11: 2605.7105 | H11: 2505.7408 | I11: 2531.1863 | J11: 2615.8905 | K11: 2716.2275 | L11: 2613.0851 | M11: 2735.3004 | N11: 2808.7662 | O11: 2807.2654 | P11: 2678.4094 | Q11: 2813.7625 | R11: … | S11: 2753.8465 | T11: 2791.8308 | U11: 2792.9358 | V11: 2718.8405 | W11: 2818.6053 | X11: 2802.2898 | Y11: 2890.9893 | Z11: 2848.8555 | AA11: 2865.0664 | AB11: 2947.3856 | AC11: 2944.3965 | AD11: 2983.8329 | AE11: 2944.9497 | AF11: 2907.9047 | AG11: 2990.1659 | AH11: 3004.2115 | AI11: 2958.7401 | AJ11: 2903.8774 | AK11: 2852.9244 | AL11: 2992.0147 | AM11: 3047.8475 | AN11: 2846.8123 | AO11: 2911.5894 | AP11: 2931.3033 | AQ11: 3067.1867 | AR11: 2879.0389 | AS11: 2844.936 | AT11: 2842.1276 | AU11: 2996.3707 | AV11: 2907.0918 | AW11: 2768.0516 | AX11: … | AY11: … | AZ11: … | BA11: 2785.7311 | BB11: 2805.8306 | BC11: 2767.1991 | BD11: 2790.3971 | BE11: 2736.7702 | BF11: 2793.0134 | BG11: 2868.2697 | BH11: 2895.7053 | BI11: 2812.3655 | BJ11: 2832.097 | BK11: 2760.241 | BL11: 2912.429 | BM11: 2930.438 | BN11: 2894.3589 | BO11: 2964.217 | BP11: 2911.603 | BQ11: 2429.005 | BR11: 2736.603 | BS11: 2789.17
A12: Entre 35 y 49 años | B12: 3173.4891 | C12: 3156.5382 | D12: 3190.5329 | E12: 3133.9536 | F12: 3193.079 | G12: 3244.1667 | H12: 3300.2904 | I12: 3283.7098 | J12: 3330.5061 | K12: 3352.0991 | L12: 3395.4097 | M12: 3348.5414 | N12: 3330.7314 | O12: 3371.7584 | P12: 3490.0821 | Q12: 3532.9525 | R12: … | S12: 3482.2474 | T12: 3602.1901 | U12: 3564.1868 | V12: 3608.5735 | W12: 3650.0522 | X12: 3664.7213 | Y12: 3630.3226 | Z12: 3647.627 | AA12: 3665.3903 | AB12: 3653.4537 | AC12: 3677.2194 | AD12: 3689.9469 | AE12: 3686.7212 | AF12: 3749.5921 | AG12: 3815.5636 | AH12: 3902.1442 | AI12: 3931.6373 | AJ12: 3884.44 | AK12: 3947.7801 | AL12: 3908.1271 | AM12: 3933.1418 | AN12: 3971.0476 | AO12: 4065.2145 | AP12: 4090.2734 | AQ12: 3946.1115 | AR12: 3960.8944 | AS12: 3923.6588 | AT12: 3957.6736 | AU12: 3877.1669 | AV12: 3948.4129 | AW12: 4149.6562 | AX12: … | AY12: … | AZ12: … | BA12: 4041.5633 | BB12: 4083.6752 | BC12: 4183.76 | BD12: 3952.4707 | BE12: 4002.474 | BF12: 4183.0675 | BG12: 4188.1165 | BH12: 4137.9548 | BI12: 4209.5763 | BJ12: 4255.351 | BK12: 4212.922 | BL12: 4272.766 | BM12: 4326.162 | BN12: 4428.6333 | BO12: 4414.098 | BP12: 4338.998 | BQ12: 3916.402 | BR12: 4175.178 | BS12: 4445.308
A13: Entre 50 y 59 años | B13: 1462.8036 | C13: 1455.0701 | D13: 1460.5283 | E13: 1562.3859 | F13: 1579.9763 | G13: 1543.1595 | H13: 1532.5754 | I13: 1534.5329 | J13: 1576.9235 | K13: 1565.9041 | L13: 1556.61 | M13: 1696.326 | N13: 1635.8026 | O13: 1612.8938 | P13: 1628.5544 | Q13: 1689.1018 | R13: … | S13: 1670.7331 | T13: 1679.2103 | U13: 1729.3961 | V13: 1724.7739 | W13: 1751.7219 | X13: 1774.3567 | Y13: 1710.2542 | Z13: 1720.4451 | AA13: 1791.7803 | AB13: 1721.8552 | AC13: 1706.6815 | AD13: 1754.6537 | AE13: 1781.1618 | AF13: 1797.7506 | AG13: 1814.5507 | AH13: 1809.7207 | AI13: 1797.8477 | AJ13: 1850.0238 | AK13: 1834.5652 | AL13: 1807.7008 | AM13: 1812.6617 | AN13: 1842.6064 | AO13: 1835.7076 | AP13: 1825.8148 | AQ13: 1817.962 | AR13: 1805.7876 | AS13: 1848.8217 | AT13: 1810.771 | AU13: 1825.2655 | AV13: 1846.8557 | AW13: 1895.2371 | AX13: … | AY13: … | AZ13: … | BA13: 2110.0564 | BB13: 2106.2815 | BC13: 2087.5638 | BD13: 2151.0378 | BE13: 2193.421 | BF13: 2141.4312 | BG13: 2176.7257 | BH13: 2064.5491 | BI13: 2123.4188 | BJ13: 2170.168 | BK13: 2150.81 | BL13: 2110.667 | BM13: 2176.616 | BN13: 2174.2737 | BO13: 2205.276 | BP13: 2171.826 | BQ13: 1654.418 | BR13: 1840.49 | BS13: 1952.158
A14: 60 años y más | B14: 692.44249 | C14: 783.19772 | D14: 758.29736 | E14: 762.52711 | F14: 766.84935 | G14: 797.20821 | H14: 785.96044 | I14: 858.62787 | J14: 884.02262 | K14: 891.30899 | L14: 876.74473 | M14: 865.36943 | N14: 886.37423 | O14: 948.23845 | P14: 895.26257 | Q14: 874.71543 | R14: … | S14: 856.38416 | T14: 810.96759 | U14: 863.03214 | V14: 838.32674 | W14: 873.82184 | X14: 893.05222 | Y14: 907.77217 | Z14: 875.70687 | AA14: 917.62971 | AB14: 911.18198 | AC14: 965.54157 | AD14: 950.74372 | AE14: 934.61247 | AF14: 948.94782 | AG14: 941.07714 | AH14: 1009.5559 | AI14: 976.93738 | AJ14: 908.10419 | AK14: 984.63975 | AL14: 1011.8904 | AM14: 1010.1066 | AN14: 949.18437 | AO14: 1028.855 | AP14: 1038.7705 | AQ14: 996.83978 | AR14: 979.72772 | AS14: 969.6598 | AT14: 1010.4016 | AU14: 1032.2457 | AV14: 1009.0645 | AW14: 973.19837 | AX14: … | AY14: … | AZ14: … | BA14: 1160.1856 | BB14: 1228.2365 | BC14: 1204.6695 | BD14: 1204.5353 | BE14: 1166.2597 | BF14: 1255.1543 | BG14: 1287.2248 | BH14: 1340.3195 | BI14: 1257.0781 | BJ14: 1207.177 | BK14: 1236.746 | BL14: 1322.224 | BM14: 1321.256 | BN14: 1329.5052 | BO14: 1318.581 | BP14: 1296.733 | BQ14: 757.268 | BR14: 958.771 | BS14: 1096.177
A15: Posición en el hogar
A16: Jefe | B16: 4605.5099 | C16: 4817.2879 | D16: 4730.3022 | E16: 4793.2066 | F16: 4902.6255 | G16: 4934.7648 | H16: 4907.7169 | I16: 4891.6701 | J16: 5072.6132 | K16: 5072.0338 | L16: 5005.0505 | M16: 5129.3625 | N16: 5197.1228 | O16: 5128.5182 | P16: 5119.3904 | Q16: 5243.8232 | R16: … | S16: 5122.9954 | T16: 5095.3215 | U16: 5231.0551 | V16: 5198.8088 | W16: 5238.4089 | X16: 5223.8395 | Y16: 5236.9644 | Z16: 5246.9448 | AA16: 5276.0262 | AB16: 5251.6659 | AC16: 5309.6145 | AD16: 5345.6139 | AE16: 5406.5066 | AF16: 5470.865 | AG16: 5566.868 | AH16: 5578.2079 | AI16: 5652.2001 | AJ16: 5628.6442 | AK16: 5629.0223 | AL16: 5590.905 | AM16: 5677.697 | AN16: 5607.7095 | AO16: 5770.0519 | AP16: 5683.6835 | AQ16: 5618.3911 | AR16: 5572.0031 | AS16: 5556.2343 | AT16: 5575.3267 | AU16: 5622.668 | AV16: 5615.7234 | AW16: 5657.524 | AX16: … | AY16: … | AZ16: … | BA16: 5681.6638 | BB16: 5694.673 | BC16: 5750.3811 | BD16: 5667.145 | BE16: 5672.77 | BF16: 5786.9387 | BG16: 5866.3386 | BH16: 5817.1516 | BI16: 5791.2544 | BJ16: 5862.123 | BK16: 5884.53 | BL16: 5990.395 | BM16: 6022.492 | BN16: 6037.9079 | BO16: 6100.222 | BP16: 6049.462 | BQ16: 5060.601 | BR16: 5599.697 | BS16: 5926.662
A17: Cónyuge | B17: 1941.5942 | C17: 1898.5899 | D17: 1971.5622 | E17: 2015.4843 | F17: 1999.8761 | G17: 2012.8342 | H17: 1972.6134 | I17: 2041.9458 | J17: 2038.1679 | K17: 2082.7255 | L17: 2044.8945 | M17: 2120.52 | N17: 2127.5038 | O17: 2079.8168 | P17: 2105.527 | Q17: 2175.2056 | R17: … | S17: 2115.3368 | T17: 2172.856 | U17: 2236.1022 | V17: 2209.7085 | W17: 2313.4938 | X17: 2273.8159 | Y17: 2320.0845 | Z17: 2313.1569 | AA17: 2340.6945 | AB17: 2283.9062 | AC17: 2317.9427 | AD17: 2333.4249 | AE17: 2321.4492 | AF17: 2373.5265 | AG17: 2428.5112 | AH17: 2474.6527 | AI17: 2418.0708 | AJ17: 2435.446 | AK17: 2445.7062 | AL17: 2482.0389 | AM17: 2460.3305 | AN17: 2424.9169 | AO17: 2438.8395 | AP17: 2514.2435 | AQ17: 2495.0674 | AR17: 2518.7829 | AS17: 2427.0566 | AT17: 2464.8364 | AU17: 2468.1556 | AV17: 2481.3769 | AW17: 2530.1511 | AX17: … | AY17: … | AZ17: … | BA17: 2607.4416 | BB17: 2659.5615 | BC17: 2631.908 | BD17: 2618.2832 | BE17: 2633.9844 | BF17: 2704.3104 | BG17: 2764.8548 | BH17: 2707.2606 | BI17: 2769.7992 | BJ17: 2805.543 | BK17: 2745.5 | BL17: 2821.932 | BM17: 2872.979 | BN17: 2880.641 | BO17: 2910.262 | BP17: 2816.492 | BQ17: 2345.746 | BR17: 2506.542 | BS17: 2653.93
A18: Hijo | B18: 2005.7115 | C18: 2019.4729 | D18: 2056.1615 | E18: 2035.8676 | F18: 2099.9026 | G18: 2168.2991 | H18: 2135.7309 | I18: 2184.2727 | J18: 2208.2892 | K18: 2252.3648 | L18: 2244.2994 | M18: 2298.6966 | N18: 2242.674 | O18: 2421.7014 | P18: 2380.3983 | Q18: 2314.9875 | R18: … | S18: 2520.0478 | T18: 2435.6911 | U18: 2337.6382 | V18: 2355.8612 | W18: 2464.4126 | X18: 2451.5965 | Y18: 2365.8719 | Z18: 2335.703 | AA18: 2391.5195 | AB18: 2434.5687 | AC18: 2426.2517 | AD18: 2398.2841 | AE18: 2405.4739 | AF18: 2315.4603 | AG18: 2402.2773 | AH18: 2360.6982 | AI18: 2371.4692 | AJ18: 2248.928 | AK18: 2366.6916 | AL18: 2481.7429 | AM18: 2355.6807 | AN18: 2350.7846 | AO18: 2395.1501 | AP18: 2370.1491 | AQ18: 2416.6948 | AR18: 2285.1044 | AS18: 2324.3134 | AT18: 2245.5449 | AU18: 2450.9797 | AV18: 2320.1167 | AW18: 2285.452 | AX18: … | AY18: … | AZ18: … | BA18: 2452.0572 | BB18: 2473.316 | BC18: 2470.567 | BD18: 2505.5717 | BE18: 2477.6923 | BF18: 2542.3944 | BG18: 2623.5265 | BH18: 2557.2574 | BI18: 2452.2685 | BJ18: 2416.216 | BK18: 2437.824 | BL18: 2405.447 | BM18: 2437.915 | BN18: 2490.6944 | BO18: 2528.452 | BP18: 2435.3 | BQ18: 1642.049 | BR18: 2017.611 | BS18: 2173.947
A19: Otros | B19: 470.49478 | C19: 515.01276 | D19: 500.49824 | E19: 520.75255 | F19: 553.63077 | G19: 554.63695 | H19: 504.16276 | I19: 518.68558 | J19: 592.26994 | K19: 607.7798 | L19: 606.02255 | M19: 609.6185 | N19: 593.07399 | O19: 667.87168 | P19: 636.87096 | Q19: 653.79429 | R19: … | S19: 616.06175 | T19: 660.46001 | U19: 633.20427 | V19: 661.84401 | W19: 652.34921 | X19: 698.86875 | Y19: 668.835 | Z19: 630.24784 | AA19: 681.79833 | AB19: 714.4764 | AC19: 716.72845 | AD19: 731.96889 | AE19: 693.63149 | AF19: 678.72268 | AG19: 699.03227 | AH19: 757.73053 | AI19: 664.24698 | AJ19: 647.86353 | AK19: 696.34439 | AL19: 731.04463 | AM19: 776.1679 | AN19: 691.29516 | AO19: 732.72141 | AP19: 762.44353 | AQ19: 774.42707 | AR19: 719.8516 | AS19: 703.30205 | AT19: 736.69501 | AU19: 711.15318 | AV19: 684.99967 | AW19: 677.90728 | AX19: … | AY19: … | AZ19: … | BA19: 731.23639 | BB19: 786.6674 | BC19: 743.89421 | BD19: 669.82229 | BE19: 726.6015 | BF19: 777.15781 | BG19: 756.60817 | BH19: 784.71243 | BI19: 744.27711 | BJ19: 738.142 | BK19: 725.543 | BL19: 729.543 | BM19: 740.007 | BN19: 699.78895 | BO19: 701.183 | BP19: 743.946 | BQ19: 497.684 | BR19: 533.999 | BS19: 769.11
A20: Nivel educativo
A21: Hasta primario incompleto | B21: 686.73595 | C21: 693.19604 | D21: 734.40205 | E21: 697.76721 | F21: 685.35833 | G21: 698.65078 | H21: 690.57863 | I21: 667.60071 | J21: 707.94894 | K21: 761.08648 | L21: 672.71574 | M21: 738.23967 | N21: 709.92771 | O21: 734.23324 | P21: 678.81765 | Q21: 641.46224 | R21: … | S21: 695.98933 | T21: 650.1057 | U21: 589.64304 | V21: 620.73098 | W21: 670.5551 | X21: 638.58302 | Y21: 605.08332 | Z21: 619.19627 | AA21: 577.87895 | AB21: 527.87977 | AC21: 564.09523 | AD21: 552.57939 | AE21: 536.76516 | AF21: 511.14564 | AG21: 517.20412 | AH21: 546.26058 | AI21: 518.75381 | AJ21: 521.73835 | AK21: 554.84284 | AL21: 516.19881 | AM21: 511.27705 | AN21: 453.61009 | AO21: 466.68284 | AP21: 510.47579 | AQ21: 506.96448 | AR21: 497.18474 | AS21: 416.02349 | AT21: 448.81504 | AU21: 489.55277 | AV21: 466.49833 | AW21: 444.14118 | AX21: … | AY21: … | AZ21: … | BA21: 480.09605 | BB21: 497.6507 | BC21: 461.29448 | BD21: 516.94771 | BE21: 443.63034 | BF21: 459.53388 | BG21: 466.2463 | BH21: 445.8948 | BI21: 431.23639 | BJ21: 436.961 | BK21: 452.102 | BL21: 455.973 | BM21: 463.663 | BN21: 481.33328 | BO21: 420.522 | BP21: 436.155 | BQ21: 269.804 | BR21: 354.756 | BS21: 428.671
A22: Primario completo | B22: 1986.5235 | C22: 2153.6614 | D22: 2230.3656 | E22: 2132.1105 | F22: 2215.248 | G22: 2257.1362 | H22: 2240.5492 | I22: 2240.1507 | J22: 2201.8228 | K22: 2189.1593 | L22: 2195.2395 | M22: 2208.8498 | N22: 2152.7778 | O22: 2149.2045 | P22: 2157.9148 | Q22: 2166.2385 | R22: … | S22: 1957.9163 | T22: 2070.564 | U22: 2150.1736 | V22: 2070.5257 | W22: 2001.0304 | X22: 2126.5491 | Y22: 2015.2707 | Z22: 1947.1112 | AA22: 2058.2852 | AB22: 2056.9074 | AC22: 2005.2112 | AD22: 1991.2618 | AE22: 2043.1822 | AF22: 2038.6844 | AG22: 2000.9412 | AH22: 2072.4911 | AI22: 2011.0606 | AJ22: 2029.494 | AK22: 2073.5636 | AL22: 1999.0728 | AM22: 1972.4152 | AN22: 1913.9526 | AO22: 1906.233 | AP22: 1953.0232 | AQ22: 1889.079 | AR22: 1851.7981 | AS22: 1905.9473 | AT22: 1868.0164 | AU22: 1949.8475 | AV22: 1891.9517 | AW22: 1914.0032 | AX22: … | AY22: … | AZ22: … | BA22: 1884.1202 | BB22: 1849.2396 | BC22: 1792.892 | BD22: 1656.4505 | BE22: 1781.7928 | BF22: 1796.2285 | BG22: 1762.1621 | BH22: 1693.874 | BI22: 1636.9025 | BJ22: 1615.573 | BK22: 1599.146 | BL22: 1672.822 | BM22: 1638.378 | BN22: 1568.5067 | BO22: 1598.544 | BP22: 1688.593 | BQ22: 1180.63 | BR22: 1311.873 | BS22: 1553.895
A23: Secundario incompleto | B23: 1728.5251 | C23: 1702.3238 | D23: 1622.4331 | E23: 1666.3365 | F23: 1697.4831 | G23: 1680.4512 | H23: 1704.5274 | I23: 1588.2199 | J23: 1716.3835 | K23: 1720.7868 | L23: 1708.7219 | M23: 1723.4858 | N23: 1727.3732 | O23: 1788.5327 | P23: 1807.0919 | Q23: 1817.5143 | R23: … | S23: 1826.277 | T23: 1763.6065 | U23: 1775.2679 | V23: 1754.7901 | W23: 1845.1423 | X23: 1814.8861 | Y23: 1788.3386 | Z23: 1777.498 | AA23: 1809.0144 | AB23: 1766.3702 | AC23: 1845.5001 | AD23: 1835.3608 | AE23: 1771.8523 | AF23: 1831.3515 | AG23: 1955.7012 | AH23: 1946.2283 | AI23: 1893.2912 | AJ23: 1783.6809 | AK23: 1828.9686 | AL23: 1931.81 | AM23: 1889.7603 | AN23: 1788.0466 | AO23: 1929.621 | AP23: 1916.2594 | AQ23: 1990.9141 | AR23: 1952.905 | AS23: 1922.0004 | AT23: 1956.4507 | AU23: 1922.9959 | AV23: 1800.6215 | AW23: 1958.9519 | AX23: … | AY23: … | AZ23: … | BA23: 1884.6352 | BB23: 1956.7873 | BC23: 1931.2707 | BD23: 1941.7939 | BE23: 1958.8707 | BF23: 1993.3334 | BG23: 1999.6041 | BH23: 1924.7822 | BI23: 1994.9342 | BJ23: 2024.513 | BK23: 1901.568 | BL23: 1913.673 | BM23: 1915.589 | BN23: 1915.5462 | BO23: 1945.879 | BP23: 1949.849 | BQ23: 1485.854 | BR23: 1752.868 | BS23: 2063.341
A24: Secundario completo | B24: 1791.9651 | C24: 1857.6347 | D24: 1891.6726 | E24: 1931.6696 | F24: 1988.2736 | G24: 2033.1412 | H24: 1975.9187 | I24: 2078.7372 | J24: 2123.1468 | K24: 2063.7888 | L24: 2147.2606 | M24: 2198.3362 | N24: 2207.9946 | O24: 2263.0898 | P24: 2263.0496 | Q24: 2359.2794 | R24: … | S24: 2457.348 | T24: 2375.5819 | U24: 2493.1166 | V24: 2568.4073 | W24: 2537.0946 | X24: 2463.9498 | Y24: 2531.2078 | Z24: 2577.3763 | AA24: 2586.4111 | AB24: 2567.4939 | AC24: 2524.1957 | AD24: 2654.5334 | AE24: 2663.3118 | AF24: 2641.6209 | AG24: 2728.2353 | AH24: 2686.4881 | AI24: 2758.6276 | AJ24: 2798.6139 | AK24: 2819.7746 | AL24: 2955.3119 | AM24: 2907.082 | AN24: 2837.7859 | AO24: 3061.6237 | AP24: 2916.9749 | AQ24: 2984.6863 | AR24: 2930.7303 | AS24: 2952.3444 | AT24: 2821.8128 | AU24: 2918.0856 | AV24: 2961.6933 | AW24: 2976.0756 | AX24: … | AY24: … | AZ24: … | BA24: 3105.3671 | BB24: 3144.1083 | BC24: 3234.8975 | BD24: 3166.4011 | BE24: 3182.6745 | BF24: 3244.2442 | BG24: 3270.177 | BH24: 3340.3417 | BI24: 3297.8385 | BJ24: 3337.347 | BK24: 3273.353 | BL24: 3329.956 | BM24: 3344.75 | BN24: 3312.8177 | BO24: 3407.087 | BP24: 3294.353 | BQ24: 2628.959 | BR24: 2784.584 | BS24: 2950.815
A25: Terc/univ incompleto | B25: 1169.6623 | C25: 1215.0857 | D25: 1196.5413 | E25: 1281.1407 | F25: 1269.275 | G25: 1318.9532 | H25: 1210.3684 | I25: 1349.2871 | J25: 1328.8354 | K25: 1403.2939 | L25: 1335.0399 | M25: 1422.3841 | N25: 1469.2572 | O25: 1396.179 | P25: 1358.1078 | Q25: 1437.6147 | R25: … | S25: 1420.1154 | T25: 1389.7325 | U25: 1402.1468 | V25: 1404.3169 | W25: 1448.2337 | X25: 1390.4668 | Y25: 1453.3079 | Z25: 1478.9968 | AA25: 1478.4855 | AB25: 1464.8011 | AC25: 1516.4954 | AD25: 1494.9013 | AE25: 1502.0199 | AF25: 1550.6005 | AG25: 1517.0391 | AH25: 1513.2992 | AI25: 1536.5934 | AJ25: 1444.747 | AK25: 1478.3817 | AL25: 1531.845 | AM25: 1518.2533 | AN25: 1541.0158 | AO25: 1526.1705 | AP25: 1505.4282 | AQ25: 1506.821 | AR25: 1517.6196 | AS25: 1430.3614 | AT25: 1446.5241 | AU25: 1507.1574 | AV25: 1554.2061 | AW25: 1473.804 | AX25: … | AY25: … | AZ25: … | BA25: 1553.5973 | BB25: 1559.5408 | BC25: 1519.7696 | BD25: 1568.9544 | BE25: 1647.4594 | BF25: 1695.8306 | BG25: 1693.7144 | BH25: 1689.7845 | BI25: 1708.7417 | BJ25: 1692.928 | BK25: 1724.186 | BL25: 1716.225 | BM25: 1809.014 | BN25: 1783.8056 | BO25: 1809.017 | BP25: 1815.489 | BQ25: 1468.965 | BR25: 1628.641 | BS25: 1652.229
A26: Terc/univ completo | B26: 1659.8984 | C26: 1628.4619 | D26: 1583.1094 | E26: 1656.2864 | F26: 1700.397 | G26: 1682.2024 | H26: 1698.2817 | I26: 1712.5786 | J26: 1833.2029 | K26: 1876.7888 | L26: 1841.2893 | M26: 1866.9021 | N26: 1893.0439 | O26: 1966.6687 | P26: 1977.2049 | Q26: 1965.7014 | R26: … | S26: 2016.7958 | T26: 2114.7381 | U26: 2027.652 | V26: 2007.4515 | W26: 2166.6084 | X26: 2213.6859 | Y26: 2198.5475 | Z26: 2125.8739 | AA26: 2179.9635 | AB26: 2301.1648 | AC26: 2315.0396 | AD26: 2280.6551 | AE26: 2309.9299 | AF26: 2265.1715 | AG26: 2377.5679 | AH26: 2406.5221 | AI26: 2387.6605 | AJ26: 2382.6077 | AK26: 2382.2331 | AL26: 2351.493 | AM26: 2471.0884 | AN26: 2540.2952 | AO26: 2446.4319 | AP26: 2528.3582 | AQ26: 2426.1154 | AR26: 2345.5042 | AS26: 2384.2294 | AT26: 2480.7841 | AU26: 2465.3173 | AV26: 2427.2457 | AW26: 2384.0586 | AX26: … | AY26: … | AZ26: … | BA26: 2564.5831 | BB26: 2606.8912 | BC26: 2656.6261 | BD26: 2610.2746 | BE26: 2496.6204 | BF26: 2621.6307 | BG26: 2819.4241 | BH26: 2771.7046 | BI26: 2687.9458 | BJ26: 2714.702 | BK26: 2843.042 | BL26: 2858.668 | BM26: 2901.999 | BN26: 3047.0228 | BO26: 3059.07 | BP26: 2860.761 | BQ26: 2511.868 | BR26: 2825.127 | BS26: 2874.698
A27: Categoría ocupacional
A28: Patrón | B28: 328.6914 | C28: 363.11317 | D28: 342.95958 | E28: 372.01512 | F28: 395.58134 | G28: 403.78981 | H28: 348.32733 | I28: 376.7653 | J28: 419.85763 | K28: 402.39599 | L28: 382.70292 | M28: 418.65685 | N28: 430.03303 | O28: 422.80159 | P28: 466.00016 | Q28: 458.774 | R28: … | S28: 455.84851 | T28: 481.09502 | U28: 472.10994 | V28: 459.47254 | W28: 503.49649 | X28: 503.52677 | Y28: 461.3657 | Z28: 448.066 | AA28: 473.94733 | AB28: 488.33204 | AC28: 493.7548 | AD28: 515.9935 | AE28: 442.65108 | AF28: 469.3634 | AG28: 526.46515 | AH28: 509.72742 | AI28: 471.94891 | AJ28: 382.82185 | AK28: 447.08087 | AL28: 451.52856 | AM28: 486.77695 | AN28: 405.26257 | AO28: 454.65496 | AP28: 475.30032 | AQ28: 404.39083 | AR28: 383.6707 | AS28: 377.06161 | AT28: 383.94649 | AU28: 396.72569 | AV28: 376.73172 | AW28: 394.42035 | AX28: … | AY28: … | AZ28: … | BA28: 411.02968 | BB28: 403.44871 | BC28: 437.5884 | BD28: 464.66353 | BE28: 439.52085 | BF28: 454.11268 | BG28: 434.47877 | BH28: 437.95014 | BI28: 477.38882 | BJ28: 469.03 | BK28: 462.115 | BL28: 430.617 | BM28: 416.323 | BN28: 476.89596 | BO28: 509.561 | BP28: 426.606 | BQ28: 243.605 | BR28: 316.793 | BS28: 296.084
A29: Cuenta propia | B29: 1890.0868 | C29: 1906.3848 | D29: 1871.0476 | E29: 1903.0453 | F29: 1956.8539 | G29: 1948.4514 | H29: 1919.1178 | I29: 1974.4714 | J29: 2016.9099 | K29: 2002.1951 | L29: 1925.8205 | M29: 1967.9031 | N29: 1913.3017 | O29: 1998.1301 | P29: 1887.7575 | Q29: 1901.222 | R29: … | S29: 1862.0939 | T29: 1836.3466 | U29: 1932.3827 | V29: 2006.5815 | W29: 1919.5911 | X29: 1924.6447 | Y29: 2031.6642 | Z29: 1975.0323 | AA29: 2079.1969 | AB29: 1992.5339 | AC29: 2011.57 | AD29: 1912.5484 | AE29: 1950.0851 | AF29: 1964.315 | AG29: 1969.8957 | AH29: 2007.3992 | AI29: 1966.0275 | AJ29: 2053.8132 | AK29: 2124.4785 | AL29: 2005.9554 | AM29: 2062.7459 | AN29: 2084.273 | AO29: 2232.9816 | AP29: 2124.6969 | AQ29: 2176.1818 | AR29: 2136.4228 | AS29: 2194.6046 | AT29: 2168.114 | AU29: 2195.7796 | AV29: 2128.364 | AW29: 2155.4511 | AX29: … | AY29: … | AZ29: … | BA29: 2330.997 | BB29: 2376.0984 | BC29: 2358.2108 | BD29: 2403.7754 | BE29: 2347.5715 | BF29: 2495.4329 | BG29: 2541.0711 | BH29: 2430.8155 | BI29: 2505.8992 | BJ29: 2531.269 | BK29: 2488.831 | BL29: 2544.172 | BM29: 2628.858 | BN29: 2767.3427 | BO29: 2775.34 | BP29: 2683.581 | BQ29: 1894.599 | BR29: 2660.439 | BS29: 3039.006
A30: Obrero o empleado | B30: 6652.2627 | C30: 6837.3946 | D30: 6880.3757 | E30: 6964.2268 | F30: 7081.0074 | G30: 7185.8382 | H30: 7132.7117 | I30: 7198.3249 | J30: 7363.3757 | K30: 7482.0156 | L30: 7493.505 | M30: 7659.0097 | N30: 7713.0846 | O30: 7752.6328 | P30: 7765.9573 | Q30: 7932.642 | R30: … | S30: 7950.7216 | T30: 7963.3945 | U30: 7934.4696 | V30: 7897.1587 | W30: 8160.8353 | X30: 8129.6919 | Y30: 8023.7046 | Z30: 8013.5194 | AA30: 8050.204 | AB30: 8110.7536 | AC30: 8182.6837 | AD30: 8283.1297 | AE30: 8355.0256 | AF30: 8315.3148 | AG30: 8504.6797 | AH30: 8573.8543 | AI30: 8597.9385 | AJ30: 8467.3908 | AK30: 8496.4556 | AL30: 8752.987 | AM30: 8667.2138 | AN30: 8502.587 | AO30: 8579.3729 | AP30: 8679.266 | AQ30: 8667.6243 | AR30: 8510.119 | AS30: 8378.9743 | AT30: 8396.2268 | AU30: 8587.9418 | AV30: 8539.3021 | AW30: 8547.3138 | AX30: … | AY30: … | AZ30: … | BA30: 8668.1129 | BB30: 8758.9836 | BC30: 8741.0398 | BD30: 8500.2516 | BE30: 8646.8968 | BF30: 8794.3599 | BG30: 8986.4306 | BH30: 8927.085 | BI30: 8694.8956 | BJ30: 8761.3 | BK30: 8789.726 | BL30: 8902.989 | BM30: 8951.84 | BN30: 8796.2166 | BO30: 8887.247 | BP30: 8855.204 | BQ30: 7344.854 | BR30: 7615.482 | BS30: 8123.69
A31: Trabajador familiar | B31: 152.26945 | C31: 143.47086 | D31: 164.14123 | E31: 126.02382 | F31: 122.59235 | G31: 132.45558 | H31: 120.06713 | I31: 87.012625 | J31: 111.19706 | K31: 128.29729 | L31: 98.238569 | M31: 112.62782 | N31: 103.95514 | O31: 124.34347 | P31: 122.47164 | Q31: 95.172608 | R31: … | S31: 105.77785 | T31: 83.492456 | U31: 99.037591 | V31: 63.009667 | W31: 84.741571 | X31: 90.257286 | Y31: 75.021281 | Z31: 89.434812 | AA31: 86.69035 | AB31: 92.99769 | AC31: 82.528771 | AD31: 97.620227 | AE31: 79.299417 | AF31: 89.581319 | AG31: 95.648144 | AH31: 80.308413 | AI31: 70.072088 | AJ31: 56.855952 | AK31: 69.749561 | AL31: 75.260412 | AM31: 53.139419 | AN31: 82.583692 | AO31: 69.753457 | AP31: 51.25637 | AQ31: 56.383419 | AR31: 65.529456 | AS31: 60.265914 | AT31: 74.11573 | AU31: 72.509422 | AV31: 57.818858 | AW31: 53.84913 | AX31: … | AY31: … | AZ31: … | BA31: 62.259408 | BB31: 75.687238 | BC31: 59.911357 | BD31: 92.131649 | BE31: 77.059066 | BF31: 66.895893 | BG31: 49.34759 | BH31: 70.53133 | BI31: 79.415506 | BJ31: 60.425 | BK31: 52.725 | BL31: 69.539 | BM31: 76.372 | BN31: 68.577075 | BO31: 67.971 | BP31: 79.809 | BQ31: 63.022 | BR31: 65.135 | BS31: 64.869
A32: Rama de actividad
A33: Actividades primarias | B33: 173.39646 | C33: 201.3158 | D33: 186.18436 | E33: 185.23843 | F33: 185.74157 | G33: 149.66846 | H33: 141.64646 | I33: 150.80581 | J33: 167.27638 | K33: 160.65425 | L33: 145.23162 | M33: 154.16458 | N33: 134.06663 | O33: 143.4604 | P33: 149.52309 | Q33: 120.13681 | R33: … | S33: 131.39886 | T33: 147.68571 | U33: 157.24782 | V33: 170.93732 | W33: 184.79202 | X33: 123.66132 | Y33: 191.98138 | Z33: 157.67269 | AA33: 200.61212 | AB33: 201.55539 | AC33: 183.34926 | AD33: 165.50357 | AE33: 172.47927 | AF33: 189.09725 | AG33: 197.34216 | AH33: 170.08383 | AI33: 173.93935 | AJ33: 123.03349 | AK33: 123.75551 | AL33: 107.78615 | AM33: 120.49823 | AN33: 118.20678 | AO33: 119.15601 | AP33: 109.82608 | AQ33: 123.17825 | AR33: 100.74946 | AS33: 115.41201 | AT33: 98.791586 | AU33: 118.20939 | AV33: 98.961302 | AW33: 102.87807 | AX33: … | AY33: … | AZ33: … | BA33: 107.348 | BB33: 113.40183 | BC33: 108.04608 | BD33: 92.144801 | BE33: 103.41619 | BF33: 114.42211 | BG33: 92.97757 | BH33: 116.40755 | BI33: 109.28229 | BJ33: 106.403 | BK33: 95.73 | BL33: 120.608 | BM33: 97.015 | BN33: 114.86505 | BO33: 130.121 | BP33: 121.463 | BQ33: 93.079 | BR33: 103.816 | BS33: 97.996
C34: =C33/B33-1 -> 0.16101449 | D34: =D33/C33-1 -> -0.075162699 | E34: =E33/D33-1 -> -0.0050806207 | F34: =F33/E33-1 -> 0.0027161721 | G34: =G33/F33-1 -> -0.19421129 | H34: =H33/G33-1 -> -0.05359844 | I34: =I33/H33-1 -> 0.064663463 | J34: =J33/I33-1 -> 0.10921708 | ... Q34: =Q33/P33-1 -> -0.19653336 | T34: =T33/S33-1 -> 0.12394968 | U34: =U33/T33-1 -> 0.06474636 | V34: =V33/U33-1 -> 0.087056845 | W34: =W33/V33-1 -> 0.081051342 | X34: =X33/W33-1 -> -0.3308081 | Y34: =Y33/X33-1 -> 0.55247717 | Z34: =Z33/Y33-1 -> -0.17870843 | AA34: =AA33/Z33-1 -> 0.27233271 | ... AW34: =AW33/AV33-1 -> 0.039578809 | BB34: =BB33/BA33-1 -> 0.056394456 | BC34: =BC33/BB33-1 -> -0.047228081 | BD34: =BD33/BC33-1 -> -0.14717128 | BE34: =BE33/BD33-1 -> 0.12232262 | BF34: =BF33/BE33-1 -> 0.1064235 | BG34: =BG33/BF33-1 -> -0.18741604 | BH34: =BH33/BG33-1 -> 0.25199605 | BI34: =BI33/BH33-1 -> -0.061209613 | ... BP34: =BP33/BO33-1 -> -0.066538068 | BQ34: =BQ33/$BP33-1 -> -0.23368433 | BR34: =BR33/$BP33-1 -> -0.14528704 | BS34: =BS33/$BP33-1 -> -0.19320287
A35: Industria manufacturera | B35: 1233.4292 | C35: 1219.5998 | D35: 1245.8619 | E35: 1364.8475 | F35: 1340.1157 | G35: 1387.5772 | H35: 1399.8136 | I35: 1363.8192 | J35: 1399.1954 | K35: 1414.5431 | L35: 1395.7526 | M35: 1474.0377 | N35: 1455.8325 | O35: 1447.5836 | P35: 1420.6707 | Q35: 1504.701 | R35: … | S35: 1516.9066 | T35: 1455.9423 | U35: 1434.5116 | V35: 1421.7608 | W35: 1578.0394 | X35: 1475.3441 | Y35: 1337.9247 | Z35: 1373.5355 | AA35: 1450.3726 | AB35: 1440.4429 | AC35: 1415.2776 | AD35: 1469.2864 | AE35: 1542.083 | AF35: 1440.2273 | AG35: 1467.4869 | AH35: 1619.9098 | AI35: 1557.9167 | AJ35: 1467.1648 | AK35: 1438.6615 | AL35: 1503.5723 | AM35: 1454.5082 | AN35: 1464.1951 | AO35: 1523.0941 | AP35: 1503.1658 | AQ35: 1466.8544 | AR35: 1429.0258 | AS35: 1444.9202 | AT35: 1469.4377 | AU35: 1489.3305 | AV35: 1461.515 | AW35: 1477.0482 | AX35: … | AY35: … | AZ35: … | BA35: 1393.613 | BB35: 1470.2236 | BC35: 1420.5026 | BD35: 1332.8126 | BE35: 1422.1717 | BF35: 1404.9228 | BG35: 1381.7749 | BH35: 1387.3724 | BI35: 1348.7618 | BJ35: 1310.338 | BK35: 1286.693 | BL35: 1351.109 | BM35: 1418.394 | BN35: 1420.1694 | BO35: 1332.473 | BP35: 1335.428 | BQ35: 1171.031 | BR35: 1258.233 | BS35: 1516.615
C36: =C35/B35-1 -> -0.011212218 | D36: =D35/C35-1 -> 0.021533385 | E36: =E35/D35-1 -> 0.095504655 | F36: =F35/E35-1 -> -0.018120522 | G36: =G35/F35-1 -> 0.035415917 | H36: =H35/G35-1 -> 0.0088185347 | I36: =I35/H35-1 -> -0.025713701 | J36: =J35/I35-1 -> 0.025939068 | ... Q36: =Q35/P35-1 -> 0.05914837 | T36: =T35/S35-1 -> -0.04018985 | U36: =U35/T35-1 -> -0.014719472 | V36: =V35/U35-1 -> -0.0088885953 | W36: =W35/V35-1 -> 0.109919 | X36: =X35/W35-1 -> -0.065077746 | Y36: =Y35/X35-1 -> -0.093143996 | Z36: =Z35/Y35-1 -> 0.02661644 | AA36: =AA35/Z35-1 -> 0.055941145 | ... AW36: =AW35/AV35-1 -> 0.010628126 | BB36: =BB35/BA35-1 -> 0.054972617 | BC36: =BC35/BB35-1 -> -0.033818622 | BD36: =BD35/BC35-1 -> -0.061731665 | BE36: =BE35/BD35-1 -> 0.067045475 | BF36: =BF35/BE35-1 -> -0.012128525 | BG36: =BG35/BF35-1 -> -0.016476277 | BH36: =BH35/BG35-1 -> 0.0040508912 | BI36: =BI35/BH35-1 -> -0.027829958 | ... BP36: =BP35/BO35-1 -> 0.002217681 | BQ36: =BQ35/$BP35-1 -> -0.12310435 | BR36: =BR35/$BP35-1 -> -0.057805438 | BS36: =BS35/$BP35-1 -> 0.1356771
A37: Construcción | B37: 623.91329 | C37: 674.52276 | D37: 726.34681 | E37: 684.69958 | F37: 744.71481 | G37: 740.41704 | H37: 729.85866 | I37: 767.39465 | J37: 820.49385 | K37: 864.72051 | L37: 829.08012 | M37: 824.45383 | N37: 859.39649 | O37: 948.71585 | P37: 942.22796 | Q37: 911.05562 | R37: … | S37: 943.47146 | T37: 907.62099 | U37: 887.03904 | V37: 971.78938 | W37: 961.75777 | X37: 969.46605 | Y37: 928.63258 | Z37: 959.69837 | AA37: 937.86273 | AB37: 924.33189 | AC37: 938.90433 | AD37: 948.70005 | AE37: 927.03955 | AF37: 944.53289 | AG37: 969.55331 | AH37: 1062.3459 | AI37: 1015.3674 | AJ37: 1010.0694 | AK37: 994.1477 | AL37: 1008.2168 | AM37: 1019.0741 | AN37: 971.41634 | AO37: 1040.2668 | AP37: 1038.4867 | AQ37: 992.20629 | AR37: 1019.418 | AS37: 973.17431 | AT37: 1010.9256 | AU37: 1046.309 | AV37: 950.0632 | AW37: 1064.7879 | AX37: … | AY37: … | AZ37: … | BA37: 1078.658 | BB37: 1089.8313 | BC37: 1044.8607 | BD37: 1025.5702 | BE37: 1052.0253 | BF37: 1089.7888 | BG37: 1086.8893 | BH37: 1018.5335 | BI37: 1078.9741 | BJ37: 1127.224 | BK37: 1092.546 | BL37: 1025.702 | BM37: 1109.085 | BN37: 1131.6146 | BO37: 1102.906 | BP37: 1007.773 | BQ37: 661.975 | BR37: 919.071 | BS37: 1168.902
C38: =C37/B37-1 -> 0.081116199 | D38: =D37/C37-1 -> 0.076830699 | E38: =E37/D37-1 -> -0.057337942 | F38: =F37/E37-1 -> 0.087651905 | G38: =G37/F37-1 -> -0.0057710212 | H38: =H37/G37-1 -> -0.014260042 | I38: =I37/H37-1 -> 0.051429111 | J38: =J37/I37-1 -> 0.069194127 | ... Q38: =Q37/P37-1 -> -0.033083653 | T38: =T37/S37-1 -> -0.037998463 | U38: =U37/T37-1 -> -0.022676813 | V38: =V37/U37-1 -> 0.095542962 | W38: =W37/V37-1 -> -0.010322822 | X38: =X37/W37-1 -> 0.0080147877 | Y38: =Y37/X37-1 -> -0.042119548 | Z38: =Z37/Y37-1 -> 0.033453261 | AA38: =AA37/Z37-1 -> -0.02275261 | ... AW38: =AW37/AV37-1 -> 0.12075486 | BB38: =BB37/BA37-1 -> 0.010358477 | BC38: =BC37/BB37-1 -> -0.041263771 | BD38: =BD37/BC37-1 -> -0.018462261 | BE38: =BE37/BD37-1 -> 0.025795498 | BF38: =BF37/BE37-1 -> 0.035895998 | BG38: =BG37/BF37-1 -> -0.002660634 | BH38: =BH37/BG37-1 -> -0.062891217 | BI38: =BI37/BH37-1 -> 0.059340847 | ... BP38: =BP37/BO37-1 -> -0.086256671 | BQ38: =BQ37/$BP37-1 -> -0.34313084 | BR38: =BR37/$BP37-1 -> -0.088017837 | BS38: =BS37/$BP37-1 -> 0.1598862
A39: Comercio | B39: 1831.2275 | C39: 1905.6456 | D39: 1897.4507 | E39: 1873.5423 | F39: 1927.6967 | G39: 2030.9124 | H39: 1902.3819 | I39: 1848.2711 | J39: 2026.2693 | K39: 2009.4823 | L39: 1926.6712 | M39: 2030.9294 | N39: 2056.7504 | O39: 2066.4467 | P39: 2024.322 | Q39: 1984.3038 | R39: … | S39: 2001.886 | T39: 2032.6307 | U39: 2070.599 | V39: 2083.6455 | W39: 2096.7724 | X39: 2073.5901 | Y39: 2031.1376 | Z39: 2059.8791 | AA39: 2085.86 | AB39: 2068.7691 | AC39: 2060.45 | AD39: 2118.0582 | AE39: 2101.3165 | AF39: 2159.5968 | AG39: 2192.2887 | AH39: 2085.7766 | AI39: 2111.5828 | AJ39: 2020.6753 | AK39: 2078.3417 | AL39: 2081.3947 | AM39: 2095.9739 | AN39: 2061.0353 | AO39: 2061.2487 | AP39: 2047.0068 | AQ39: 2049.312 | AR39: 1982.4622 | AS39: 1922.7086 | AT39: 1867.7088 | AU39: 2001.1939 | AV39: 1902.5956 | AW39: 1906.1461 | AX39: … | AY39: … | AZ39: … | BA39: 2053.979 | BB39: 2126.0885 | BC39: 2037.82 | BD39: 2050.7995 | BE39: 2112.108 | BF39: 2137.7665 | BG39: 2146.0773 | BH39: 2139.7941 | BI39: 2173.1856 | BJ39: 2211.081 | BK39: 2164.153 | BL39: 2191.236 | BM39: 2221.356 | BN39: 2253.8614 | BO39: 2221.819 | BP39: 2239.307 | BQ39: 1652.157 | BR39: 1907.095 | BS39: 1959.377
C40: =C39/B39-1 -> 0.040638361 | D40: =D39/C39-1 -> -0.0043003149 | E40: =E39/D39-1 -> -0.012600278 | F40: =F39/E39-1 -> 0.0289048 | G40: =G39/F39-1 -> 0.053543566 | H40: =H39/G39-1 -> -0.063287067 | I40: =I39/H39-1 -> -0.028443729 | J40: =J39/I39-1 -> 0.096305221 | ... Q40: =Q39/P39-1 -> -0.019768725 | T40: =T39/S39-1 -> 0.015357855 | U40: =U39/T39-1 -> 0.018679416 | V40: =V39/U39-1 -> 0.0063008277 | W40: =W39/V39-1 -> 0.0062999905 | X40: =X39/W39-1 -> -0.011056205 | Y40: =Y39/X39-1 -> -0.020472957 | Z40: =Z39/Y39-1 -> 0.014150469 | AA40: =AA39/Z39-1 -> 0.012612823 | ... AW40: =AW39/AV39-1 -> 0.0018661333 | BB40: =BB39/BA39-1 -> 0.035107242 | BC40: =BC39/BB39-1 -> -0.041516854 | BD40: =BD39/BC39-1 -> 0.0063692875 | BE40: =BE39/BD39-1 -> 0.029894919 | BF40: =BF39/BE39-1 -> 0.012148324 | BG40: =BG39/BF39-1 -> 0.0038875811 | BH40: =BH39/BG39-1 -> -0.002927765 | BI40: =BI39/BH39-1 -> 0.01560503 | ... BP40: =BP39/BO39-1 -> 0.0078710282 | BQ40: =BQ39/$BP39-1 -> -0.26220165 | BR40: =BR39/$BP39-1 -> -0.14835483 | BS40: =BS39/$BP39-1 -> -0.12500742
...

Sheet Empleo Formales
B1: 3° Trim 03 | C1: 4° Trim 03 | D1: 1° Trim 04 | E1: 2° Trim 04 | F1: 3° Trim 04 | G1: 4° Trim 04 | H1: 1° Trim 05 | I1: 2° Trim 05 | J1: 3° Trim 05 | K1: 4° Trim 05 | L1: 1° Trim 06 | M1: 2° Trim 06 | N1: 3° Trim 06 | O1: 4° Trim 06 | P1: 1° Trim 07 | Q1: 2° Trim 07 1 | R1: 3° Trim 07 1 2 | S1: 4° Trim 07 1 | T1: 1° Trim 08 1 | U1: 2° Trim 08 1 | V1: 3° Trim 08 1 | W1: 4° Trim 08 1 | X1: 1° Trim 09 1 | Y1: 2° Trim 09 1 | Z1: 3° Trim 09 1 | AA1: 4° Trim 09 1 | AB1: 1° Trim 10 1 | AC1: 2° Trim 10 1 | AD1: 3° Trim 10 1 | AE1: 4° Trim 10 1 | AF1: 1° Trim 11 1 | AG1: 2° Trim 11 1 | AH1: 3° Trim 11 1 | AI1: 4° Trim 11 1 | AJ1: 1° Trim 12 1 | AK1: 2° Trim 12 1 | AL1: 3° Trim 12 1 | AM1: 4° Trim 12 1 | AN1: 1° Trim 13 1 | AO1: 2° Trim 13 1 | AP1: 3° Trim 13 1 | AQ1: 4° Trim 13 1 | AR1: 1° Trim 14 13 | AS1: 2° Trim 14 1 | AT1: 3° Trim 14 1 | AU1: 4° Trim 14 1 | AV1: 1° Trim 15 1 | AW1: 2° Trim 15 1 | AX1: 3° Trim 15 1 4 | AY1: 4° Trim 15 1 4 | AZ1: 1° Trim 16 4 | BA1: 2° Trim 16 | BB1: 3° Trim 16 | BC1: 4° Trim 16 | BD1: 1° Trim 17 | BE1: 2° Trim 17 | BF1: 3° Trim 17 | BG1: 4° Trim 17 | BH1: 1° Trim 18 | BI1: 2° Trim 18 | BJ1: 3° Trim 18 | BK1: 4° Trim 18 | BL1: 1° Trim 19 | BM1: 2° Trim 19 | BN1: 3° Trim 19 | BO1: 4° Trim 19 | BP1: 1° Trim 20 | BQ1: 2° Trim 20 | BR1: 3° Trim 20 | BS1: 4° Trim 20
A2: Actividades primarias | B2: ='Empleo Población'!B33-'Empleo Informales'!B28 -> 102.68926 | C2: ='Empleo Población'!C33-'Empleo Informales'!C28 -> 115.38429 | D2: ='Empleo Población'!D33-'Empleo Informales'!D28 -> 107.38708 | E2: ='Empleo Población'!E33-'Empleo Informales'!E28 -> 110.41846 | F2: ='Empleo Población'!F33-'Empleo Informales'!F28 -> 105.07007 | G2: ='Empleo Población'!G33-'Empleo Informales'!G28 -> 82.727102 | H2: ='Empleo Población'!H33-'Empleo Informales'!H28 -> 87.743595 | I2: ='Empleo Población'!I33-'Empleo Informales'!I28 -> 84.428484 | ... Q2: ='Empleo Población'!Q33-'Empleo Informales'!Q28 -> 90.632857 | S2: ='Empleo Población'!S33-'Empleo Informales'!S28 -> 106.26183 | T2: ='Empleo Población'!T33-'Empleo Informales'!T28 -> 111.48325 | U2: ='Empleo Población'!U33-'Empleo Informales'!U28 -> 128.38497 | V2: ='Empleo Población'!V33-'Empleo Informales'!V28 -> 134.01048 | W2: ='Empleo Población'!W33-'Empleo Informales'!W28 -> 152.08349 | X2: ='Empleo Población'!X33-'Empleo Informales'!X28 -> 96.373528 | Y2: ='Empleo Población'!Y33-'Empleo Informales'!Y28 -> 152.26538 | Z2: ='Empleo Población'!Z33-'Empleo Informales'!Z28 -> 136.73095 | ... AW2: ='Empleo Población'!AW33-'Empleo Informales'!AW28 -> 81.165198 | BA2: ='Empleo Población'!BA33-'Empleo Informales'!BA28 -> 85.301982 | BB2: ='Empleo Población'!BB33-'Empleo Informales'!BB28 -> 98.386426 | BC2: ='Empleo Población'!BC33-'Empleo Informales'!BC28 -> 82.141615 | BD2: ='Empleo Población'!BD33-'Empleo Informales'!BD28 -> 76.932006 | BE2: ='Empleo Población'!BE33-'Empleo Informales'!BE28 -> 81.152633 | BF2: ='Empleo Población'!BF33-'Empleo Informales'!BF28 -> 96.741317 | BG2: ='Empleo Población'!BG33-'Empleo Informales'!BG28 -> 75.36115 | BH2: ='Empleo Población'!BH33-'Empleo Informales'!BH28 -> 98.054138 | ... BS2: ='Empleo Población'!BS33-'Empleo Informales'!BS28 -> 79.189
C3: =C2/B2-1 -> 0.12362561 | D3: =D2/C2-1 -> -0.069309348 | E3: =E2/D2-1 -> 0.028228559 | F3: =F2/E2-1 -> -0.048437411 | G3: =G2/F2-1 -> -0.2126483 | H3: =H2/G2-1 -> 0.060639057 | I3: =I2/H2-1 -> -0.037781809 | J3: =J2/I2-1 -> 0.2076646 | ... Q3: =Q2/P2-1 -> -0.18358178 | T3: =T2/S2-1 -> 0.049137262 | U3: =U2/T2-1 -> 0.15160775 | V3: =V2/U2-1 -> 0.043817548 | W3: =W2/V2-1 -> 0.13486262 | X3: =X2/W2-1 -> -0.3663117 | Y3: =Y2/X2-1 -> 0.57995021 | Z3: =Z2/Y2-1 -> -0.10202204 | AA3: =AA2/Z2-1 -> 0.2126962 | ... AW3: =AW2/AV2-1 -> 0.043579125 | BB3: =BB2/BA2-1 -> 0.15338968 | BC3: =BC2/BB2-1 -> -0.16511232 | BD3: =BD2/BC2-1 -> -0.063422289 | BE3: =BE2/BD2-1 -> 0.054861785 | BF3: =BF2/BE2-1 -> 0.19209093 | BG3: =BG2/BF2-1 -> -0.22100348 | BH3: =BH2/BG2-1 -> 0.30112316 | BI3: =BI2/BH2-1 -> -0.060467002 | ... BP3: =BP2/BO2-1 -> -0.079748747 | BQ3: =BQ2/$BP2-1 -> -0.23378402 | BR3: =BR2/$BP2-1 -> -0.10632129 | BS3: =BS2/$BP2-1 -> -0.20277658
A4: Industria manufacturera | B4: ='Empleo Población'!B35-'Empleo Informales'!B30 -> 836.21996 | C4: ='Empleo Población'!C35-'Empleo Informales'!C30 -> 858.38342 | D4: ='Empleo Población'!D35-'Empleo Informales'!D30 -> 889.2015 | E4: ='Empleo Población'!E35-'Empleo Informales'!E30 -> 910.28702 | F4: ='Empleo Población'!F35-'Empleo Informales'!F30 -> 944.75457 | G4: ='Empleo Población'!G35-'Empleo Informales'!G30 -> 980.92495 | H4: ='Empleo Población'!H35-'Empleo Informales'!H30 -> 1006.7285 | I4: ='Empleo Población'!I35-'Empleo Informales'!I30 -> 976.71498 | ... Q4: ='Empleo Población'!Q35-'Empleo Informales'!Q30 -> 1087.8443 | S4: ='Empleo Población'!S35-'Empleo Informales'!S30 -> 1130.049 | T4: ='Empleo Población'!T35-'Empleo Informales'!T30 -> 1136.147 | U4: ='Empleo Población'!U35-'Empleo Informales'!U30 -> 1103.9192 | V4: ='Empleo Población'!V35-'Empleo Informales'!V30 -> 1105.0728 | W4: ='Empleo Población'!W35-'Empleo Informales'!W30 -> 1214.5044 | X4: ='Empleo Población'!X35-'Empleo Informales'!X30 -> 1164.9923 | Y4: ='Empleo Población'!Y35-'Empleo Informales'!Y30 -> 1036.3837 | Z4: ='Empleo Población'!Z35-'Empleo Informales'!Z30 -> 1035.3062 | ... AW4: ='Empleo Población'!AW35-'Empleo Informales'!AW30 -> 1161.5702 | BA4: ='Empleo Población'!BA35-'Empleo Informales'!BA30 -> 1111.4032 | BB4: ='Empleo Población'!BB35-'Empleo Informales'!BB30 -> 1145.1883 | BC4: ='Empleo Población'!BC35-'Empleo Informales'!BC30 -> 1128.4563 | BD4: ='Empleo Población'!BD35-'Empleo Informales'!BD30 -> 1059.65 | BE4: ='Empleo Población'!BE35-'Empleo Informales'!BE30 -> 1120.5524 | BF4: ='Empleo Población'!BF35-'Empleo Informales'!BF30 -> 1098.805 | BG4: ='Empleo Población'!BG35-'Empleo Informales'!BG30 -> 1085.1642 | BH4: ='Empleo Población'!BH35-'Empleo Informales'!BH30 -> 1084.9211 | ... BS4: ='Empleo Población'!BS35-'Empleo Informales'!BS30 -> 1210.635
C5: =C4/B4-1 -> 0.026504345 | D5: =D4/C4-1 -> 0.035902471 | E5: =E4/D4-1 -> 0.02371286 | F5: =F4/E4-1 -> 0.037864485 | G5: =G4/F4-1 -> 0.038285486 | H5: =H4/G4-1 -> 0.026305351 | I5: =I4/H4-1 -> -0.029812947 | J5: =J4/I4-1 -> 0.010351868 | ... Q5: =Q4/P4-1 -> 0.033828663 | T5: =T4/S4-1 -> 0.0053961609 | U5: =U4/T4-1 -> -0.028365879 | V5: =V4/U4-1 -> 0.0010450645 | W5: =W4/V4-1 -> 0.099026531 | X5: =X4/W4-1 -> -0.040767303 | Y5: =Y4/X4-1 -> -0.11039442 | Z5: =Z4/Y4-1 -> -0.0010396684 | AA5: =AA4/Z4-1 -> 0.056177872 | ... AW5: =AW4/AV4-1 -> 3.708873e-05 | BB5: =BB4/BA4-1 -> 0.030398599 | BC5: =BC4/BB4-1 -> -0.014610732 | BD5: =BD4/BC4-1 -> -0.06097376 | BE5: =BE4/BD4-1 -> 0.057474016 | BF5: =BF4/BE4-1 -> -0.019407762 | BG5: =BG4/BF4-1 -> -0.012414179 | BH5: =BH4/BG4-1 -> -0.00022401428 | BI5: =BI4/BH4-1 -> -0.01428175 | ... BP5: =BP4/BO4-1 -> -0.0054178096 | BQ5: =BQ4/$BP4-1 -> -0.038228718 | BR5: =BR4/$BP4-1 -> 0.0069150594 | BS5: =BS4/$BP4-1 -> 0.16824071
A6: Construcción | B6: ='Empleo Población'!B37-'Empleo Informales'!B32 -> 367.97706 | C6: ='Empleo Población'!C37-'Empleo Informales'!C32 -> 402.88276 | D6: ='Empleo Población'!D37-'Empleo Informales'!D32 -> 435.09196 | E6: ='Empleo Población'!E37-'Empleo Informales'!E32 -> 415.08896 | F6: ='Empleo Población'!F37-'Empleo Informales'!F32 -> 448.97651 | G6: ='Empleo Población'!G37-'Empleo Informales'!G32 -> 420.05929 | H6: ='Empleo Población'!H37-'Empleo Informales'!H32 -> 414.98218 | I6: ='Empleo Población'!I37-'Empleo Informales'!I32 -> 468.26394 | ... Q6: ='Empleo Población'!Q37-'Empleo Informales'!Q32 -> 585.03774 | S6: ='Empleo Población'!S37-'Empleo Informales'!S32 -> 602.63706 | T6: ='Empleo Población'!T37-'Empleo Informales'!T32 -> 588.78861 | U6: ='Empleo Población'!U37-'Empleo Informales'!U32 -> 544.12741 | V6: ='Empleo Población'!V37-'Empleo Informales'!V32 -> 628.93626 | W6: ='Empleo Población'!W37-'Empleo Informales'!W32 -> 589.18524 | X6: ='Empleo Población'!X37-'Empleo Informales'!X32 -> 645.88474 | Y6: ='Empleo Población'!Y37-'Empleo Informales'!Y32 -> 582.22139 | Z6: ='Empleo Población'!Z37-'Empleo Informales'!Z32 -> 609.70596 | ... AW6: ='Empleo Población'!AW37-'Empleo Informales'!AW32 -> 642.4007 | BA6: ='Empleo Población'!BA37-'Empleo Informales'!BA32 -> 624.39411 | BB6: ='Empleo Población'!BB37-'Empleo Informales'!BB32 -> 694.61177 | BC6: ='Empleo Población'!BC37-'Empleo Informales'!BC32 -> 650.02127 | BD6: ='Empleo Población'!BD37-'Empleo Informales'!BD32 -> 642.78991 | BE6: ='Empleo Población'!BE37-'Empleo Informales'!BE32 -> 644.02007 | BF6: ='Empleo Población'!BF37-'Empleo Informales'!BF32 -> 654.28419 | BG6: ='Empleo Población'!BG37-'Empleo Informales'!BG32 -> 701.17432 | BH6: ='Empleo Población'!BH37-'Empleo Informales'!BH32 -> 645.63182 | ... BS6: ='Empleo Población'!BS37-'Empleo Informales'!BS32 -> 691.241
C7: =C6/B6-1 -> 0.094858374 | D7: =D6/C6-1 -> 0.079946833 | E7: =E6/D6-1 -> -0.045974202 | F7: =F6/E6-1 -> 0.081639249 | G7: =G6/F6-1 -> -0.064406976 | H7: =H6/G6-1 -> -0.012086644 | I7: =I6/H6-1 -> 0.1283953 | J7: =J6/I6-1 -> 0.027388684 | ... Q7: =Q6/P6-1 -> 0.032889458 | T7: =T6/S6-1 -> -0.022979751 | U7: =U6/T6-1 -> -0.075852701 | V7: =V6/U6-1 -> 0.15586212 | W7: =W6/V6-1 -> -0.063203567 | X7: =X6/W6-1 -> 0.096233731 | Y7: =Y6/X6-1 -> -0.098567665 | Z7: =Z6/Y6-1 -> 0.047206395 | AA7: =AA6/Z6-1 -> 0.036835055 | ... AW7: =AW6/AV6-1 -> 0.11589058 | BB7: =BB6/BA6-1 -> 0.11245728 | BC7: =BC6/BB6-1 -> -0.064194862 | BD7: =BD6/BC6-1 -> -0.011124802 | BE7: =BE6/BD6-1 -> 0.0019137919 | BF7: =BF6/BE6-1 -> 0.015937577 | BG7: =BG6/BF6-1 -> 0.071666298 | BH7: =BH6/BG6-1 -> -0.079213545 | BI7: =BI6/BH6-1 -> 0.092028828 | ... BP7: =BP6/BO6-1 -> -0.067639014 | BQ7: =BQ6/$BP6-1 -> -0.25865936 | BR7: =BR6/$BP6-1 -> 0.0034958371 | BS7: =BS6/$BP6-1 -> 0.12603258
A8: Comercio | B8: ='Empleo Población'!B39-'Empleo Informales'!B34 -> 1326.143 | C8: ='Empleo Población'!C39-'Empleo Informales'!C34 -> 1401.2745 | D8: ='Empleo Población'!D39-'Empleo Informales'!D34 -> 1424.6741 | E8: ='Empleo Población'!E39-'Empleo Informales'!E34 -> 1377.9824 | F8: ='Empleo Población'!F39-'Empleo Informales'!F34 -> 1411.2833 | G8: ='Empleo Población'!G39-'Empleo Informales'!G34 -> 1472.1893 | H8: ='Empleo Población'!H39-'Empleo Informales'!H34 -> 1399.3199 | I8: ='Empleo Población'!I39-'Empleo Informales'!I34 -> 1354.5604 | ... Q8: ='Empleo Población'!Q39-'Empleo Informales'!Q34 -> 1496.885 | S8: ='Empleo Población'!S39-'Empleo Informales'!S34 -> 1492.5518 | T8: ='Empleo Población'!T39-'Empleo Informales'!T34 -> 1512.1142 | U8: ='Empleo Población'!U39-'Empleo Informales'!U34 -> 1612.1019 | V8: ='Empleo Población'!V39-'Empleo Informales'!V34 -> 1633.1314 | W8: ='Empleo Población'!W39-'Empleo Informales'!W34 -> 1624.5813 | X8: ='Empleo Población'!X39-'Empleo Informales'!X34 -> 1570.5783 | Y8: ='Empleo Población'!Y39-'Empleo Informales'!Y34 -> 1580.5629 | Z8: ='Empleo Población'!Z39-'Empleo Informales'!Z34 -> 1591.2627 | ... AW8: ='Empleo Población'!AW39-'Empleo Informales'!AW34 -> 1502.4298 | BA8: ='Empleo Población'!BA39-'Empleo Informales'!BA34 -> 1617.3676 | BB8: ='Empleo Población'!BB39-'Empleo Informales'!BB34 -> 1630.565 | BC8: ='Empleo Población'!BC39-'Empleo Informales'!BC34 -> 1582.8964 | BD8: ='Empleo Población'!BD39-'Empleo Informales'!BD34 -> 1589.51 | BE8: ='Empleo Población'!BE39-'Empleo Informales'!BE34 -> 1644.3351 | BF8: ='Empleo Población'!BF39-'Empleo Informales'!BF34 -> 1642.9994 | BG8: ='Empleo Población'!BG39-'Empleo Informales'!BG34 -> 1633.579 | BH8: ='Empleo Población'!BH39-'Empleo Informales'!BH34 -> 1671.9523 | ... BS8: ='Empleo Población'!BS39-'Empleo Informales'!BS34 -> 1544.333
C9: =C8/B8-1 -> 0.056654174 | D9: =D8/C8-1 -> 0.016698793 | E9: =E8/D8-1 -> -0.03277366 | F9: =F8/E8-1 -> 0.024166488 | G9: =G8/F8-1 -> 0.043156455 | H9: =H8/G8-1 -> -0.049497318 | I9: =I8/H8-1 -> -0.031986613 | J9: =J8/I8-1 -> 0.12649735 | ... Q9: =Q8/P8-1 -> -0.02384005 | T9: =T8/S8-1 -> 0.013106716 | U9: =U8/T8-1 -> 0.066124437 | V9: =V8/U8-1 -> 0.013044748 | W9: =W8/V8-1 -> -0.0052353802 | X9: =X8/W8-1 -> -0.033241198 | Y9: =Y8/X8-1 -> 0.0063573075 | Z9: =Z8/Y8-1 -> 0.0067696116 | AA9: =AA8/Z8-1 -> -0.0050711762 | ... AW9: =AW8/AV8-1 -> -0.00068376888 | BB9: =BB8/BA8-1 -> 0.0081597775 | BC9: =BC8/BB8-1 -> -0.029234368 | BD9: =BD8/BC8-1 -> 0.0041781106 | BE9: =BE8/BD8-1 -> 0.034491865 | BF9: =BF8/BE8-1 -> -0.00081233335 | BG9: =BG8/BF8-1 -> -0.0057336097 | BH9: =BH8/BG8-1 -> 0.023490289 | BI9: =BI8/BH8-1 -> 0.019134147 | ... BP9: =BP8/BO8-1 -> -0.01804749 | BQ9: =BQ8/$BP8-1 -> -0.22413696 | BR9: =BR8/$BP8-1 -> -0.091702494 | BS9: =BS8/$BP8-1 -> -0.091957679
A10: Hoteles y restaurantes | B10: ='Empleo Población'!B41-'Empleo Informales'!B36 -> 140.09215 | C10: ='Empleo Población'!C41-'Empleo Informales'!C36 -> 146.027 | D10: ='Empleo Población'!D41-'Empleo Informales'!D36 -> 198.45703 | E10: ='Empleo Población'!E41-'Empleo Informales'!E36 -> 179.53188 | F10: ='Empleo Población'!F41-'Empleo Informales'!F36 -> 208.70856 | G10: ='Empleo Población'!G41-'Empleo Informales'!G36 -> 177.20351 | H10: ='Empleo Población'!H41-'Empleo Informales'!H36 -> 197.03357 | I10: ='Empleo Población'!I41-'Empleo Informales'!I36 -> 188.61541 | ... Q10: ='Empleo Población'!Q41-'Empleo Informales'!Q36 -> 227.64602 | S10: ='Empleo Población'!S41-'Empleo Informales'!S36 -> 226.13159 | T10: ='Empleo Población'!T41-'Empleo Informales'!T36 -> 258.73783 | U10: ='Empleo Población'!U41-'Empleo Informales'!U36 -> 236.03897 | V10: ='Empleo Población'!V41-'Empleo Informales'!V36 -> 220.48158 | W10: ='Empleo Población'!W41-'Empleo Informales'!W36 -> 277.37775 | X10: ='Empleo Población'!X41-'Empleo Informales'!X36 -> 261.80601 | Y10: ='Empleo Población'!Y41-'Empleo Informales'!Y36 -> 259.61594 | Z10: ='Empleo Población'!Z41-'Empleo Informales'!Z36 -> 225.30127 | ... AW10: ='Empleo Población'!AW41-'Empleo Informales'!AW36 -> 241.11554 | BA10: ='Empleo Población'!BA41-'Empleo Informales'!BA36 -> 265.28041 | BB10: ='Empleo Población'!BB41-'Empleo Informales'!BB36 -> 280.51729 | BC10: ='Empleo Población'!BC41-'Empleo Informales'!BC36 -> 282.24771 | BD10: ='Empleo Población'!BD41-'Empleo Informales'!BD36 -> 298.5793 | BE10: ='Empleo Población'!BE41-'Empleo Informales'!BE36 -> 307.16566 | BF10: ='Empleo Población'!BF41-'Empleo Informales'!BF36 -> 334.09967 | BG10: ='Empleo Población'!BG41-'Empleo Informales'!BG36 -> 293.70699 | BH10: ='Empleo Población'!BH41-'Empleo Informales'!BH36 -> 334.88252 | ... BS10: ='Empleo Población'!BS41-'Empleo Informales'!BS36 -> 214.049
C11: =C10/B10-1 -> 0.042363872 | D11: =D10/C10-1 -> 0.35904342 | E11: =E10/D10-1 -> -0.095361436 | F11: =F10/E10-1 -> 0.16251527 | G11: =G10/F10-1 -> -0.15095234 | H11: =H10/G10-1 -> 0.11190559 | I11: =I10/H10-1 -> -0.0427245 | J11: =J10/I10-1 -> 0.036337551 | ... Q11: =Q10/P10-1 -> -0.18169483 | T11: =T10/S10-1 -> 0.14419143 | U11: =U10/T10-1 -> -0.087729201 | V11: =V10/U10-1 -> -0.065910245 | W11: =W10/V10-1 -> 0.25805405 | X11: =X10/W10-1 -> -0.056139089 | Y11: =Y10/X10-1 -> -0.0083652493 | Z11: =Z10/Y10-1 -> -0.13217475 | AA11: =AA10/Z10-1 -> 0.074341092 | ... AW11: =AW10/AV10-1 -> -0.16998489 | BB11: =BB10/BA10-1 -> 0.057436866 | BC11: =BC10/BB10-1 -> 0.00616869 | BD11: =BD10/BC10-1 -> 0.057862624 | BE11: =BE10/BD10-1 -> 0.028757363 | BF11: =BF10/BE10-1 -> 0.087685616 | BG11: =BG10/BF10-1 -> -0.12090008 | BH11: =BH10/BG10-1 -> 0.14019255 | BI11: =BI10/BH10-1 -> -0.093295282 | ... BP11: =BP10/BO10-1 -> -0.067161729 | BQ11: =BQ10/$BP10-1 -> -0.29479681 | BR11: =BR10/$BP10-1 -> 0.038557227 | BS11: =BS10/$BP10-1 -> -0.26139826
A12: Transporte, almacenaje y comunicaciones | B12: ='Empleo Población'!B43-'Empleo Informales'!B38 -> 394.57192 | C12: ='Empleo Población'!C43-'Empleo Informales'!C38 -> 403.51507 | D12: ='Empleo Población'!D43-'Empleo Informales'!D38 -> 373.14084 | E12: ='Empleo Población'!E43-'Empleo Informales'!E38 -> 368.81198 | F12: ='Empleo Población'!F43-'Empleo Informales'!F38 -> 400.25142 | G12: ='Empleo Población'!G43-'Empleo Informales'!G38 -> 410.23363 | H12: ='Empleo Población'!H43-'Empleo Informales'!H38 -> 397.9986 | I12: ='Empleo Población'!I43-'Empleo Informales'!I38 -> 403.75236 | ... Q12: ='Empleo Población'!Q43-'Empleo Informales'!Q38 -> 490.8774 | S12: ='Empleo Población'!S43-'Empleo Informales'!S38 -> 486.85383 | T12: ='Empleo Población'!T43-'Empleo Informales'!T38 -> 496.64021 | U12: ='Empleo Población'!U43-'Empleo Informales'!U38 -> 557.83084 | V12: ='Empleo Población'!V43-'Empleo Informales'!V38 -> 527.15289 | W12: ='Empleo Población'!W43-'Empleo Informales'!W38 -> 491.02901 | X12: ='Empleo Población'!X43-'Empleo Informales'!X38 -> 514.7077 | Y12: ='Empleo Población'!Y43-'Empleo Informales'!Y38 -> 516.61382 | Z12: ='Empleo Población'!Z43-'Empleo Informales'!Z38 -> 533.67952 | ... AW12: ='Empleo Población'!AW43-'Empleo Informales'!AW38 -> 735.87169 | BA12: ='Empleo Población'!BA43-'Empleo Informales'!BA38 -> 621.31028 | BB12: ='Empleo Población'!BB43-'Empleo Informales'!BB38 -> 595.10106 | BC12: ='Empleo Población'!BC43-'Empleo Informales'!BC38 -> 622.33123 | BD12: ='Empleo Población'!BD43-'Empleo Informales'!BD38 -> 625.15209 | BE12: ='Empleo Población'!BE43-'Empleo Informales'!BE38 -> 614.79427 | BF12: ='Empleo Población'!BF43-'Empleo Informales'!BF38 -> 607.00747 | BG12: ='Empleo Población'!BG43-'Empleo Informales'!BG38 -> 653.29426 | BH12: ='Empleo Población'!BH43-'Empleo Informales'!BH38 -> 646.02065 | ... BS12: ='Empleo Población'!BS43-'Empleo Informales'!BS38 -> 642.825
C13: =C12/B12-1 -> 0.022665443 | D13: =D12/C12-1 -> -0.07527408 | E13: =E12/D12-1 -> -0.011601148 | F13: =F12/E12-1 -> 0.085245165 | G13: =G12/F12-1 -> 0.024939861 | H13: =H12/G12-1 -> -0.02982455 | I13: =I12/H12-1 -> 0.014456738 | J13: =J12/I12-1 -> 0.042176653 | ... Q13: =Q12/P12-1 -> 0.04425812 | T13: =T12/S12-1 -> 0.020101258 | U13: =U12/T12-1 -> 0.12320918 | V13: =V12/U12-1 -> -0.054995081 | W13: =W12/V12-1 -> -0.068526385 | X13: =X12/W12-1 -> 0.048222592 | Y13: =Y12/X12-1 -> 0.0037033126 | Z13: =Z12/Y12-1 -> 0.033033773 | AA13: =AA12/Z12-1 -> -0.062101645 | ... AW13: =AW12/AV12-1 -> 0.071259067 | BB13: =BB12/BA12-1 -> -0.042183776 | BC13: =BC12/BB12-1 -> 0.045757212 | BD13: =BD12/BC12-1 -> 0.0045327341 | BE13: =BE12/BD12-1 -> -0.016568477 | BF13: =BF12/BE12-1 -> -0.012665698 | BG13: =BG12/BF12-1 -> 0.076254063 | BH13: =BH12/BG12-1 -> -0.011133735 | BI13: =BI12/BH12-1 -> 0.00099306875 | ... BP13: =BP12/BO12-1 -> -0.036707985 | BQ13: =BQ12/$BP12-1 -> -0.16132562 | BR13: =BR12/$BP12-1 -> -0.075212622 | BS13: =BS12/$BP12-1 -> -0.076806749
A14: Serv financieros, inmobiliarios, alquileres y empresariales | B14: ='Empleo Población'!B45-'Empleo Informales'!B40 -> 624.3635 | C14: ='Empleo Población'!C45-'Empleo Informales'!C40 -> 673.90435 | D14: ='Empleo Población'!D45-'Empleo Informales'!D40 -> 668.11705 | E14: ='Empleo Población'!E45-'Empleo Informales'!E40 -> 642.18657 | F14: ='Empleo Población'!F45-'Empleo Informales'!F40 -> 616.11367 | G14: ='Empleo Población'!G45-'Empleo Informales'!G40 -> 673.50444 | H14: ='Empleo Población'!H45-'Empleo Informales'!H40 -> 727.19532 | I14: ='Empleo Población'!I45-'Empleo Informales'!I40 -> 740.08788 | ... Q14: ='Empleo Población'!Q45-'Empleo Informales'!Q40 -> 852.56738 | S14: ='Empleo Población'!S45-'Empleo Informales'!S40 -> 887.0803 | T14: ='Empleo Población'!T45-'Empleo Informales'!T40 -> 852.82359 | U14: ='Empleo Población'!U45-'Empleo Informales'!U40 -> 942.57318 | V14: ='Empleo Población'!V45-'Empleo Informales'!V40 -> 845.90472 | W14: ='Empleo Población'!W45-'Empleo Informales'!W40 -> 813.69806 | X14: ='Empleo Población'!X45-'Empleo Informales'!X40 -> 927.97196 | Y14: ='Empleo Población'!Y45-'Empleo Informales'!Y40 -> 1004.7544 | Z14: ='Empleo Población'!Z45-'Empleo Informales'!Z40 -> 904.38611 | ... AW14: ='Empleo Población'!AW45-'Empleo Informales'!AW40 -> 866.90992 | BA14: ='Empleo Población'!BA45-'Empleo Informales'!BA40 -> 951.81652 | BB14: ='Empleo Población'!BB45-'Empleo Informales'!BB40 -> 978.31976 | BC14: ='Empleo Población'!BC45-'Empleo Informales'!BC40 -> 1060.7607 | BD14: ='Empleo Población'!BD45-'Empleo Informales'!BD40 -> 1028.9169 | BE14: ='Empleo Población'!BE45-'Empleo Informales'!BE40 -> 981.09014 | BF14: ='Empleo Población'!BF45-'Empleo Informales'!BF40 -> 1016.7616 | BG14: ='Empleo Población'!BG45-'Empleo Informales'!BG40 -> 1082.421 | BH14: ='Empleo Población'!BH45-'Empleo Informales'!BH40 -> 1054.3203 | ... BS14: ='Empleo Población'!BS45-'Empleo Informales'!BS40 -> 1084.12
