Workbook

Sheet Tabla 1
A1: AÑO | B1: POBREZA
B2: Incidencia (FGT0) | F2: Brecha (FGT1) | J2: Severidad (FGT2)
B3: Total nacional | C3: Principales ciudades | D3: Resto urbano | E3: Rural | F3: Total nacional | G3: Principales ciudades | H3: Resto urbano | I3: Rural | J3: Total nacional | K3: Principales ciudades | L3: Resto urbano | M3: Rural
A4: 2002 | B4: 49.368687 | C4: 35.907803 | D4: 59.349861 | E4: 60.916786 | F4: 21.707022 | G4: 13.825745 | H4: 27.427788 | I4: 28.608437 | J4: 12.646281 | K4: 7.4270291 | L4: 16.290251 | M4: 17.380991
A5: 2003 | B5: 47.694141 | C5: 36.431412 | D5: 57.020992 | E5: 56.34063 | F5: 20.340767 | G5: 14.021665 | H5: 25.613695 | I5: 25.145542 | J5: 11.536758 | K5: 7.4626689 | L5: 14.830616 | M5: 14.757377
A6: 2004 | B6: 47.356251 | C6: 34.22744 | D6: 57.594173 | E6: 58.292534 | F6: 19.819868 | G6: 12.871613 | H6: 24.994251 | I6: 25.896906 | J6: 11.065257 | K6: 6.7913513 | L6: 14.047096 | M6: 15.04149
A7: 2005 | B7: 44.952667 | C7: 32.2099 | D7: 54.30801 | E7: 56.387482 | F7: 18.380169 | G7: 11.618706 | H7: 23.11046 | I7: 24.730082 | J7: 10.121404 | K7: 5.9389281 | L7: 12.90586 | M7: 14.220386
A8: 2008 | B8: 42.004955 | C8: 26.928564 | D8: 52.141876 | E8: 57.095619 | F8: 18.363205 | G8: 9.6745787 | H8: 24.377932 | I8: 26.841516 | J8: 10.821671 | K8: 5.0564618 | L8: 14.745811 | M8: 16.531895
A9: 2009 | B9: 40.217781 | C9: 25.561539 | D9: 50.66526 | E9: 54.256287 | F9: 16.738041 | G9: 9.1323996 | H9: 22.140453 | I9: 24.04767 | J9: 9.5029335 | K9: 4.7965655 | L9: 12.797422 | M9: 14.088326
A10: 2010 | B10: 37.174511 | C10: 23.22587 | D10: 47.352413 | E10: 50.341492 | F10: 15.118712 | G10: 8.2836952 | H10: 19.826813 | I10: 21.933365 | J10: 8.4541292 | K10: 4.3747501 | L10: 11.104407 | M10: 12.728765
A11: 2011 | B11: 34.039177 | C11: 20.597191 | D11: 43.783295 | E11: 46.909653 | F11: 13.368128 | G11: 6.8817616 | H11: 18.073257 | I11: 19.574564 | J11: 7.2484851 | K11: 3.4479198 | L11: 9.9877338 | M11: 10.908216
A12: 2012 | B12: 32.734791 | C12: 18.941196 | D12: 42.158108 | E12: 46.794525 | F12: 12.888946 | G12: 6.369525 | H12: 17.377151 | I12: 19.488533 | J12: 7.0461273 | K12: 3.205198 | L12: 9.6195011 | M12: 11.028374
A13: 2013 | B13: 30.571781 | C13: 17.501566 | D13: 40.41188 | E13: 42.761982 | F13: 11.79701 | G13: 5.9308577 | H13: 16.219566 | I13: 17.259958 | J13: 6.4046993 | K13: 3.0454993 | L13: 8.9180202 | M13: 9.5587978
A14: 2014 | B14: 28.53315 | C14: 15.884819 | D14: 37.296734 | E14: 41.428699 | F14: 10.8354 | G14: 5.2488384 | H14: 14.628272 | I14: 16.636728 | J14: 5.8237042 | K14: 2.6739705 | L14: 7.9056406 | M14: 9.1711473
A15: 2015 | B15: 27.849176 | C15: 15.351085 | D15: 36.779545 | E15: 40.294449 | F15: 10.30078 | G15: 5.1123586 | H15: 13.869401 | I15: 15.657194 | J15: 5.4340925 | K15: 2.6394188 | L15: 7.2382007 | M15: 8.4809322
... A18: 2018 | B18: 27.014765 | C18: 16.189911 | D18: 36.087666 | E18: 36.065628 | F18: 9.8325825 | G18: 5.3376679 | H18: 13.44041 | I18: 13.815189 | J18: 5.1967907 | K18: 2.7629483 | L18: 7.0490499 | M18: 7.4955478

Sheet Tabla 2
A1: AÑO | B1: INDIGENCIA
B2: Incidencia (FGT0) | F2: Brecha (FGT1) | J2: Severidad (FGT2)
B3: Total nacional | C3: Principales ciudades | D3: Resto urbano | E3: Rural | F3: Total nacional | G3: Principales ciudades | H3: Resto urbano | I3: Rural | J3: Total nacional | K3: Principales ciudades | L3: Resto urbano | M3: Rural
A4: 2002 | B4: 17.637814 | C4: 7.4407234 | D4: 19.552263 | E4: 32.807678 | F4: 6.7014413 | G4: 2.7041831 | H4: 6.9257145 | I4: 13.246451 | J4: 3.6983347 | K4: 1.5567216 | L4: 3.6877034 | M4: 7.353703
A5: 2003 | B5: 15.56423 | C5: 7.3150067 | D5: 16.638546 | E5: 28.586454 | F5: 5.7371449 | G5: 2.5989482 | H5: 6.0322361 | I5: 10.823102 | J5: 3.112448 | K5: 1.4516253 | L5: 3.2489853 | M5: 5.8268933
A6: 2004 | B6: 14.843343 | C6: 6.5363078 | D6: 15.176298 | E6: 29.047745 | F6: 5.3722749 | G6: 2.4179981 | H6: 5.1589098 | I6: 10.817177 | J6: 2.8364866 | K6: 1.3803052 | L6: 2.6081755 | M6: 5.6662951
A7: 2005 | B7: 13.79723 | C7: 5.6362271 | D7: 14.251158 | E7: 27.811903 | F7: 4.8323107 | G7: 1.9343753 | H7: 4.6525512 | I7: 10.22084 | J7: 2.506314 | K7: 1.0641171 | L7: 2.2804217 | M7: 5.3528457
A8: 2008 | B8: 16.413343 | C8: 5.5752292 | D8: 19.194359 | E8: 32.962204 | F8: 6.7177672 | G8: 2.0906219 | H8: 7.6234174 | I8: 14.139317 | J8: 3.9523299 | K8: 1.2543527 | L8: 4.4473276 | M8: 8.3214855
A9: 2009 | B9: 14.427792 | C9: 5.2337637 | D9: 16.445438 | E9: 29.048914 | F9: 5.4795661 | G9: 1.9772407 | H9: 5.9826708 | I9: 11.389569 | J9: 3.0474379 | K9: 1.1929848 | L9: 3.226625 | M9: 6.288516
A10: 2010 | B10: 12.278517 | C10: 4.6380692 | D10: 13.249061 | E10: 25.471567 | F10: 4.6093907 | G10: 1.8083382 | H10: 4.6438189 | I10: 9.8635206 | J10: 2.5390058 | K10: 1.0946975 | L10: 2.420923 | M10: 5.4246321
A11: 2011 | B11: 10.621201 | C11: 3.4709594 | D11: 11.892561 | E11: 22.61034 | F11: 3.7947774 | G11: 1.2857649 | H11: 4.0746164 | I11: 8.2203617 | J11: 2.0224745 | K11: 0.75957298 | L11: 2.1351266 | M11: 4.2871547
A12: 2012 | B12: 10.396332 | C12: 3.3154364 | D12: 11.36407 | E12: 22.75181 | F12: 3.7822487 | G12: 1.2282641 | H12: 3.9957082 | I12: 8.4187346 | J12: 2.0719452 | K12: 0.72233832 | L12: 2.1801605 | M12: 4.5280976
A13: 2013 | B13: 9.0640411 | C13: 3.0035658 | D13: 10.338158 | E13: 19.130285 | F13: 3.3075383 | G13: 1.2313378 | H13: 3.6075971 | I13: 6.939146 | J13: 1.8294617 | K13: 0.77509612 | L13: 1.9603776 | M13: 3.7025249
A14: 2014 | B14: 8.0824814 | C14: 2.6593378 | D14: 8.5913525 | E14: 18.016718 | F14: 2.9789026 | G14: 1.0889528 | H14: 3.0546944 | I14: 6.5786514 | J14: 1.6688943 | K14: 0.70494425 | L14: 1.702387 | M14: 3.5119131
A15: 2015 | B15: 7.9416318 | C15: 2.7217386 | D15: 8.1169701 | E15: 18.006321 | F15: 2.8532488 | G15: 1.176249 | H15: 2.7184772 | I15: 6.3484025 | J15: 1.5720376 | K15: 0.78596514 | L15: 1.451849 | M15: 3.2884142
... A18: 2018 | B18: 7.2499385 | C18: 2.8528001 | D18: 7.7751117 | E18: 15.36821 | F18: 2.7252879 | G18: 1.2546458 | H18: 2.7567813 | I18: 5.6430831 | J18: 1.5609756 | K18: 0.85290676 | L18: 1.5179766 | M18: 3.0475492

Sheet Tabla 3
A1: AÑO | B1: POBREZA (FGT0) | F1: INDIGENCIA (FGT0)
B2: Total nacional | C2: Principales ciudades | D2: Resto urbano | E2: Rural | F2: Total Nacional | G2: Principales ciudades | H2: Resto urbano | I2: Rural
A3: 2002 | B3: 49.368687 | C3: 35.907803 | D3: 59.349861 | E3: 60.916786 | F3: 17.637814 | G3: 7.4407234 | H3: 19.552263 | I3: 32.807678
A4: 2003 | B4: 47.694141 | C4: 36.431412 | D4: 57.020992 | E4: 56.34063 | F4: 15.56423 | G4: 7.3150067 | H4: 16.638546 | I4: 28.586454
A5: 2004 | B5: 47.356251 | C5: 34.22744 | D5: 57.594173 | E5: 58.292534 | F5: 14.843343 | G5: 6.5363078 | H5: 15.176298 | I5: 29.047745
A6: 2005 | B6: 44.952667 | C6: 32.2099 | D6: 54.30801 | E6: 56.387482 | F6: 13.79723 | G6: 5.6362271 | H6: 14.251158 | I6: 27.811903
A7: 2008 | B7: 42.004955 | C7: 26.928564 | D7: 52.141876 | E7: 57.095619 | F7: 16.413343 | G7: 5.5752292 | H7: 19.194359 | I7: 32.962204
A8: 2009 | B8: 40.217781 | C8: 25.561539 | D8: 50.66526 | E8: 54.256287 | F8: 14.427792 | G8: 5.2337637 | H8: 16.445438 | I8: 29.048914
A9: 2010 | B9: 37.174511 | C9: 23.22587 | D9: 47.352413 | E9: 50.341492 | F9: 12.278517 | G9: 4.6380692 | H9: 13.249061 | I9: 25.471567
A10: 2011 | B10: 34.039177 | C10: 20.597191 | D10: 43.783295 | E10: 46.909653 | F10: 10.621201 | G10: 3.4709594 | H10: 11.892561 | I10: 22.61034
A11: 2012 | B11: 32.734791 | C11: 18.941196 | D11: 42.158108 | E11: 46.794525 | F11: 10.396332 | G11: 3.3154364 | H11: 11.36407 | I11: 22.75181
A12: 2013 | B12: 30.571781 | C12: 17.501566 | D12: 40.41188 | E12: 42.761982 | F12: 9.0640411 | G12: 3.0035658 | H12: 10.338158 | I12: 19.130285
A13: 2014 | B13: 28.53315 | C13: 15.884819 | D13: 37.296734 | E13: 41.428699 | F13: 8.0824814 | G13: 2.6593378 | H13: 8.5913525 | I13: 18.016718
A14: 2015 | B14: 27.849176 | C14: 15.351085 | D14: 36.779545 | E14: 40.294449 | F14: 7.9416318 | G14: 2.7217386 | H14: 8.1169701 | I14: 18.006321
... A17: 2018 | B17: 27.014765 | C17: 16.189911 | D17: 36.087666 | E17: 36.065628 | F17: 7.2499385 | G17: 2.8528001 | H17: 7.7751117 | I17: 15.36821

Sheet Tabla 4
A1: AÑO | B1: POBREZA (FGT1) | F1: INDIGENCIA (FGT1)
B2: Total nacional | C2: Principales ciudades | D2: Resto urbano | E2: Rural | F2: Total Nacional | G2: Principales ciudades | H2: Resto urbano | I2: Rural
A3: 2002 | B3: 21.707022 | C3: 13.825745 | D3: 27.427788 | E3: 28.608437 | F3: 6.7014413 | G3: 2.7041831 | H3: 6.9257145 | I3: 13.246451
A4: 2003 | B4: 20.340767 | C4: 14.021665 | D4: 25.613695 | E4: 25.145542 | F4: 5.7371449 | G4: 2.5989482 | H4: 6.0322361 | I4: 10.823102
A5: 2004 | B5: 19.819868 | C5: 12.871613 | D5: 24.994251 | E5: 25.896906 | F5: 5.3722749 | G5: 2.4179981 | H5: 5.1589098 | I5: 10.817177
A6: 2005 | B6: 18.380169 | C6: 11.618706 | D6: 23.11046 | E6: 24.730082 | F6: 4.8323107 | G6: 1.9343753 | H6: 4.6525512 | I6: 10.22084
A7: 2008 | B7: 18.363205 | C7: 9.6745787 | D7: 24.377932 | E7: 26.841516 | F7: 6.7177672 | G7: 2.0906219 | H7: 7.6234174 | I7: 14.139317
A8: 2009 | B8: 16.738041 | C8: 9.1323996 | D8: 22.140453 | E8: 24.04767 | F8: 5.4795661 | G8: 1.9772407 | H8: 5.9826708 | I8: 11.389569
A9: 2010 | B9: 15.118712 | C9: 8.2836952 | D9: 19.826813 | E9: 21.933365 | F9: 4.6093907 | G9: 1.8083382 | H9: 4.6438189 | I9: 9.8635206
A10: 2011 | B10: 13.368128 | C10: 6.8817616 | D10: 18.073257 | E10: 19.574564 | F10: 3.7947774 | G10: 1.2857649 | H10: 4.0746164 | I10: 8.2203617
A11: 2012 | B11: 12.888946 | C11: 6.369525 | D11: 17.377151 | E11: 19.488533 | F11: 3.7822487 | G11: 1.2282641 | H11: 3.9957082 | I11: 8.4187346
A12: 2013 | B12: 11.79701 | C12: 5.9308577 | D12: 16.219566 | E12: 17.259958 | F12: 3.3075383 | G12: 1.2313378 | H12: 3.6075971 | I12: 6.939146
A13: 2014 | B13: 10.8354 | C13: 5.2488384 | D13: 14.628272 | E13: 16.636728 | F13: 2.9789026 | G13: 1.0889528 | H13: 3.0546944 | I13: 6.5786514
A14: 2015 | B14: 10.30078 | C14: 5.1123586 | D14: 13.869401 | E14: 15.657194 | F14: 2.8532488 | G14: 1.176249 | H14: 2.7184772 | I14: 6.3484025
... A17: 2018 | B17: 9.8325825 | C17: 5.3376679 | D17: 13.44041 | E17: 13.815189 | F17: 2.7252879 | G17: 1.2546458 | H17: 2.7567813 | I17: 5.6430831

Sheet Tabla 5
A1: AÑO | B1: POBREZA (FGT2) | F1: INDIGENCIA (FGT2)
B2: Total nacional | C2: Principales ciudades | D2: Resto urbano | E2: Rural | F2: Total Nacional | G2: Principales ciudades | H2: Resto urbano | I2: Rural
A3: 2002 | B3: 12.646281 | C3: 7.4270291 | D3: 16.290251 | E3: 17.380991 | F3: 3.6983347 | G3: 1.5567216 | H3: 3.6877034 | I3: 7.353703
A4: 2003 | B4: 11.536758 | C4: 7.4626689 | D4: 14.830616 | E4: 14.757377 | F4: 3.112448 | G4: 1.4516253 | H4: 3.2489853 | I4: 5.8268933
A5: 2004 | B5: 11.065257 | C5: 6.7913513 | D5: 14.047096 | E5: 15.04149 | F5: 2.8364866 | G5: 1.3803052 | H5: 2.6081755 | I5: 5.6662951
A6: 2005 | B6: 10.121404 | C6: 5.9389281 | D6: 12.90586 | E6: 14.220386 | F6: 2.506314 | G6: 1.0641171 | H6: 2.2804217 | I6: 5.3528457
A7: 2008 | B7: 10.821671 | C7: 5.0564618 | D7: 14.745811 | E7: 16.531895 | F7: 3.9523299 | G7: 1.2543527 | H7: 4.4473276 | I7: 8.3214855
A8: 2009 | B8: 9.5029335 | C8: 4.7965655 | D8: 12.797422 | E8: 14.088326 | F8: 3.0474379 | G8: 1.1929848 | H8: 3.226625 | I8: 6.288516
A9: 2010 | B9: 8.4541292 | C9: 4.3747501 | D9: 11.104407 | E9: 12.728765 | F9: 2.5390058 | G9: 1.0946975 | H9: 2.420923 | I9: 5.4246321
A10: 2011 | B10: 7.2484851 | C10: 3.4479198 | D10: 9.9877338 | E10: 10.908216 | F10: 2.0224745 | G10: 0.75957298 | H10: 2.1351266 | I10: 4.2871547
A11: 2012 | B11: 7.0461273 | C11: 3.205198 | D11: 9.6195011 | E11: 11.028374 | F11: 2.0719452 | G11: 0.72233832 | H11: 2.1801605 | I11: 4.5280976
A12: 2013 | B12: 6.4046993 | C12: 3.0454993 | D12: 8.9180202 | E12: 9.5587978 | F12: 1.8294617 | G12: 0.77509612 | H12: 1.9603776 | I12: 3.7025249
A13: 2014 | B13: 5.8237042 | C13: 2.6739705 | D13: 7.9056406 | E13: 9.1711473 | F13: 1.6688943 | G13: 0.70494425 | H13: 1.702387 | I13: 3.5119131
A14: 2015 | B14: 5.4340925 | C14: 2.6394188 | D14: 7.2382007 | E14: 8.4809322 | F14: 1.5720376 | G14: 0.78596514 | H14: 1.451849 | I14: 3.2884142
... A17: 2018 | B17: 5.1967907 | C17: 2.7629483 | D17: 7.0490499 | E17: 7.4955478 | F17: 1.5609756 | G17: 0.85290676 | H17: 1.5179766 | I17: 3.0475492

Sheet Tabla 6
A1: AÑO | B1: POBREZA (FGT0) | P1: POBREZA (FGT0)
B2: Barranquilla | C2: Bogotá | D2: Bucaramanga | E2: Cali | F2: Cartagena | G2: Cúcuta | H2: Ibagué | I2: Manizales | J2: Medellín | K2: Montería | L2: Pasto | M2: Pereira | N2: Villavicencio | P2: Ciudad | Q2: 2002 | R2: 2018
A3: 2002 | B3: 43.097088 | C3: 31.345976 | D3: 33.52282 | E3: 33.112995 | F3: 47.718971 | G3: 52.862793 | H3: 38.16066 | I3: 37.030666 | J3: 36.1395 | K3: 48.665123 | L3: 44.679497 | M3: 32.092312 | N3: 33.922077 | P3: Cúcuta | Q3: 52.862793 | R3: 36.188557
A4: 2003 | B4: 48.837101 | C4: 31.792337 | D4: 34.008984 | E4: 33.353092 | F4: 43.595036 | G4: 57.010399 | H4: 39.966877 | I4: 39.456783 | J4: 34.470146 | K4: 50.760235 | L4: 46.779312 | M4: 29.61698 | N4: 35.717373 | P4: Montería | Q4: 48.665123 | R4: 27.501991
A5: 2004 | B5: 45.905304 | C5: 28.666929 | D5: 31.318411 | E5: 31.602165 | F5: 44.992023 | G5: 55.249531 | H5: 42.984318 | I5: 40.49284 | J5: 31.604752 | K5: 50.637173 | L5: 46.152203 | M5: 29.629719 | N5: 32.346237 | P5: Cartagena | Q5: 47.718971 | R5: 25.930798
A6: 2005 | B6: 44.064323 | C6: 26.638157 | D6: 31.073042 | E6: 30.0975 | F6: 37.719124 | G6: 55.172913 | H6: 39.456856 | I6: 36.50716 | J6: 29.365074 | K6: 46.907452 | L6: 45.745422 | M6: 28.687859 | N6: 34.823673 | P6: Pasto | Q6: 44.679497 | R6: 25.438892
A7: 2008 | B7: 43.337368 | C7: 19.573092 | D7: 19.094011 | E7: 28.430832 | F7: 40.19894 | G7: 42.232906 | H7: 32.602684 | I7: 31.249466 | J7: 24.950214 | K7: 40.512745 | L7: 39.378342 | M7: 27.502146 | N7: 26.719851 | P7: Barranquilla | Q7: 43.097088 | R7: 21.087166
A8: 2009 | B8: 42.388611 | C8: 18.275114 | D8: 13.85709 | E8: 28.332504 | F8: 38.478054 | G8: 38.207577 | H8: 28.658379 | I8: 27.302036 | J8: 23.906239 | K8: 38.361816 | L8: 42.258263 | M8: 28.38448 | N8: 27.606306 | P8: Ibagué | Q8: 38.16066 | R8: 18.127588
A9: 2010 | B9: 39.542732 | C9: 15.50841 | D9: 10.845887 | E9: 26.111567 | F9: 34.222897 | G9: 39.224377 | H9: 26.646402 | I9: 23.88616 | J9: 22.023884 | K9: 39.48893 | L9: 42.647152 | M9: 26.647711 | N9: 25.34408 | P9: Manizales | Q9: 37.030666 | R9: 11.900731
A10: 2011 | B10: 34.812019 | C10: 13.09496 | D10: 10.711445 | E10: 25.142944 | F10: 33.380325 | G10: 33.863663 | H10: 22.013241 | I10: 19.308872 | J10: 19.168381 | K10: 37.233349 | L10: 39.959137 | M10: 21.50341 | N10: 22.952587 | P10: Medellín | Q10: 36.1395 | R10: 13.876122
A11: 2012 | B11: 30.410555 | C11: 11.556772 | D11: 10.413187 | E11: 23.120148 | F11: 32.706352 | G11: 32.375324 | H11: 21.342207 | I11: 17.638386 | J11: 17.693378 | K11: 36.872829 | L11: 36.752747 | M11: 21.851046 | N11: 21.644363 | P11: Villavicencio | Q11: 33.922077 | R11: 18.054688
A12: 2013 | B12: 29.071976 | C12: 10.191796 | D12: 10.32049 | E12: 21.930019 | F12: 29.167526 | G12: 31.343645 | H12: 18.583275 | I12: 16.230381 | J12: 16.131672 | K12: 34.776466 | L12: 30.507473 | M12: 23.993284 | N12: 19.54365 | P12: Bucaramanga | Q12: 33.52282 | R12: 14.491611
A13: 2014 | B13: 25.509123 | C13: 10.135043 | D13: 8.4339485 | E13: 19.066301 | F13: 26.583784 | G13: 33.059032 | H13: 16.448017 | I13: 15.700269 | J13: 14.679392 | K13: 20.931366 | L13: 26.855167 | M13: 18.133526 | N13: 17.109291 | P13: Cali | Q13: 33.112995 | R13: 15.711862
A14: 2015 | B14: 22.031775 | C14: 10.424039 | D14: 9.1028605 | E14: 16.537071 | F14: 26.154413 | G14: 32.869865 | H14: 17.456661 | I14: 13.894011 | J14: 14.293904 | K14: 25.201273 | L14: 25.317463 | M14: 17.662262 | N14: 16.583149 | P14: Pereira | Q14: 32.092312 | R14: 14.60987
A15: 2016 | B15: 21.682148 | C15: 11.596971 | D15: 10.632632 | E15: 15.430878 | F15: 29.129774 | G15: 33.373501 | H15: 17.29357 | I15: 14.631772 | J15: 14.074914 | K15: 30.989477 | L15: 23.038546 | M15: 16.370054 | N15: 19.781441 | P15: Bogotá | Q15: 31.345976 | R15: 12.420043
A16: 2017 | B16: 20.026363 | C16: 12.449298 | D16: 11.985432 | E16: 15.465808 | F16: 26.962999 | G16: 33.531418 | H16: 18.360502 | I16: 13.804939 | J16: 13.351928 | K16: 28.245369 | L16: 20.191628 | M16: 12.698195 | N16: 19.49556
A17: 2018 | B17: 21.087166 | C17: 12.420043 | D17: 14.491611 | E17: 15.711862 | F17: 25.930798 | G17: 36.188557 | H17: 18.127588 | I17: 11.900731 | J17: 13.876122 | K17: 27.501991 | L17: 25.438892 | M17: 14.60987 | N17: 18.054688
A19: AÑO | B19: POBREZA (FGT1) | P19: POBREZA (FGT1)
B20: Barranquilla | C20: Bogotá | D20: Bucaramanga | E20: Cali | F20: Cartagena | G20: Cúcuta | H20: Ibagué | I20: Manizales | J20: Medellín | K20: Montería | L20: Pasto | M20: Pereira | N20: Villavicencio | P20: Ciudad | Q20: 2002 | R20: 2018
A21: 2002 | B21: 16.27467 | C21: 12.543071 | D21: 12.048072 | E21: 12.233554 | F21: 17.890142 | G21: 20.424326 | H21: 14.639002 | I21: 14.094773 | J21: 14.063554 | K21: 18.828196 | L21: 18.489391 | M21: 10.501594 | N21: 12.761795 | P21: Cúcuta | Q21: 20.424326 | R21: 12.832698
A22: 2003 | B22: 19.36684 | C22: 12.658799 | D22: 12.006065 | E22: 12.038741 | F22: 15.877758 | G22: 23.216633 | H22: 15.884588 | I22: 15.413776 | J22: 13.065402 | K22: 20.282286 | L22: 19.052521 | M22: 9.2790575 | N22: 13.250601 | P22: Montería | Q22: 18.828196 | R22: 9.0409451
A23: 2004 | B23: 17.247526 | C23: 11.139953 | D23: 10.530184 | E23: 11.311297 | F23: 16.010931 | G23: 23.067144 | H23: 17.387203 | I23: 16.344889 | J23: 11.560973 | K23: 20.031652 | L23: 18.316132 | M23: 9.1131611 | N23: 11.392766 | P23: Pasto | Q23: 18.489391 | R23: 8.2633133
A24: 2005 | B24: 16.392799 | C24: 9.6132803 | D24: 10.83423 | E24: 10.45592 | F24: 12.339745 | G24: 21.533607 | H24: 15.142507 | I24: 14.012222 | J24: 10.311176 | K24: 18.40967 | L24: 18.475172 | M24: 9.2146282 | N24: 12.623903 | P24: Cartagena | Q24: 17.890142 | R24: 7.786808
A25: 2008 | B25: 16.208549 | C25: 6.5818367 | D25: 5.805819 | E25: 10.958691 | F25: 13.850716 | G25: 15.051824 | H25: 12.036057 | I25: 11.673295 | J25: 9.5357265 | K25: 14.038785 | L25: 15.37762 | M25: 9.2852135 | N25: 9.6751776 | P25: Barranquilla | Q25: 16.27467 | R25: 5.8592548
A26: 2009 | B26: 14.754171 | C26: 6.2411861 | D26: 3.7520139 | E26: 11.094965 | F26: 13.28916 | G26: 13.383304 | H26: 9.8398876 | I26: 10.596485 | J26: 9.2798624 | K26: 12.937914 | L26: 16.498932 | M26: 9.3803377 | N26: 9.8065968 | P26: Ibagué | Q26: 14.639002 | R26: 5.8541665
A27: 2010 | B27: 13.886645 | C27: 5.1114159 | D27: 2.9817922 | E27: 10.124674 | F27: 11.970845 | G27: 15.081912 | H27: 9.0061169 | I27: 8.4764853 | J27: 8.4415035 | K27: 13.662465 | L27: 17.347054 | M27: 8.8130484 | N27: 8.9845743 | P27: Manizales | Q27: 14.094773 | R27: 4.0452361
A28: 2011 | B28: 11.518625 | C28: 4.0939765 | D28: 2.9854755 | E28: 9.0670319 | F28: 10.79492 | G28: 11.558115 | H28: 6.6727386 | I28: 6.0342379 | J28: 6.8801427 | K28: 13.165154 | L28: 14.970553 | M28: 6.3771992 | N28: 7.8343005 | P28: Medellín | Q28: 14.063554 | R28: 4.8362389
A29: 2012 | B29: 9.360899 | C29: 3.7265604 | D29: 2.966033 | E29: 8.567543 | F29: 11.162038 | G29: 11.01073 | H29: 6.7519078 | I29: 5.6424117 | J29: 6.2344713 | K29: 13.043674 | L29: 13.703747 | M29: 6.8239808 | N29: 7.6488628 | P29: Villavicencio | Q29: 12.761795 | R29: 6.4537926
A30: 2013 | B30: 9.2140942 | C30: 3.241945 | D30: 2.9154043 | E30: 7.9251661 | F30: 10.333026 | G30: 11.394206 | H30: 5.7750106 | I30: 5.3131146 | J30: 5.7574515 | K30: 12.329181 | L30: 10.08035 | M30: 8.7750778 | N30: 6.6331291 | P30: Bogotá | Q30: 12.543071 | R30: 4.2878966
A31: 2014 | B31: 7.8015437 | C31: 3.4069724 | D31: 2.3081768 | E31: 6.4895725 | F31: 8.6552601 | G31: 11.774523 | H31: 5.1817284 | I31: 5.2146239 | J31: 5.1201425 | K31: 5.5850787 | L31: 8.7466354 | M31: 5.7128844 | N31: 5.6483254 | P31: Cali | Q31: 12.233554 | R31: 5.3859568
A32: 2015 | B32: 6.1012721 | C32: 3.57145 | D32: 2.749974 | E32: 5.8150177 | F32: 8.0778446 | G32: 11.84818 | H32: 5.4468827 | I32: 4.3486943 | J32: 5.3473396 | K32: 6.8639793 | L32: 8.1351233 | M32: 5.2618847 | N32: 5.7594495 | P32: Bucaramanga | Q32: 12.048072 | R32: 4.0637708
A33: 2016 | B33: 5.943675 | C33: 3.8824029 | D33: 2.8715434 | E33: 5.0442076 | F33: 9.7445736 | G33: 12.055407 | H33: 5.1898332 | I33: 4.8104906 | J33: 5.0393076 | K33: 9.5496397 | L33: 6.8961353 | M33: 4.4485588 | N33: 7.1539707 | P33: Pereira | Q33: 10.501594 | R33: 4.1872578
A34: 2017 | B34: 5.5666833 | C34: 4.1392064 | D34: 3.3853393 | E34: 5.2094417 | F34: 8.4730816 | G34: 11.400387 | H34: 5.6237392 | I34: 4.342979 | J34: 4.5145316 | K34: 9.8552456 | L34: 6.0605702 | M34: 3.1828229 | N34: 7.0440598
A35: 2018 | B35: 5.8592548 | C35: 4.2878966 | D35: 4.0637708 | E35: 5.3859568 | F35: 7.786808 | G35: 12.832698 | H35: 5.8541665 | I35: 4.0452361 | J35: 4.8362389 | K35: 9.0409451 | L35: 8.2633133 | M35: 4.1872578 | N35: 6.4537926
A37: AÑO | B37: POBREZA (FGT2) | P37: POBREZA (FGT2)
B38: Barranquilla | C38: Bogotá | D38: Bucaramanga | E38: Cali | F38: Cartagena | G38: Cúcuta | H38: Ibagué | I38: Manizales | J38: Medellín | K38: Montería | L38: Pasto | M38: Pereira | N38: Villavicencio | P38: Ciudad | Q38: 2002 | R38: 2018
A39: 2002 | B39: 8.2844353 | C39: 7.0165386 | D39: 6.261343 | E39: 6.4249234 | F39: 9.0022964 | G39: 10.611624 | H39: 7.9118462 | I39: 7.645402 | J39: 7.7511134 | K39: 9.6982765 | L39: 10.009566 | M39: 4.931016 | N39: 6.8188043 | P39: Cúcuta | Q39: 10.611624 | R39: 6.7785187
A40: 2003 | B40: 10.135808 | C40: 6.9862962 | D40: 5.9544973 | E40: 6.1354647 | F40: 7.8289399 | G40: 12.492064 | H40: 8.8501797 | I40: 8.2837772 | J40: 7.0318213 | K40: 10.605284 | L40: 10.144947 | M40: 4.2926974 | N40: 7.0144153 | P40: Pasto | Q40: 10.009566 | R40: 3.9471009
A41: 2004 | B41: 8.7158575 | C41: 6.1257 | D41: 5.1501842 | E41: 5.7864051 | F41: 7.7386866 | G41: 12.664132 | H41: 9.6664648 | I41: 9.0868969 | J41: 6.1140614 | K41: 10.408613 | L41: 9.6177607 | M41: 4.185143 | N41: 5.773397 | P41: Montería | Q41: 9.6982765 | R41: 4.3111792
A42: 2005 | B42: 8.2463961 | C42: 4.9880633 | D42: 5.4699969 | E42: 5.2644835 | F42: 5.6106491 | G42: 11.353683 | H42: 8.1247683 | I42: 7.630424 | J42: 5.2283192 | K42: 9.6087646 | L42: 9.915226 | M42: 4.3258166 | N42: 6.642796 | P42: Cartagena | Q42: 9.0022964 | R42: 3.6136944
...

Sheet Tabla 7
A1: AÑO | B1: INDIGENCIA (FGT0) | P1: INDIGENCIA (FGT0)
B2: Barranquilla | C2: Bogotá | D2: Bucaramanga | E2: Cali | F2: Cartagena | G2: Cúcuta | H2: Ibagué | I2: Manizales | J2: Medellín | K2: Montería | L2: Pasto | M2: Pereira | N2: Villavicencio | P2: Ciudad | Q2: 2002 | R2: 2018
A3: 2002 | B3: 8.4546175 | C3: 6.9875469 | D3: 6.0661988 | E3: 6.0818405 | F3: 9.4850836 | G3: 11.069615 | H3: 8.4059286 | I3: 7.2938309 | J3: 7.8771105 | K3: 9.5317335 | L3: 10.810506 | M3: 4.0400052 | N3: 7.4426756 | P3: Cúcuta | Q3: 11.069615 | R3: 6.9796109
A4: 2003 | B4: 10.710732 | C4: 6.942553 | D4: 5.1872673 | E4: 5.3221188 | F4: 7.4786296 | G4: 13.220535 | H4: 9.5766335 | I4: 8.3108492 | J4: 6.6549597 | K4: 11.231053 | L4: 11.283892 | M4: 3.0446465 | N4: 6.7933173 | P4: Pasto | Q4: 10.810506 | R4: 4.1619906
A5: 2004 | B5: 8.5476532 | C5: 6.0144839 | D5: 4.6998143 | E5: 5.264246 | F5: 6.9415255 | G5: 13.179191 | H5: 10.394216 | I5: 9.0224924 | J5: 5.61166 | K5: 9.8716965 | L5: 10.365441 | M5: 3.2720473 | N5: 5.3324709 | P5: Montería | Q5: 9.5317335 | R5: 3.9328153
A6: 2005 | B6: 7.8294506 | C6: 4.6634259 | D6: 4.8251748 | E6: 5.0233145 | F6: 4.6530643 | G6: 11.255477 | H6: 8.5270596 | I6: 7.5625286 | J6: 4.9620466 | K6: 9.2549582 | L6: 11.65069 | M6: 3.6930897 | N6: 6.241859 | P6: Cartagena | Q6: 9.4850836 | R6: 3.3911419
A7: 2008 | B7: 10.034184 | C7: 3.3649273 | D7: 2.58411 | E7: 7.3777452 | F7: 6.8975463 | G7: 7.8750772 | H7: 7.2629266 | I7: 6.8489151 | J7: 6.1507025 | K7: 6.6170788 | L7: 10.064957 | M7: 4.7520046 | N7: 5.2306237 | P7: Barranquilla | Q7: 8.4546175 | R7: 2.2256844
A8: 2009 | B8: 8.2878675 | C8: 3.1890512 | D8: 1.7154657 | E8: 7.4337392 | F8: 6.8429804 | G8: 6.8458476 | H8: 5.0542855 | I8: 6.7459354 | J8: 6.2407813 | K8: 5.9042377 | L8: 10.54347 | M8: 4.6297073 | N8: 5.362937 | P8: Ibagué | Q8: 8.4059286 | R8: 2.9705465
A9: 2010 | B9: 7.431519 | C9: 2.5844669 | D9: 1.1710273 | E9: 6.3673539 | F9: 6.2362919 | G9: 8.3558283 | H9: 4.3221226 | I9: 4.7421541 | J9: 5.5760412 | K9: 6.691473 | L9: 11.455095 | M9: 3.7797887 | N9: 4.819551 | P9: Medellín | Q9: 7.8771105 | R9: 2.6862013
A10: 2011 | B10: 5.3618116 | C10: 2.0058658 | D10: 1.1233734 | E10: 5.2530932 | F10: 4.7214746 | G10: 5.6532259 | H10: 2.7223668 | I10: 2.3315783 | J10: 3.987144 | K10: 6.3915505 | L10: 8.5682259 | M10: 2.1988187 | N10: 3.9773827 | P10: Villavicencio | Q10: 7.4426756 | R10: 3.8829949
A11: 2012 | B11: 3.8181455 | C11: 2.0160193 | D11: 1.1533376 | E11: 5.2719617 | F11: 5.893877 | G11: 5.0988131 | H11: 2.7982931 | I11: 2.3980775 | J11: 3.5250864 | K11: 6.2869034 | L11: 8.0434895 | M11: 3.0421371 | N11: 3.8832207 | P11: Manizales | Q11: 7.2938309 | R11: 2.1334209
A12: 2013 | B12: 4.1553631 | C12: 1.5702063 | D12: 1.2342023 | E12: 4.3563766 | F12: 5.8287835 | G12: 5.9608827 | H12: 2.5145552 | I12: 2.5605075 | J12: 3.0203955 | K12: 6.4647121 | L12: 4.4466839 | M12: 5.0651073 | N12: 3.0579464 | P12: Bogotá | Q12: 6.9875469 | R12: 2.5256009
A13: 2014 | B13: 3.6301329 | C13: 1.9122049 | D13: 1.128463 | E13: 3.3293478 | F13: 4.2861285 | G13: 5.7277451 | H13: 2.2859848 | I13: 2.1793284 | J13: 2.7766669 | K13: 1.3682346 | L13: 4.0843482 | M13: 2.4651351 | N13: 2.7823286 | P13: Cali | Q13: 6.0818405 | R13: 3.428864
A14: 2015 | B14: 2.4301882 | C14: 1.9907209 | D14: 1.2843486 | E14: 3.3958893 | F14: 3.9696701 | G14: 6.8575082 | H14: 2.5587332 | I14: 1.7335906 | J14: 3.2608535 | K14: 2.1474452 | L14: 4.2330379 | M14: 2.1085908 | N14: 3.1404965 | P14: Bucaramanga | Q14: 6.0661988 | R14: 1.5500067
A15: 2016 | B15: 2.7946653 | C15: 2.3253326 | D15: 1.1922936 | E15: 3.1889536 | F15: 5.5186043 | G15: 7.0410647 | H15: 2.43223 | I15: 2.5409226 | J15: 2.9402945 | K15: 4.2668095 | L15: 3.1924686 | M15: 1.7546868 | N15: 4.6848998 | P15: Pereira | Q15: 4.0400052 | R15: 1.7405335
A16: 2017 | B16: 2.4110539 | C16: 2.4426885 | D16: 1.3947796 | E16: 3.4522614 | F16: 4.1372452 | G16: 5.3111458 | H16: 2.564888 | I16: 2.0691984 | J16: 2.4124582 | K16: 5.4868312 | L16: 2.9108775 | M16: 0.83062464 | N16: 4.5399928
A17: 2018 | B17: 2.2256844 | C17: 2.5256009 | D17: 1.5500067 | E17: 3.428864 | F17: 3.3911419 | G17: 6.9796109 | H17: 2.9705465 | I17: 2.1334209 | J17: 2.6862013 | K17: 3.9328153 | L17: 4.1619906 | M17: 1.7405335 | N17: 3.8829949
A19: AÑO | B19: INDIGENCIA (FGT1) | P19: INDIGENCIA (FGT1)
B20: Barranquilla | C20: Bogotá | D20: Bucaramanga | E20: Cali | F20: Cartagena | G20: Cúcuta | H20: Ibagué | I20: Manizales | J20: Medellín | K20: Montería | L20: Pasto | M20: Pereira | N20: Villavicencio | P20: Ciudad | Q20: 2002 | R20: 2018
A21: 2002 | B21: 2.4102759 | C21: 2.8358536 | D21: 2.1817839 | E21: 2.2488973 | F21: 2.5079703 | G21: 3.5154104 | H21: 2.9123108 | I21: 2.8040082 | J21: 3.0791337 | K21: 2.818537 | L21: 3.272177 | M21: 1.2597417 | N21: 2.6720512 | P21: Cúcuta | Q21: 3.5154104 | R21: 2.8344967
A22: 2003 | B22: 3.1135385 | C22: 2.7192183 | D22: 1.7507192 | E22: 1.894671 | F22: 2.0747511 | G22: 4.119554 | H22: 3.5535831 | I22: 2.841794 | J22: 2.6110518 | K22: 3.1027651 | L22: 3.2092199 | M22: 1.106017 | N22: 2.6183093 | P22: Pasto | Q22: 3.272177 | R22: 1.3381162
A23: 2004 | B23: 2.426158 | C23: 2.5305769 | D23: 1.5193269 | E23: 1.9417878 | F23: 1.8519346 | G23: 4.5585322 | H23: 3.7773476 | I23: 3.6129131 | J23: 2.3000891 | K23: 2.8667283 | L23: 2.896389 | M23: 1.0687602 | N23: 1.9008567 | P23: Medellín | Q23: 3.0791337 | R23: 1.1962758
A24: 2005 | B24: 2.288305 | C24: 1.7371953 | D24: 1.7744647 | E24: 1.7750273 | F24: 1.1495408 | G24: 3.6719925 | H24: 2.9863868 | I24: 2.933532 | J24: 1.7303689 | K24: 2.8318081 | L24: 3.3844638 | M24: 1.1050611 | N24: 2.518295 | P24: Ibagué | Q24: 2.9123108 | R24: 1.1256243
A25: 2008 | B25: 3.0394244 | C25: 1.3108158 | D25: 0.8772921 | E25: 3.1359699 | F25: 1.9205317 | G25: 2.6300797 | H25: 2.5225677 | I25: 2.8319726 | J25: 2.7703431 | K25: 1.8068058 | L25: 2.7846634 | M25: 1.5067878 | N25: 2.2491281 | P25: Bogotá | Q25: 2.8358536 | R25: 1.2858262
A26: 2009 | B26: 2.4713387 | C26: 1.3851379 | D26: 0.59100848 | E26: 2.9764938 | F26: 1.9790528 | G26: 2.4866447 | H26: 1.7274973 | I26: 2.6127677 | J26: 2.5686626 | K26: 1.6847538 | L26: 3.0651679 | M26: 1.5453047 | N26: 2.1734078 | P26: Montería | Q26: 2.818537 | R26: 1.2601551
A27: 2010 | B27: 2.251514 | C27: 1.0844729 | D27: 0.38381052 | E27: 2.8610802 | F27: 2.0565548 | G27: 3.2539389 | H27: 1.2632691 | I27: 1.8851469 | J27: 2.3988631 | K27: 2.010591 | L27: 3.6474209 | M27: 1.3491489 | N27: 2.0411692 | P27: Manizales | Q27: 2.8040082 | R27: 1.0235896
A28: 2011 | B28: 1.6587076 | C28: 0.73613507 | D28: 0.52773809 | E28: 2.1772938 | F28: 1.3418281 | G28: 2.1820221 | H28: 0.99112511 | I28: 0.83019185 | J28: 1.6204304 | K28: 2.0052688 | L28: 2.5262487 | M28: 0.77542806 | N28: 1.8714623 | P28: Villavicencio | Q28: 2.6720512 | R28: 1.9100323
A29: 2012 | B29: 1.2363653 | C29: 0.77949685 | D29: 0.47143343 | E29: 2.0649292 | F29: 2.0046556 | G29: 2.0182023 | H29: 0.93364483 | I29: 0.81426752 | J29: 1.3410579 | K29: 2.0446141 | L29: 2.3678401 | M29: 0.98142225 | N29: 1.8531485 | P29: Cartagena | Q29: 2.5079703 | R29: 1.0923841
A30: 2013 | B30: 1.3162903 | C30: 0.68966532 | D30: 0.58321083 | E30: 1.9686993 | F30: 2.1626749 | G30: 2.421042 | H30: 0.88637406 | I30: 0.84228057 | J30: 1.350131 | K30: 2.0158966 | L30: 1.3048937 | M30: 2.1910295 | N30: 1.5817761 | P30: Barranquilla | Q30: 2.4102759 | R30: 0.62925351
A31: 2014 | B31: 1.0541174 | C31: 0.82030994 | D31: 0.42734692 | E31: 1.5685624 | F31: 1.5619653 | G31: 2.3680234 | H31: 0.79887009 | I31: 0.80282378 | J31: 1.2147685 | K31: 0.39952743 | L31: 1.3945453 | M31: 1.0443081 | N31: 1.5023689 | P31: Cali | Q31: 2.2488973 | R31: 1.5424696
A32: 2015 | B32: 0.76747406 | C32: 0.97755325 | D32: 0.58279341 | E32: 1.537183 | F32: 1.4177064 | G32: 2.8376634 | H32: 0.77843916 | I32: 0.87974852 | J32: 1.4526764 | K32: 0.68591356 | L32: 1.4268335 | M32: 0.80755818 | N32: 1.4422629 | P32: Bucaramanga | Q32: 2.1817839 | R32: 0.7309112
A33: 2016 | B33: 0.81660867 | C33: 1.1058217 | D33: 0.49793619 | E33: 1.2891557 | F33: 2.015491 | G33: 2.8484387 | H33: 0.87942427 | I33: 1.0837166 | J33: 1.3750023 | K33: 1.3756548 | L33: 0.88832092 | M33: 0.59825033 | N33: 2.2816825 | P33: Pereira | Q33: 1.2597417 | R33: 0.6834653
A34: 2017 | B34: 0.64139915 | C34: 1.1956277 | D34: 0.69480181 | E34: 1.436909 | F34: 1.3918457 | G34: 2.0065994 | H34: 0.98119611 | I34: 0.88872093 | J34: 1.1541643 | K34: 2.2504356 | L34: 0.90810871 | M34: 0.26832226 | N34: 2.2666533
A35: 2018 | B35: 0.62925351 | C35: 1.2858262 | D35: 0.7309112 | E35: 1.5424696 | F35: 1.0923841 | G35: 2.8344967 | H35: 1.1256243 | I35: 1.0235896 | J35: 1.1962758 | K35: 1.2601551 | L35: 1.3381162 | M35: 0.6834653 | N35: 1.9100323
A37: AÑO | B37: INDIGENCIA (FGT2) | P37: INDIGENCIA (FGT2)
B38: Barranquilla | C38: Bogotá | D38: Bucaramanga | E38: Cali | F38: Cartagena | G38: Cúcuta | H38: Ibagué | I38: Manizales | J38: Medellín | K38: Montería | L38: Pasto | M38: Pereira | N38: Villavicencio | P38: Ciudad | Q38: 2002 | R38: 2018
A39: 2002 | B39: 1.1061652 | C39: 1.8061826 | D39: 1.250968 | E39: 1.3023583 | F39: 1.038608 | G39: 1.8110805 | H39: 1.5424199 | I39: 1.7401609 | J39: 1.781266 | K39: 1.3090138 | L39: 1.5386983 | M39: 0.61806726 | N39: 1.534315 | P39: Cúcuta | Q39: 1.8110805 | R39: 1.7543111
A40: 2003 | B40: 1.40528 | C40: 1.6627241 | D40: 0.91349381 | E40: 1.0247607 | F40: 0.94926858 | G40: 1.9978424 | H40: 1.9679562 | I40: 1.6001817 | J40: 1.532137 | K40: 1.346272 | L40: 1.4478507 | M40: 0.67505443 | N40: 1.5867203 | P40: Bogotá | Q40: 1.8061826 | R40: 0.95430017
A41: 2004 | B41: 1.0980579 | C41: 1.5570136 | D41: 0.83731037 | E41: 1.1076155 | F41: 0.81085086 | G41: 2.41486 | H41: 2.1155899 | I41: 2.1213186 | J41: 1.4054705 | K41: 1.3080702 | L41: 1.2821652 | M41: 0.59621769 | N41: 1.0612446 | P41: Medellín | Q41: 1.781266 | R41: 0.81463391
A42: 2005 | B42: 1.0617353 | C42: 1.0235724 | D42: 1.0443329 | E42: 0.97922415 | F42: 0.49950373 | G42: 1.9305815 | H42: 1.6175913 | I42: 1.7020596 | J42: 0.96393657 | K42: 1.3685477 | L42: 1.5308999 | M42: 0.58834058 | N42: 1.5689015 | P42: Manizales | Q42: 1.7401609 | R42: 0.75246382
...

Sheet Tabla 8
A1: PERÍODO | B1: POBREZA (FGT0) | F1: POBREZA (FGT1) | J1: POBREZA (FGT2)
B2: Total nacional | C2: Principales ciudades | D2: Resto urbano | E2: Rural | F2: Total nacional | G2: Principales ciudades | H2: Resto urbano | I2: Rural | J2: Total nacional | K2: Principales ciudades | L2: Resto urbano | M2: Rural
A3: 2002-2005 | B3: ='Tabla 1'!B7-'Tabla 1'!B4 -> -4.4160194 | C3: ='Tabla 1'!C7-'Tabla 1'!C4 -> -3.6979027 | D3: ='Tabla 1'!D7-'Tabla 1'!D4 -> -5.041851 | E3: ='Tabla 1'!E7-'Tabla 1'!E4 -> -4.5293045 | F3: ='Tabla 1'!F7-'Tabla 1'!F4 -> -3.3268528 | G3: ='Tabla 1'!G7-'Tabla 1'!G4 -> -2.2070389 | H3: ='Tabla 1'!H7-'Tabla 1'!H4 -> -4.3173275 | I3: ='Tabla 1'!I7-'Tabla 1'!I4 -> -3.878355 | ... M3: ='Tabla 1'!M7-'Tabla 1'!M4 -> -3.1606054
A4: 2008-2018 | B4: ='Tabla 1'!B18-'Tabla 1'!B8 -> -14.990191 | C4: ='Tabla 1'!C18-'Tabla 1'!C8 -> -10.738653 | D4: ='Tabla 1'!D18-'Tabla 1'!D8 -> -16.054211 | E4: ='Tabla 1'!E18-'Tabla 1'!E8 -> -21.029991 | F4: ='Tabla 1'!F18-'Tabla 1'!F8 -> -8.5306225 | G4: ='Tabla 1'!G18-'Tabla 1'!G8 -> -4.3369107 | H4: ='Tabla 1'!H18-'Tabla 1'!H8 -> -10.937522 | I4: ='Tabla 1'!I18-'Tabla 1'!I8 -> -13.026327 | ... M4: ='Tabla 1'!M18-'Tabla 1'!M8 -> -9.0363469
A5: 2002-2018 | B5: ='Tabla 1'!B18-'Tabla 1'!B4 -> -22.353922 | C5: ='Tabla 1'!C18-'Tabla 1'!C4 -> -19.717892 | D5: ='Tabla 1'!D18-'Tabla 1'!D4 -> -23.262196 | E5: ='Tabla 1'!E18-'Tabla 1'!E4 -> -24.851158 | F5: ='Tabla 1'!F18-'Tabla 1'!F4 -> -11.874439 | G5: ='Tabla 1'!G18-'Tabla 1'!G4 -> -8.4880767 | H5: ='Tabla 1'!H18-'Tabla 1'!H4 -> -13.987378 | I5: ='Tabla 1'!I18-'Tabla 1'!I4 -> -14.793247 | ... M5: ='Tabla 1'!M18-'Tabla 1'!M4 -> -9.8854432
A7: PERÍODO | B7: INDIGENCIA (FGT0) | F7: INDIGENCIA (FGT1) | J7: INDIGENCIA (FGT2)
B8: Total nacional | C8: Principales ciudades | D8: Resto urbano | E8: Rural | F8: Total nacional | G8: Principales ciudades | H8: Resto urbano | I8: Rural | J8: Total nacional | K8: Principales ciudades | L8: Resto urbano | M8: Rural
A9: 2002-2005 | B9: ='Tabla 2'!B7-'Tabla 2'!B4 -> -3.8405838 | C9: ='Tabla 2'!C7-'Tabla 2'!C4 -> -1.8044963 | D9: ='Tabla 2'!D7-'Tabla 2'!D4 -> -5.3011055 | E9: ='Tabla 2'!E7-'Tabla 2'!E4 -> -4.9957752 | F9: ='Tabla 2'!F7-'Tabla 2'!F4 -> -1.8691306 | G9: ='Tabla 2'!G7-'Tabla 2'!G4 -> -0.76980782 | H9: ='Tabla 2'!H7-'Tabla 2'!H4 -> -2.2731633 | I9: ='Tabla 2'!I7-'Tabla 2'!I4 -> -3.0256119 | ... M9: ='Tabla 2'!M7-'Tabla 2'!M4 -> -2.0008574
A10: 2008-2018 | B10: ='Tabla 2'!B18-'Tabla 2'!B8 -> -9.1634049 | C10: ='Tabla 2'!C18-'Tabla 2'!C8 -> -2.722429 | D10: ='Tabla 2'!D18-'Tabla 2'!D8 -> -11.419247 | E10: ='Tabla 2'!E18-'Tabla 2'!E8 -> -17.593994 | F10: ='Tabla 2'!F18-'Tabla 2'!F8 -> -3.9924793 | G10: ='Tabla 2'!G18-'Tabla 2'!G8 -> -0.83597612 | H10: ='Tabla 2'!H18-'Tabla 2'!H8 -> -4.866636 | I10: ='Tabla 2'!I18-'Tabla 2'!I8 -> -8.4962335 | ... M10: ='Tabla 2'!M18-'Tabla 2'!M8 -> -5.2739363
A11: 2002-2018 | B11: ='Tabla 2'!B18-'Tabla 2'!B4 -> -10.387875 | C11: ='Tabla 2'!C18-'Tabla 2'!C4 -> -4.5879233 | D11: ='Tabla 2'!D18-'Tabla 2'!D4 -> -11.777152 | E11: ='Tabla 2'!E18-'Tabla 2'!E4 -> -17.439468 | F11: ='Tabla 2'!F18-'Tabla 2'!F4 -> -3.9761534 | G11: ='Tabla 2'!G18-'Tabla 2'!G4 -> -1.4495373 | H11: ='Tabla 2'!H18-'Tabla 2'!H4 -> -4.1689332 | I11: ='Tabla 2'!I18-'Tabla 2'!I4 -> -7.6033683 | ... M11: ='Tabla 2'!M18-'Tabla 2'!M4 -> -4.3061538

Sheet Tabla 9
A1: PERÍODO | B1: POBREZA (FGT0) | O1: INDIGENCIA (FGT0)
B2: Barranquilla | C2: Bogotá | D2: Bucaramanga | E2: Cali | F2: Cartagena | G2: Cúcuta | H2: Ibagué | I2: Manizales | J2: Medellín | K2: Montería | L2: Pasto | M2: Pereira | N2: Villavicencio | O2: Barranquilla | P2: Bogotá | Q2: Bucaramanga | R2: Cali | S2: Cartagena | T2: Cúcuta | U2: Ibagué | V2: Manizales | W2: Medellín | X2: Montería | Y2: Pasto | Z2: Pereira | AA2: Villavicencio
A3: 2002-2005 | B3: ='Tabla 6'!B6-'Tabla 6'!B3 -> 0.96723557 | C3: ='Tabla 6'!C6-'Tabla 6'!C3 -> -4.707819 | D3: ='Tabla 6'!D6-'Tabla 6'!D3 -> -2.4497776 | E3: ='Tabla 6'!E6-'Tabla 6'!E3 -> -3.0154953 | F3: ='Tabla 6'!F6-'Tabla 6'!F3 -> -9.9998474 | G3: ='Tabla 6'!G6-'Tabla 6'!G3 -> 2.3101196 | H3: ='Tabla 6'!H6-'Tabla 6'!H3 -> 1.296196 | I3: ='Tabla 6'!I6-'Tabla 6'!I3 -> -0.52350616 | ... N3: ='Tabla 6'!N6-'Tabla 6'!N3 -> 0.90159607 | O3: ='Tabla 7'!B6-'Tabla 7'!B3 -> -0.62516689 | P3: ='Tabla 7'!C6-'Tabla 7'!C3 -> -2.324121 | Q3: ='Tabla 7'!D6-'Tabla 7'!D3 -> -1.241024 | R3: ='Tabla 7'!E6-'Tabla 7'!E3 -> -1.058526 | S3: ='Tabla 7'!F6-'Tabla 7'!F3 -> -4.8320193 | T3: ='Tabla 7'!G6-'Tabla 7'!G3 -> 0.18586159 | U3: ='Tabla 7'!H6-'Tabla 7'!H3 -> 0.12113094 | V3: ='Tabla 7'!I6-'Tabla 7'!I3 -> 0.26869774 | ... AA3: ='Tabla 7'!N6-'Tabla 7'!N3 -> -1.2008166
A4: 2008-2018 | B4: ='Tabla 6'!B17-'Tabla 6'!B7 -> -22.250202 | C4: ='Tabla 6'!C17-'Tabla 6'!C7 -> -7.1530485 | D4: ='Tabla 6'!D17-'Tabla 6'!D7 -> -4.6023998 | E4: ='Tabla 6'!E17-'Tabla 6'!E7 -> -12.71897 | F4: ='Tabla 6'!F17-'Tabla 6'!F7 -> -14.268143 | G4: ='Tabla 6'!G17-'Tabla 6'!G7 -> -6.0443497 | H4: ='Tabla 6'!H17-'Tabla 6'!H7 -> -14.475096 | I4: ='Tabla 6'!I17-'Tabla 6'!I7 -> -19.348735 | ... N4: ='Tabla 6'!N17-'Tabla 6'!N7 -> -8.665163 | O4: ='Tabla 7'!B17-'Tabla 7'!B7 -> -7.8085001 | P4: ='Tabla 7'!C17-'Tabla 7'!C7 -> -0.83932638 | Q4: ='Tabla 7'!D17-'Tabla 7'!D7 -> -1.0341033 | R4: ='Tabla 7'!E17-'Tabla 7'!E7 -> -3.9488811 | S4: ='Tabla 7'!F17-'Tabla 7'!F7 -> -3.5064044 | T4: ='Tabla 7'!G17-'Tabla 7'!G7 -> -0.89546633 | U4: ='Tabla 7'!H17-'Tabla 7'!H7 -> -4.2923801 | V4: ='Tabla 7'!I17-'Tabla 7'!I7 -> -4.7154942 | ... AA4: ='Tabla 7'!N17-'Tabla 7'!N7 -> -1.3476288
A5: 2002-2018 | B5: ='Tabla 6'!B17-'Tabla 6'!B3 -> -22.009922 | C5: ='Tabla 6'!C17-'Tabla 6'!C3 -> -18.925933 | D5: ='Tabla 6'!D17-'Tabla 6'!D3 -> -19.031208 | E5: ='Tabla 6'!E17-'Tabla 6'!E3 -> -17.401134 | F5: ='Tabla 6'!F17-'Tabla 6'!F3 -> -21.788174 | G5: ='Tabla 6'!G17-'Tabla 6'!G3 -> -16.674236 | H5: ='Tabla 6'!H17-'Tabla 6'!H3 -> -20.033072 | I5: ='Tabla 6'!I17-'Tabla 6'!I3 -> -25.129935 | ... N5: ='Tabla 6'!N17-'Tabla 6'!N3 -> -15.86739 | O5: ='Tabla 7'!B17-'Tabla 7'!B3 -> -6.2289331 | P5: ='Tabla 7'!C17-'Tabla 7'!C3 -> -4.461946 | Q5: ='Tabla 7'!D17-'Tabla 7'!D3 -> -4.5161921 | R5: ='Tabla 7'!E17-'Tabla 7'!E3 -> -2.6529765 | S5: ='Tabla 7'!F17-'Tabla 7'!F3 -> -6.0939417 | T5: ='Tabla 7'!G17-'Tabla 7'!G3 -> -4.0900044 | U5: ='Tabla 7'!H17-'Tabla 7'!H3 -> -5.4353821 | V5: ='Tabla 7'!I17-'Tabla 7'!I3 -> -5.1604099 | ... AA5: ='Tabla 7'!N17-'Tabla 7'!N3 -> -3.5596807
A7: PERÍODO | B7: POBREZA (FGT1) | O7: INDIGENCIA (FGT1)
B8: Barranquilla | C8: Bogotá | D8: Bucaramanga | E8: Cali | F8: Cartagena | G8: Cúcuta | H8: Ibagué | I8: Manizales | J8: Medellín | K8: Montería | L8: Pasto | M8: Pereira | N8: Villavicencio | O8: Barranquilla | P8: Bogotá | Q8: Bucaramanga | R8: Cali | S8: Cartagena | T8: Cúcuta | U8: Ibagué | V8: Manizales | W8: Medellín | X8: Montería | Y8: Pasto | Z8: Pereira | AA8: Villavicencio
A9: 2002-2005 | B9: ='Tabla 6'!B24-'Tabla 6'!B21 -> 0.11812973 | C9: ='Tabla 6'!C24-'Tabla 6'!C21 -> -2.9297905 | D9: ='Tabla 6'!D24-'Tabla 6'!D21 -> -1.2138414 | E9: ='Tabla 6'!E24-'Tabla 6'!E21 -> -1.7776337 | F9: ='Tabla 6'!F24-'Tabla 6'!F21 -> -5.5503979 | G9: ='Tabla 6'!G24-'Tabla 6'!G21 -> 1.1092815 | H9: ='Tabla 6'!H24-'Tabla 6'!H21 -> 0.50350475 | I9: ='Tabla 6'!I24-'Tabla 6'!I21 -> -0.082551003 | ... N9: ='Tabla 6'!N24-'Tabla 6'!N21 -> -0.13789177 | O9: ='Tabla 7'!B24-'Tabla 7'!B21 -> -0.12197089 | P9: ='Tabla 7'!C24-'Tabla 7'!C21 -> -1.0986583 | Q9: ='Tabla 7'!D24-'Tabla 7'!D21 -> -0.40731919 | R9: ='Tabla 7'!E24-'Tabla 7'!E21 -> -0.47387004 | S9: ='Tabla 7'!F24-'Tabla 7'!F21 -> -1.3584296 | T9: ='Tabla 7'!G24-'Tabla 7'!G21 -> 0.15658212 | U9: ='Tabla 7'!H24-'Tabla 7'!H21 -> 0.074075937 | V9: ='Tabla 7'!I24-'Tabla 7'!I21 -> 0.12952375 | ... AA9: ='Tabla 7'!N24-'Tabla 7'!N21 -> -0.15375614
A10: 2008-2018 | B10: ='Tabla 6'!B35-'Tabla 6'!B25 -> -10.349295 | C10: ='Tabla 6'!C35-'Tabla 6'!C25 -> -2.2939401 | D10: ='Tabla 6'!D35-'Tabla 6'!D25 -> -1.7420483 | E10: ='Tabla 6'!E35-'Tabla 6'!E25 -> -5.5727339 | F10: ='Tabla 6'!F35-'Tabla 6'!F25 -> -6.0639076 | G10: ='Tabla 6'!G35-'Tabla 6'!G25 -> -2.2191257 | H10: ='Tabla 6'!H35-'Tabla 6'!H25 -> -6.181891 | I10: ='Tabla 6'!I35-'Tabla 6'!I25 -> -7.6280589 | ... N10: ='Tabla 6'!N35-'Tabla 6'!N25 -> -3.221385 | O10: ='Tabla 7'!B35-'Tabla 7'!B25 -> -2.4101709 | P10: ='Tabla 7'!C35-'Tabla 7'!C25 -> -0.024989605 | Q10: ='Tabla 7'!D35-'Tabla 7'!D25 -> -0.1463809 | R10: ='Tabla 7'!E35-'Tabla 7'!E25 -> -1.5935003 | S10: ='Tabla 7'!F35-'Tabla 7'!F25 -> -0.82814765 | T10: ='Tabla 7'!G35-'Tabla 7'!G25 -> 0.20441699 | U10: ='Tabla 7'!H35-'Tabla 7'!H25 -> -1.3969434 | V10: ='Tabla 7'!I35-'Tabla 7'!I25 -> -1.808383 | ... AA10: ='Tabla 7'!N35-'Tabla 7'!N25 -> -0.33909583
A11: 2002-2018 | B11: ='Tabla 6'!B35-'Tabla 6'!B21 -> -10.415415 | C11: ='Tabla 6'!C35-'Tabla 6'!C21 -> -8.2551742 | D11: ='Tabla 6'!D35-'Tabla 6'!D21 -> -7.9843011 | E11: ='Tabla 6'!E35-'Tabla 6'!E21 -> -6.8475971 | F11: ='Tabla 6'!F35-'Tabla 6'!F21 -> -10.103334 | G11: ='Tabla 6'!G35-'Tabla 6'!G21 -> -7.5916281 | H11: ='Tabla 6'!H35-'Tabla 6'!H21 -> -8.7848353 | I11: ='Tabla 6'!I35-'Tabla 6'!I21 -> -10.049537 | ... N11: ='Tabla 6'!N35-'Tabla 6'!N21 -> -6.3080025 | O11: ='Tabla 7'!B35-'Tabla 7'!B21 -> -1.7810224 | P11: ='Tabla 7'!C35-'Tabla 7'!C21 -> -1.5500274 | Q11: ='Tabla 7'!D35-'Tabla 7'!D21 -> -1.4508727 | R11: ='Tabla 7'!E35-'Tabla 7'!E21 -> -0.70642769 | S11: ='Tabla 7'!F35-'Tabla 7'!F21 -> -1.4155862 | T11: ='Tabla 7'!G35-'Tabla 7'!G21 -> -0.68091369 | U11: ='Tabla 7'!H35-'Tabla 7'!H21 -> -1.7866865 | V11: ='Tabla 7'!I35-'Tabla 7'!I21 -> -1.7804186 | ... AA11: ='Tabla 7'!N35-'Tabla 7'!N21 -> -0.76201892
A13: PERÍODO | B13: POBREZA (FGT2) | O13: INDIGENCIA (FGT2)
B14: Barranquilla | C14: Bogotá | D14: Bucaramanga | E14: Cali | F14: Cartagena | G14: Cúcuta | H14: Ibagué | I14: Manizales | J14: Medellín | K14: Montería | L14: Pasto | M14: Pereira | N14: Villavicencio | O14: Barranquilla | P14: Bogotá | Q14: Bucaramanga | R14: Cali | S14: Cartagena | T14: Cúcuta | U14: Ibagué | V14: Manizales | W14: Medellín | X14: Montería | Y14: Pasto | Z14: Pereira | AA14: Villavicencio
A15: 2002-2005 | B15: ='Tabla 6'!B42-'Tabla 6'!B39 -> -0.038039207 | C15: ='Tabla 6'!C42-'Tabla 6'!C39 -> -2.0284753 | D15: ='Tabla 6'!D42-'Tabla 6'!D39 -> -0.79134607 | E15: ='Tabla 6'!E42-'Tabla 6'!E39 -> -1.16044 | F15: ='Tabla 6'!F42-'Tabla 6'!F39 -> -3.3916473 | G15: ='Tabla 6'!G42-'Tabla 6'!G39 -> 0.74205971 | H15: ='Tabla 6'!H42-'Tabla 6'!H39 -> 0.2129221 | I15: ='Tabla 6'!I42-'Tabla 6'!I39 -> -0.014977932 | ... N15: ='Tabla 6'!N42-'Tabla 6'!N39 -> -0.17600822 | O15: ='Tabla 7'!B42-'Tabla 7'!B39 -> -0.044429898 | P15: ='Tabla 7'!C42-'Tabla 7'!C39 -> -0.78261018 | Q15: ='Tabla 7'!D42-'Tabla 7'!D39 -> -0.20663512 | R15: ='Tabla 7'!E42-'Tabla 7'!E39 -> -0.32313412 | S15: ='Tabla 7'!F42-'Tabla 7'!F39 -> -0.53910422 | T15: ='Tabla 7'!G42-'Tabla 7'!G39 -> 0.11950099 | U15: ='Tabla 7'!H42-'Tabla 7'!H39 -> 0.075171351 | V15: ='Tabla 7'!I42-'Tabla 7'!I39 -> -0.038101315 | ... AA15: ='Tabla 7'!N42-'Tabla 7'!N39 -> 0.034586549
A16: 2008-2018 | B16: ='Tabla 6'!B53-'Tabla 6'!B43 -> -5.8701968 | C16: ='Tabla 6'!C53-'Tabla 6'!C43 -> -0.95787406 | D16: ='Tabla 6'!D53-'Tabla 6'!D43 -> -0.83409739 | E16: ='Tabla 6'!E53-'Tabla 6'!E43 -> -3.2926288 | F16: ='Tabla 6'!F53-'Tabla 6'!F43 -> -3.0088336 | G16: ='Tabla 6'!G53-'Tabla 6'!G43 -> -0.81561136 | H16: ='Tabla 6'!H53-'Tabla 6'!H43 -> -3.3991067 | I16: ='Tabla 6'!I53-'Tabla 6'!I43 -> -4.129864 | ... N16: ='Tabla 6'!N53-'Tabla 6'!N43 -> -1.5437834 | O16: ='Tabla 7'!B53-'Tabla 7'!B43 -> -1.2562116 | P16: ='Tabla 7'!C53-'Tabla 7'!C43 -> 0.14474177 | Q16: ='Tabla 7'!D53-'Tabla 7'!D43 -> 0.011352301 | R16: ='Tabla 7'!E53-'Tabla 7'!E43 -> -0.99508631 | S16: ='Tabla 7'!F53-'Tabla 7'!F43 -> -0.20350903 | T16: ='Tabla 7'!G53-'Tabla 7'!G43 -> 0.33474243 | U16: ='Tabla 7'!H53-'Tabla 7'!H43 -> -0.70756364 | V16: ='Tabla 7'!I53-'Tabla 7'!I43 -> -0.99721861 | ... AA16: ='Tabla 7'!N53-'Tabla 7'!N43 -> -0.10188627
A17: 2002-2018 | B17: ='Tabla 6'!B53-'Tabla 6'!B39 -> -5.8132701 | C17: ='Tabla 6'!C53-'Tabla 6'!C39 -> -4.6527598 | D17: ='Tabla 6'!D53-'Tabla 6'!D39 -> -4.369024 | E17: ='Tabla 6'!E53-'Tabla 6'!E39 -> -3.5017972 | F17: ='Tabla 6'!F53-'Tabla 6'!F39 -> -5.388602 | G17: ='Tabla 6'!G53-'Tabla 6'!G39 -> -3.8331051 | H17: ='Tabla 6'!H53-'Tabla 6'!H39 -> -5.0014651 | I17: ='Tabla 6'!I53-'Tabla 6'!I39 -> -5.4778216 | ... N17: ='Tabla 6'!N53-'Tabla 6'!N39 -> -3.2082541 | O17: ='Tabla 7'!B53-'Tabla 7'!B39 -> -0.8226915 | P17: ='Tabla 7'!C53-'Tabla 7'!C39 -> -0.85188246 | Q17: ='Tabla 7'!D53-'Tabla 7'!D39 -> -0.7191807 | R17: ='Tabla 7'!E53-'Tabla 7'!E39 -> -0.2538867 | S17: ='Tabla 7'!F53-'Tabla 7'!F39 -> -0.41455203 | T17: ='Tabla 7'!G53-'Tabla 7'!G39 -> -0.056769371 | U17: ='Tabla 7'!H53-'Tabla 7'!H39 -> -0.86120868 | V17: ='Tabla 7'!I53-'Tabla 7'!I39 -> -0.98769712 | ... AA17: ='Tabla 7'!N53-'Tabla 7'!N39 -> -0.14403427

Sheet Tabla 10
A1: AÑO | B1: POBLACIÓN
B2: Total | F2: Porcentaje
B3: Principales ciudades | C3: Resto urbano | D3: Rural | E3: Total nacional | F3: Principales ciudades | G3: Resto urbano | H3: Rural | I3: Total nacional
A4: 2002 | B4: 17806378 | C4: 11903920 | D4: 10467051 | E4: =SUM(B4:D4) -> 40177349 | F4: =B4/$E4 -> 0.44319445 | G4: =C4/$E4 -> 0.29628436 | H4: =D4/$E4 -> 0.2605212 | I4: =SUM(F4:H4) -> 1
A5: 2003 | B5: 18081858 | C5: 12144980 | D5: 10452419 | E5: =SUM(B5:D5) -> 40679257 | F5: =B5/$E5 -> 0.44449824 | G5: =C5/$E5 -> 0.29855462 | H5: =D5/$E5 -> 0.25694715 | I5: =SUM(F5:H5) -> 1
A6: 2004 | B6: 18355894 | C6: 12381911 | D6: 10444679 | E6: =SUM(B6:D6) -> 41182484 | F6: =B6/$E6 -> 0.4457209 | G6: =C6/$E6 -> 0.30065964 | H6: =D6/$E6 -> 0.25361945 | I6: =SUM(F6:H6) -> 1
A7: 2005 | B7: 18627918 | C7: 12613672 | D7: 10438829 | E7: =SUM(B7:D7) -> 41680419 | F7: =B7/$E7 -> 0.44692252 | G7: =C7/$E7 -> 0.30262824 | H7: =D7/$E7 -> 0.25044923 | I7: =SUM(F7:H7) -> 1
A8: 2008 | B8: 19428196 | C8: 13273991 | D8: 10493045 | E8: =SUM(B8:D8) -> 43195232 | F8: =B8/$E8 -> 0.4497764 | G8: =C8/$E8 -> 0.30730223 | H8: =D8/$E8 -> 0.24292137 | I8: =SUM(F8:H8) -> 1
A9: 2009 | B9: 19694234 | C9: 13488477 | D9: 10522489 | E9: =SUM(B9:D9) -> 43705200 | F9: =B9/$E9 -> 0.45061535 | G9: =C9/$E9 -> 0.30862408 | H9: =D9/$E9 -> 0.24076057 | I9: =SUM(F9:H9) -> 1
A10: 2010 | B10: 19960462 | C10: 13705246 | D10: 10551365 | E10: =SUM(B10:D10) -> 44217073 | F10: =B10/$E10 -> 0.45141979 | G10: =C10/$E10 -> 0.30995371 | H10: =D10/$E10 -> 0.23862649 | I10: =SUM(F10:H10) -> 1
A11: 2011 | B11: 20227704 | C11: 13919482 | D11: 10587607 | E11: =SUM(B11:D11) -> 44734793 | F11: =B11/$E11 -> 0.45216939 | G11: =C11/$E11 -> 0.31115561 | H11: =D11/$E11 -> 0.236675 | I11: =SUM(F11:H11) -> 1
A12: 2012 | B12: 20491984 | C12: 14124077 | D12: 10637646 | E12: =SUM(B12:D12) -> 45253707 | F12: =B12/$E12 -> 0.45282443 | G12: =C12/$E12 -> 0.31210873 | H12: =D12/$E12 -> 0.23506684 | I12: =SUM(F12:H12) -> 1
A13: 2013 | B13: 20756004 | C13: 14336558 | D13: 10681720 | E13: =SUM(B13:D13) -> 45774282 | F13: =B13/$E13 -> 0.45344248 | G13: =C13/$E13 -> 0.31320116 | H13: =D13/$E13 -> 0.23335636 | I13: =SUM(F13:H13) -> 1
A14: 2014 | B14: 21018726 | C14: 14548332 | D14: 10728994 | E14: =SUM(B14:D14) -> 46296052 | F14: =B14/$E14 -> 0.45400688 | G14: =C14/$E14 -> 0.31424563 | H14: =D14/$E14 -> 0.23174749 | I14: =SUM(F14:H14) -> 1
A15: 2015 | B15: 21279954 | C15: 14759347 | D15: 10779390 | E15: =SUM(B15:D15) -> 46818691 | F15: =B15/$E15 -> 0.45451835 | G15: =C15/$E15 -> 0.31524476 | H15: =D15/$E15 -> 0.23023689 | I15: =SUM(F15:H15) -> 1
... A18: 2018 | B18: 22052810 | C18: 15388667 | D18: 10949071 | E18: =SUM(B18:D18) -> 48390548 | F18: =B18/$E18 -> 0.45572557 | G18: =C18/$E18 -> 0.31800977 | H18: =D18/$E18 -> 0.22626466 | I18: =SUM(F18:H18) -> 1
F19: =AVERAGE(F4:F18) -> 0.45136221 | G19: =AVERAGE(G4:G18) -> 0.30906909 | H19: =AVERAGE(H4:H18) -> 0.2395687 | I19: =SUM(F19:H19) -> 1

Sheet Tabla 11
A1: AÑO | B1: POBREZA
B2: Incidencia (FGT0) | F2: Brecha (FGT1) | J2: Severidad (FGT2)
B3: Principales ciudades | C3: Resto urbano | D3: Rural | E3: Total nacional | F3: Principales ciudades | G3: Resto urbano | H3: Rural | I3: Total nacional | J3: Principales ciudades | K3: Resto urbano | L3: Rural | M3: Total nacional
A4: 2002 | B4: ='Tabla 1'!C4/'Tabla 1'!$B4*'Tabla 10'!F4 -> 0.32235289 | C4: ='Tabla 1'!D4/'Tabla 1'!$B4*'Tabla 10'!G4 -> 0.35618601 | D4: ='Tabla 1'!E4/'Tabla 1'!$B4*'Tabla 10'!H4 -> 0.32146113 | E4: =SUM(B4:D4) -> 1 | F4: ='Tabla 1'!G4/'Tabla 1'!$F4*'Tabla 10'!F4 -> 0.28228162 | G4: ='Tabla 1'!H4/'Tabla 1'!$F4*'Tabla 10'!G4 -> 0.37436847 | H4: ='Tabla 1'!I4/'Tabla 1'!$F4*'Tabla 10'!H4 -> 0.34334992 | I4: =SUM(F4:H4) -> 1 | J4: ='Tabla 1'!K4/'Tabla 1'!$J4*'Tabla 10'!F4 -> 0.26028348 | K4: ='Tabla 1'!L4/'Tabla 1'!$J4*'Tabla 10'!G4 -> 0.38165737 | L4: ='Tabla 1'!M4/'Tabla 1'!$J4*'Tabla 10'!H4 -> 0.35805914 | M4: =SUM(J4:L4) -> 0.99999999
A5: 2003 | B5: ='Tabla 1'!C5/'Tabla 1'!$B5*'Tabla 10'!F5 -> 0.33953223 | C5: ='Tabla 1'!D5/'Tabla 1'!$B5*'Tabla 10'!G5 -> 0.35693861 | D5: ='Tabla 1'!E5/'Tabla 1'!$B5*'Tabla 10'!H5 -> 0.30352919 | E5: =SUM(B5:D5) -> 1 | F5: ='Tabla 1'!G5/'Tabla 1'!$F5*'Tabla 10'!F5 -> 0.30640955 | G5: ='Tabla 1'!H5/'Tabla 1'!$F5*'Tabla 10'!G5 -> 0.3759488 | H5: ='Tabla 1'!I5/'Tabla 1'!$F5*'Tabla 10'!H5 -> 0.31764168 | I5: =SUM(F5:H5) -> 1 | J5: ='Tabla 1'!K5/'Tabla 1'!$J5*'Tabla 10'!F5 -> 0.28752818 | K5: ='Tabla 1'!L5/'Tabla 1'!$J5*'Tabla 10'!G5 -> 0.38379489 | L5: ='Tabla 1'!M5/'Tabla 1'!$J5*'Tabla 10'!H5 -> 0.32867689 | M5: =SUM(J5:L5) -> 0.99999995
A6: 2004 | B6: ='Tabla 1'!C6/'Tabla 1'!$B6*'Tabla 10'!F6 -> 0.32215146 | C6: ='Tabla 1'!D6/'Tabla 1'!$B6*'Tabla 10'!G6 -> 0.36565909 | D6: ='Tabla 1'!E6/'Tabla 1'!$B6*'Tabla 10'!H6 -> 0.31218942 | E6: =SUM(B6:D6) -> 0.99999998 | F6: ='Tabla 1'!G6/'Tabla 1'!$F6*'Tabla 10'!F6 -> 0.28946443 | G6: ='Tabla 1'!H6/'Tabla 1'!$F6*'Tabla 10'!G6 -> 0.37915301 | H6: ='Tabla 1'!I6/'Tabla 1'!$F6*'Tabla 10'!H6 -> 0.33138258 | I6: =SUM(F6:H6) -> 1 | J6: ='Tabla 1'!K6/'Tabla 1'!$J6*'Tabla 10'!F6 -> 0.27356321 | K6: ='Tabla 1'!L6/'Tabla 1'!$J6*'Tabla 10'!G6 -> 0.38168069 | L6: ='Tabla 1'!M6/'Tabla 1'!$J6*'Tabla 10'!H6 -> 0.34475605 | M6: =SUM(J6:L6) -> 0.99999995
A7: 2005 | B7: ='Tabla 1'!C7/'Tabla 1'!$B7*'Tabla 10'!F7 -> 0.32023305 | C7: ='Tabla 1'!D7/'Tabla 1'!$B7*'Tabla 10'!G7 -> 0.36560985 | D7: ='Tabla 1'!E7/'Tabla 1'!$B7*'Tabla 10'!H7 -> 0.31415714 | E7: =SUM(B7:D7) -> 1 | F7: ='Tabla 1'!G7/'Tabla 1'!$F7*'Tabla 10'!F7 -> 0.28251434 | G7: ='Tabla 1'!H7/'Tabla 1'!$F7*'Tabla 10'!G7 -> 0.38051217 | H7: ='Tabla 1'!I7/'Tabla 1'!$F7*'Tabla 10'!H7 -> 0.33697351 | I7: =SUM(F7:H7) -> 1 | J7: ='Tabla 1'!K7/'Tabla 1'!$J7*'Tabla 10'!F7 -> 0.26224038 | K7: ='Tabla 1'!L7/'Tabla 1'!$J7*'Tabla 10'!G7 -> 0.38588301 | L7: ='Tabla 1'!M7/'Tabla 1'!$J7*'Tabla 10'!H7 -> 0.35187656 | M7: =SUM(J7:L7) -> 0.99999994
A8: 2008 | B8: ='Tabla 1'!C8/'Tabla 1'!$B8*'Tabla 10'!F8 -> 0.28834295 | C8: ='Tabla 1'!D8/'Tabla 1'!$B8*'Tabla 10'!G8 -> 0.38146249 | D8: ='Tabla 1'!E8/'Tabla 1'!$B8*'Tabla 10'!H8 -> 0.33019309 | E8: =SUM(B8:D8) -> 0.99999853 | F8: ='Tabla 1'!G8/'Tabla 1'!$F8*'Tabla 10'!F8 -> 0.23696284 | G8: ='Tabla 1'!H8/'Tabla 1'!$F8*'Tabla 10'!G8 -> 0.40795671 | H8: ='Tabla 1'!I8/'Tabla 1'!$F8*'Tabla 10'!H8 -> 0.35507843 | I8: =SUM(F8:H8) -> 0.99999798 | J8: ='Tabla 1'!K8/'Tabla 1'!$J8*'Tabla 10'!F8 -> 0.21015951 | K8: ='Tabla 1'!L8/'Tabla 1'!$J8*'Tabla 10'!G8 -> 0.41873572 | L8: ='Tabla 1'!M8/'Tabla 1'!$J8*'Tabla 10'!H8 -> 0.37110261 | M8: =SUM(J8:L8) -> 0.99999784
A9: 2009 | B9: ='Tabla 1'!C9/'Tabla 1'!$B9*'Tabla 10'!F9 -> 0.28640122 | C9: ='Tabla 1'!D9/'Tabla 1'!$B9*'Tabla 10'!G9 -> 0.38879617 | D9: ='Tabla 1'!E9/'Tabla 1'!$B9*'Tabla 10'!H9 -> 0.32480098 | E9: =SUM(B9:D9) -> 0.99999837 | F9: ='Tabla 1'!G9/'Tabla 1'!$F9*'Tabla 10'!F9 -> 0.24585908 | G9: ='Tabla 1'!H9/'Tabla 1'!$F9*'Tabla 10'!G9 -> 0.40823636 | H9: ='Tabla 1'!I9/'Tabla 1'!$F9*'Tabla 10'!H9 -> 0.34590254 | I9: =SUM(F9:H9) -> 0.99999799 | J9: ='Tabla 1'!K9/'Tabla 1'!$J9*'Tabla 10'!F9 -> 0.22744619 | K9: ='Tabla 1'!L9/'Tabla 1'!$J9*'Tabla 10'!G9 -> 0.41561826 | L9: ='Tabla 1'!M9/'Tabla 1'!$J9*'Tabla 10'!H9 -> 0.35693329 | M9: =SUM(J9:L9) -> 0.99999774
A10: 2010 | B10: ='Tabla 1'!C10/'Tabla 1'!$B10*'Tabla 10'!F10 -> 0.28203781 | C10: ='Tabla 1'!D10/'Tabla 1'!$B10*'Tabla 10'!G10 -> 0.39481505 | D10: ='Tabla 1'!E10/'Tabla 1'!$B10*'Tabla 10'!H10 -> 0.32314651 | E10: =SUM(B10:D10) -> 0.99999937 | F10: ='Tabla 1'!G10/'Tabla 1'!$F10*'Tabla 10'!F10 -> 0.24733746 | G10: ='Tabla 1'!H10/'Tabla 1'!$F10*'Tabla 10'!G10 -> 0.40647603 | H10: ='Tabla 1'!I10/'Tabla 1'!$F10*'Tabla 10'!H10 -> 0.34618569 | I10: =SUM(F10:H10) -> 0.99999919 | J10: ='Tabla 1'!K10/'Tabla 1'!$J10*'Tabla 10'!F10 -> 0.23359577 | K10: ='Tabla 1'!L10/'Tabla 1'!$J10*'Tabla 10'!G10 -> 0.40712085 | L10: ='Tabla 1'!M10/'Tabla 1'!$J10*'Tabla 10'!H10 -> 0.35928247 | M10: =SUM(J10:L10) -> 0.99999909
A11: 2011 | B11: ='Tabla 1'!C11/'Tabla 1'!$B11*'Tabla 10'!F11 -> 0.27360882 | C11: ='Tabla 1'!D11/'Tabla 1'!$B11*'Tabla 10'!G11 -> 0.4002276 | D11: ='Tabla 1'!E11/'Tabla 1'!$B11*'Tabla 10'!H11 -> 0.32616364 | E11: =SUM(B11:D11) -> 1.0000001 | F11: ='Tabla 1'!G11/'Tabla 1'!$F11*'Tabla 10'!F11 -> 0.23277171 | G11: ='Tabla 1'!H11/'Tabla 1'!$F11*'Tabla 10'!G11 -> 0.42067188 | H11: ='Tabla 1'!I11/'Tabla 1'!$F11*'Tabla 10'!H11 -> 0.34655637 | I11: =SUM(F11:H11) -> 0.99999996 | J11: ='Tabla 1'!K11/'Tabla 1'!$J11*'Tabla 10'!F11 -> 0.21508547 | K11: ='Tabla 1'!L11/'Tabla 1'!$J11*'Tabla 10'!G11 -> 0.42874331 | L11: ='Tabla 1'!M11/'Tabla 1'!$J11*'Tabla 10'!H11 -> 0.35617123 | M11: =SUM(J11:L11) -> 1
A12: 2012 | B12: ='Tabla 1'!C12/'Tabla 1'!$B12*'Tabla 10'!F12 -> 0.26201592 | C12: ='Tabla 1'!D12/'Tabla 1'!$B12*'Tabla 10'!G12 -> 0.40195502 | D12: ='Tabla 1'!E12/'Tabla 1'!$B12*'Tabla 10'!H12 -> 0.33602907 | E12: =SUM(B12:D12) -> 1 | F12: ='Tabla 1'!G12/'Tabla 1'!$F12*'Tabla 10'!F12 -> 0.22377909 | G12: ='Tabla 1'!H12/'Tabla 1'!$F12*'Tabla 10'!G12 -> 0.42079165 | H12: ='Tabla 1'!I12/'Tabla 1'!$F12*'Tabla 10'!H12 -> 0.35542922 | I12: =SUM(F12:H12) -> 0.99999996 | J12: ='Tabla 1'!K12/'Tabla 1'!$J12*'Tabla 10'!F12 -> 0.20598435 | K12: ='Tabla 1'!L12/'Tabla 1'!$J12*'Tabla 10'!G12 -> 0.42609651 | L12: ='Tabla 1'!M12/'Tabla 1'!$J12*'Tabla 10'!H12 -> 0.36791912 | M12: =SUM(J12:L12) -> 0.99999999
A13: 2013 | B13: ='Tabla 1'!C13/'Tabla 1'!$B13*'Tabla 10'!F13 -> 0.25958427 | C13: ='Tabla 1'!D13/'Tabla 1'!$B13*'Tabla 10'!G13 -> 0.4140108 | D13: ='Tabla 1'!E13/'Tabla 1'!$B13*'Tabla 10'!H13 -> 0.32640495 | E13: =SUM(B13:D13) -> 1 | F13: ='Tabla 1'!G13/'Tabla 1'!$F13*'Tabla 10'!F13 -> 0.22796477 | G13: ='Tabla 1'!H13/'Tabla 1'!$F13*'Tabla 10'!G13 -> 0.43061646 | H13: ='Tabla 1'!I13/'Tabla 1'!$F13*'Tabla 10'!H13 -> 0.3414188 | I13: =SUM(F13:H13) -> 1 | J13: ='Tabla 1'!K13/'Tabla 1'!$J13*'Tabla 10'!F13 -> 0.21561649 | K13: ='Tabla 1'!L13/'Tabla 1'!$J13*'Tabla 10'!G13 -> 0.43610701 | L13: ='Tabla 1'!M13/'Tabla 1'!$J13*'Tabla 10'!H13 -> 0.34827651 | M13: =SUM(J13:L13) -> 1
A14: 2014 | B14: ='Tabla 1'!C14/'Tabla 1'!$B14*'Tabla 10'!F14 -> 0.25275223 | C14: ='Tabla 1'!D14/'Tabla 1'!$B14*'Tabla 10'!G14 -> 0.41076207 | D14: ='Tabla 1'!E14/'Tabla 1'!$B14*'Tabla 10'!H14 -> 0.33648571 | E14: =SUM(B14:D14) -> 1 | F14: ='Tabla 1'!G14/'Tabla 1'!$F14*'Tabla 10'!F14 -> 0.21992809 | G14: ='Tabla 1'!H14/'Tabla 1'!$F14*'Tabla 10'!G14 -> 0.42424559 | H14: ='Tabla 1'!I14/'Tabla 1'!$F14*'Tabla 10'!H14 -> 0.35582629 | I14: =SUM(F14:H14) -> 0.99999998 | J14: ='Tabla 1'!K14/'Tabla 1'!$J14*'Tabla 10'!F14 -> 0.20845856 | K14: ='Tabla 1'!L14/'Tabla 1'!$J14*'Tabla 10'!G14 -> 0.4265864 | L14: ='Tabla 1'!M14/'Tabla 1'!$J14*'Tabla 10'!H14 -> 0.36495507 | M14: =SUM(J14:L14) -> 1
A15: 2015 | B15: ='Tabla 1'!C15/'Tabla 1'!$B15*'Tabla 10'!F15 -> 0.25054061 | C15: ='Tabla 1'!D15/'Tabla 1'!$B15*'Tabla 10'!G15 -> 0.41633399 | D15: ='Tabla 1'!E15/'Tabla 1'!$B15*'Tabla 10'!H15 -> 0.33312543 | E15: =SUM(B15:D15) -> 1 | F15: ='Tabla 1'!G15/'Tabla 1'!$F15*'Tabla 10'!F15 -> 0.22558104 | G15: ='Tabla 1'!H15/'Tabla 1'!$F15*'Tabla 10'!G15 -> 0.42445872 | H15: ='Tabla 1'!I15/'Tabla 1'!$F15*'Tabla 10'!H15 -> 0.34996026 | I15: =SUM(F15:H15) -> 1 | J15: ='Tabla 1'!K15/'Tabla 1'!$J15*'Tabla 10'!F15 -> 0.22076626 | K15: ='Tabla 1'!L15/'Tabla 1'!$J15*'Tabla 10'!G15 -> 0.41990541 | L15: ='Tabla 1'!M15/'Tabla 1'!$J15*'Tabla 10'!H15 -> 0.35932835 | M15: =SUM(J15:L15) -> 1
... A18: 2018 | B18: ='Tabla 1'!C18/'Tabla 1'!$B18*'Tabla 10'!F18 -> 0.2731157 | C18: ='Tabla 1'!D18/'Tabla 1'!$B18*'Tabla 10'!G18 -> 0.42481326 | D18: ='Tabla 1'!E18/'Tabla 1'!$B18*'Tabla 10'!H18 -> 0.30207101 | E18: =SUM(B18:D18) -> 0.99999996 | F18: ='Tabla 1'!G18/'Tabla 1'!$F18*'Tabla 10'!F18 -> 0.24739297 | G18: ='Tabla 1'!H18/'Tabla 1'!$F18*'Tabla 10'!G18 -> 0.43469573 | H18: ='Tabla 1'!I18/'Tabla 1'!$F18*'Tabla 10'!H18 -> 0.31791131 | I18: =SUM(F18:H18) -> 1 | J18: ='Tabla 1'!K18/'Tabla 1'!$J18*'Tabla 10'!F18 -> 0.24229303 | K18: ='Tabla 1'!L18/'Tabla 1'!$J18*'Tabla 10'!G18 -> 0.43135597 | L18: ='Tabla 1'!M18/'Tabla 1'!$J18*'Tabla 10'!H18 -> 0.32635095 | M18: =SUM(J18:L18) -> 0.99999996
B19: =AVERAGE(B4:B18) -> 0.28421151 | C19: =AVERAGE(C4:C18) -> 0.39521261 | D19: =AVERAGE(D4:D18) -> 0.32057564 | E19: =SUM(B19:D19) -> 0.99999976 | F19: =AVERAGE(F4:F18) -> 0.24937972 | G19: =AVERAGE(G4:G18) -> 0.41135146 | H19: =AVERAGE(H4:H18) -> 0.3392685 | I19: =SUM(F19:H19) -> 0.99999968 | J19: =AVERAGE(J4:J18) -> 0.23474515 | K19: =AVERAGE(K4:K18) -> 0.41543453 | L19: =AVERAGE(L4:L18) -> 0.34981996 | M19: =SUM(J19:L19) -> 0.99999964

Sheet Tabla 12
A1: AÑO | B1: INDIGENCIA
B2: Incidencia (FGT0) | F2: Brecha (FGT1) | J2: Severidad (FGT2)
B3: Principales ciudades | C3: Resto urbano | D3: Rural | E3: Total nacional | F3: Principales ciudades | G3: Resto urbano | H3: Rural | I3: Total nacional | J3: Principales ciudades | K3: Resto urbano | L3: Rural | M3: Total nacional
A4: 2002 | B4: ='Tabla 2'!C4/'Tabla 2'!$B4*'Tabla 10'!F4 -> 0.1869669 | C4: ='Tabla 2'!D4/'Tabla 2'!$B4*'Tabla 10'!G4 -> 0.32844376 | D4: ='Tabla 2'!E4/'Tabla 2'!$B4*'Tabla 10'!H4 -> 0.48458929 | E4: =SUM(B4:D4) -> 0.99999995 | F4: ='Tabla 2'!G4/'Tabla 2'!$F4*'Tabla 10'!F4 -> 0.17883898 | G4: ='Tabla 2'!H4/'Tabla 2'!$F4*'Tabla 10'!G4 -> 0.30619993 | H4: ='Tabla 2'!I4/'Tabla 2'!$F4*'Tabla 10'!H4 -> 0.51496107 | I4: =SUM(F4:H4) -> 0.99999998 | J4: ='Tabla 2'!K4/'Tabla 2'!$J4*'Tabla 10'!F4 -> 0.18655163 | K4: ='Tabla 2'!L4/'Tabla 2'!$J4*'Tabla 10'!G4 -> 0.29543265 | L4: ='Tabla 2'!M4/'Tabla 2'!$J4*'Tabla 10'!H4 -> 0.51801572 | M4: =SUM(J4:L4) -> 1
A5: 2003 | B5: ='Tabla 2'!C5/'Tabla 2'!$B5*'Tabla 10'!F5 -> 0.20890899 | C5: ='Tabla 2'!D5/'Tabla 2'!$B5*'Tabla 10'!G5 -> 0.31916225 | D5: ='Tabla 2'!E5/'Tabla 2'!$B5*'Tabla 10'!H5 -> 0.47192877 | E5: =SUM(B5:D5) -> 1 | F5: ='Tabla 2'!G5/'Tabla 2'!$F5*'Tabla 10'!F5 -> 0.20135937 | G5: ='Tabla 2'!H5/'Tabla 2'!$F5*'Tabla 10'!G5 -> 0.31391083 | H5: ='Tabla 2'!I5/'Tabla 2'!$F5*'Tabla 10'!H5 -> 0.48472981 | I5: =SUM(F5:H5) -> 1 | J5: ='Tabla 2'!K5/'Tabla 2'!$J5*'Tabla 10'!F5 -> 0.20731107 | K5: ='Tabla 2'!L5/'Tabla 2'!$J5*'Tabla 10'!G5 -> 0.31165165 | L5: ='Tabla 2'!M5/'Tabla 2'!$J5*'Tabla 10'!H5 -> 0.48103731 | M5: =SUM(J5:L5) -> 1
