Workbook
Name qn: #REF!
Name qn: #REF!
Name qo210.: #REF!
Name qo210.: #REF!
Name QO21O: #REF!
Name QO21O: #REF!
Name TOTALD.21: #REF!
Name TOTALD.21: #REF!
Name TOTALOFERTA: #REF!
Name TOTALOFERTA: #REF!
Name TOTALP.1: #REF!
Name TOTALP.1: #REF!
Name TOTALP.2: #REF!
Name TOTALP.2: #REF!
Name TOTALP.3: #REF!
Name TOTALP.3: #REF!
Name TOTALP.31HOG: #REF!
Name TOTALP.31HOG: #REF!
Name TOTALP.5: #REF!
Name TOTALP.5: #REF!
Name TOTALP.51: #REF!
Name TOTALP.51: #REF!
Name TOTALP.52: #REF!
Name TOTALP.52: #REF!
Name TOTALP.6: #REF!
Name TOTALP.6: #REF!
Name TOTALP.7: #REF!
Name TOTALP.7: #REF!
Name TOTALP2EQ: #REF!
Name TOTALP2EQ: #REF!
Name TOTALP31ISFLSH: #REF!
Name TOTALP31ISFLSH: #REF!
Name TOTALP3GOB: #REF!
Name TOTALP3GOB: #REF!
Name TOTALUTILIZ.1: #REF!
Name TOTALUTILIZ.1: #REF!

Sheet sets
A1: ac | B1: a(ac) | C1: c(ac) | D1: ins(ac)
A2: a-agr | B2: a-agr | C2: c-agr | D2: hhd
A3: a-min | B3: a-min | C3: c-min | D3: gov
A4: a-food | B4: a-food | C4: c-food | D4: row
A5: a-refpet | B5: a-refpet | C5: c-refpet
A6: a-biofuels | B6: a-biofuels | C6: c-biofuels
A7: a-maq | B7: a-maq | C7: c-maq
A8: a-othmnfc | B8: a-othmnfc | C8: c-othmnfc
A9: a-othind | B9: a-othind | C9: c-othind
A10: a-trdtrns | B10: a-trdtrns | C10: c-trdtrns
A11: a-admpub | B11: a-admpub | C11: c-admpub
A12: a-othsvc | B12: a-othsvc | C12: c-othsvc
A13: c-agr
A14: c-min
A15: c-food
A16: c-refpet
A17: c-biofuels
A18: c-maq
A19: c-othmnfc
A20: c-othind
A21: c-trdtrns
A22: c-admpub
A23: c-othsvc
A24: lab
... A36: total

Sheet SAM
A1: SAM Brazil 2017; 1 000 000 R$
B2: a-agr | C2: a-min | D2: a-food | E2: a-refpet | F2: a-biofuels | G2: a-maq | H2: a-othmnfc | I2: a-othind | J2: a-trdtrns | K2: a-admpub | L2: a-othsvc | M2: c-agr | N2: c-min | O2: c-food | P2: c-refpet | Q2: c-biofuels | R2: c-maq | S2: c-othmnfc | T2: c-othind | U2: c-trdtrns | V2: c-admpub | W2: c-othsvc | X2: lab | Y2: cap | Z2: tax-act | AA2: tax-imp | AB2: tax-com | AC2: tax-dir | AD2: hhd | AE2: gov | AF2: row | AG2: sav-inv | AH2: dstk | AI2: total
A3: a-agr | M3: 524682 | N3: 269 | O3: 7563 | Q3: 25 | S3: 1205 | T3: 6613 | W3: 219 | AI3: =SUM(B3:AH3) -> 540576
A4: a-min | N4: 104418 | O4: 154 | P4: 138952 | R4: 336 | S4: 2070 | T4: 6464 | U4: 76 | W4: 819 | AI4: =SUM(B4:AH4) -> 253289
A5: a-food | N5: 67 | O5: 674106 | P5: 8 | Q5: 24835 | R5: 855 | S5: 4582 | U5: 8795 | W5: 1965 | AI5: =SUM(B5:AH5) -> 715213
A6: a-refpet | P6: 373076 | R6: 2 | S6: 391 | U6: 21 | W6: 272 | AI6: =SUM(B6:AH6) -> 373762
A7: a-biofuels | O7: 8958 | Q7: 38657 | R7: 284 | S7: 135 | U7: 154 | W7: 46 | AI7: =SUM(B7:AH7) -> 48234
A8: a-maq | P8: 161 | R8: 624074 | S8: 17516 | U8: 4301 | W8: 10347 | AI8: =SUM(B8:AH8) -> 656399
A9: a-othmnfc | N9: 1823 | O9: 2793 | P9: 2884 | Q9: 218 | R9: 11379 | S9: 1110909 | U9: 4302 | W9: 20888 | AI9: =SUM(B9:AH9) -> 1155196
A10: a-othind | R10: 38 | T10: 904913 | U10: 182 | W10: 8359 | AI10: =SUM(B10:AH10) -> 913492
A11: a-trdtrns | M11: 326 | N11: 112 | O11: 42540 | P11: 2981 | Q11: 607 | R11: 9702 | S11: 12356 | U11: 1661284 | W11: 34562 | AI11: =SUM(B11:AH11) -> 1764470
A12: a-admpub | M12: 768 | N12: 8 | R12: 213 | S12: 1044 | T12: 5967 | U12: 6169 | V12: 1259476 | W12: 68308 | AI12: =SUM(B12:AH12) -> 1341953
A13: a-othsvc | R13: 2491 | S13: 623 | U13: 2426 | W13: 3266668 | AI13: =SUM(B13:AH13) -> 3272208
A14: c-agr | B14: 25283.021 | C14: 1.6569795 | D14: 195689.27 | F14: 18441.353 | H14: 12805.137 | I14: 846.7165 | J14: 10162.255 | K14: 2675.1933 | L14: 8278.2693 | AD14: 131965.16 | AE14: 42.252976 | AF14: 126429 | AG14: 14928.556 | AH14: 7385.1574 | AI14: =SUM(B14:AH14) -> 554933
A15: c-min | B15: 444.25709 | C15: 3268.048 | D15: 354.97012 | E15: 35.569603 | F15: 237.37266 | G15: 136.47113 | H15: 36983.676 | I15: 8922.889 | J15: 77.672399 | K15: 84.205591 | L15: 395.6211 | AF15: 73400 | AH15: 1951.2468 | AI15: =SUM(B15:AH15) -> 126292
A16: c-food | B16: 17046.881 | C16: 27.059735 | D16: 98380.177 | F16: 3716.9553 | G16: 1.5033186 | H16: 5906.5388 | J16: 3747.0216 | K16: 10938.146 | L16: 73527.313 | AD16: 533563.86 | AE16: 177.3916 | AF16: 137722 | AH16: 1543.1566 | AI16: =SUM(B16:AH16) -> 886298
A17: c-refpet | B17: 19063.259 | C17: 17656.772 | D17: 9193.0637 | E17: 233006.9 | F17: 1036.4989 | G17: 3731.7501 | H17: 36632.403 | I17: 20737.059 | J17: 105343.16 | K17: 3313.964 | L17: 10078.204 | AD17: 169225.48 | AF17: 67589 | AG17: 4229.1988 | AH17: -7962.7191 | AI17: =SUM(B17:AH17) -> 692874
A18: c-biofuels | B18: 273.17487 | C18: 843.96197 | D18: 264.44724 | E18: 30840.832 | F18: 528.02171 | G18: 16.5825 | H18: 3782.5555 | I18: 328.15895 | J18: 1385.9479 | K18: 1030.7333 | L18: 606.57039 | AD18: 35817.327 | AF18: 2701 | AH18: 2560.6871 | AI18: =SUM(B18:AH18) -> 80980
A19: c-maq | B19: 462.34121 | C19: 17699.452 | D19: 3061.6009 | E19: 612.15909 | F19: 811.11079 | G19: 176941.36 | H19: 24053.019 | I19: 30577.347 | J19: 57096.723 | K19: 7027.7474 | L19: 28380.823 | AD19: 220473.93 | AE19: 12827.149 | AF19: 124138 | AG19: 247619.16 | AH19: -8024.9224 | AI19: =SUM(B19:AH19) -> 943757
A20: c-othmnfc | B20: 94725.196 | C20: 17700.869 | D20: 45317.789 | E20: 975.38665 | F20: 1356.0996 | G20: 120602.26 | H20: 347754.66 | I20: 131540.14 | J20: 48973.395 | K20: 25430.104 | L20: 91959.697 | AD20: 454988.56 | AE20: 6445.4707 | AF20: 178624 | AG20: 25783.406 | AH20: 4729.978 | AI20: =SUM(B20:AH20) -> 1596907
A21: c-othind | B21: 14154.513 | C21: 7491.3406 | D21: 7734.217 | E21: 487.74341 | F21: 208.0375 | G21: 5930.5617 | H21: 41899.15 | I21: 184346.11 | J21: 37461.68 | K21: 42557.106 | L21: 60403.538 | AD21: 142699.79 | AF21: 2819 | AG21: 469843.23 | AH21: 433.9921 | AI21: =SUM(B21:AH21) -> 1018470
A22: c-trdtrns | B22: 51832.529 | C22: 42925.407 | D22: 141712.16 | E22: 39714.546 | F22: 8478.1742 | G22: 110340.52 | H22: 201203.78 | I22: 66787.988 | J22: 201056.74 | K22: 31510.909 | L22: 109406.29 | AD22: 625281.3 | AE22: 5351.2716 | AF22: 27773 | AG22: 74036.659 | AH22: 1661.7256 | AI22: =SUM(B22:AH22) -> 1739073
A23: c-admpub | AE23: 1259476 | AI23: =SUM(B23:AH23) -> 1259476
A24: c-othsvc | B24: 14319.828 | C24: 55097.432 | D24: 67618.306 | E24: 11811.863 | F24: 3430.3765 | G24: 68441.995 | H24: 105127.08 | I24: 68584.595 | J24: 307837.4 | K24: 216409.89 | L24: 711610.67 | AD24: 1931083.6 | AE24: 59363.464 | AF24: 83239 | AG24: 122338.79 | AH24: 107.69787 | AI24: =SUM(B24:AH24) -> 3826422
A25: lab | B25: 109808.5 | C25: 27445.808 | D25: 85510.111 | E25: 7664 | F25: 6646 | G25: 113847.76 | H25: 214412.73 | I25: 185624.93 | J25: 585155.62 | K25: 897677 | L25: 981175.4 | AF25: 908 | AI25: =SUM(B25:AH25) -> 3215875.8
A26: cap | B26: 201153.5 | C26: 61289.192 | D26: 54089.889 | E26: 47753 | F26: 3081 | G26: 51337.242 | H26: 114651.27 | I26: 209085.07 | J26: 390371.38 | K26: 103129 | L26: 1164946.6 | AI26: =SUM(B26:AH26) -> 2400887.2
A27: tax-act | B27: -7991 | C27: 1842 | D27: 6287 | E27: 860 | F27: 263 | G27: 5071 | H27: 9984 | I27: 6111 | J27: 15801 | K27: 169 | L27: 31439 | AI27: =SUM(B27:AH27) -> 69836
A28: tax-imp | M28: 488 | N28: 24 | O28: 1385 | P28: 23 | Q28: 76 | R28: 13372 | S28: 16905 | W28: 11 | AI28: =SUM(B28:AH28) -> 32284
A29: tax-com | M29: 14656 | N29: 2476 | O29: 114057 | P29: 112063 | Q29: 13327 | R29: 95207 | S29: 183699 | T29: 87258 | U29: 33217 | W29: 225309 | AI29: =SUM(B29:AH29) -> 881269
A30: tax-dir | AD30: 1147901 | AI30: =SUM(B30:AH30) -> 1147901
A31: hhd | X31: 3215875.8 | Y31: 2400887.2 | AE31: 1886954 | AF31: 4982.8775 | AI31: =SUM(B31:AH31) -> 7508699.9
A32: gov | Z32: 69836 | AA32: 32284 | AB32: 881269 | AC32: 1147901 | AD32: 767036.88 | AF32: 2275.1225 | AI32: =SUM(B32:AH32) -> 2900602
A33: row | M33: 14013 | N33: 17095 | O33: 34742 | P33: 62726 | Q33: 3235 | R33: 185804 | S33: 245472 | T33: 7255 | U33: 18146 | W33: 188649 | AD33: 81430.014 | AE33: 42593.986 | AI33: =SUM(B33:AH33) -> 901161
A34: sav-inv | AD34: 1267233 | AE34: -372629 | AF34: 68561 | AI34: =SUM(B34:AH34) -> 963165
A35: dstk | AG35: 4386 | AI35: =SUM(B35:AH35) -> 4386
A36: total | B36: =SUM(B3:B35) -> 540576 | C36: =SUM(C3:C35) -> 253289 | D36: =SUM(D3:D35) -> 715213 | E36: =SUM(E3:E35) -> 373762 | F36: =SUM(F3:F35) -> 48234 | G36: =SUM(G3:G35) -> 656399 | H36: =SUM(H3:H35) -> 1155196 | I36: =SUM(I3:I35) -> 913492 | ... AH36: =SUM(AH3:AH35) -> 4386

Sheet SAM-agg
A1: SAM Brazil 2017; 1 000 000 R$; Source: sam-adj.gms; automatic
B2: a-agr | C2: a-livestock | D2: a-forfsh | E2: a-carbonminnmet | F2: a-petgas | G2: a-ironore | H2: a-nferrmetmin | I2: a-meatdairy | J2: a-sugar | K2: a-othfood | L2: a-bev | M2: a-tob | N2: a-textiles | O2: a-wapp | P2: a-leather | Q2: a-woodprod | R2: a-paper | S2: a-printing | T2: a-refpet | U2: a-biofuels | V2: a-chemicalsinorgorg | W2: a-othchemicals | X2: a-perfumery | Y2: a-pharmaceuticals | Z2: a-rubberplast | AA2: a-minnmetprod | AB2: a-steelferroalloys | AC2: a-castmetal | AD2: a-metprod | AE2: a-machineryoffice | AF2: a-machineryeqelect | AG2: a-machineryeqmechanic | AH2: a-carstrucks | AI2: a-autoparts | AJ2: a-othvehicles | AK2: a-othmnfc | AL2: a-repairmachinery | AM2: a-elegas | AN2: a-wat | AO2: a-cns | AP2: a-trdvehicles | AQ2: a-trd | AR2: a-trnsland | AS2: a-trnswat | AT2: a-trnsair | AU2: a-trnsauxpostal | AV2: a-hotel | AW2: a-rest | AX2: a-books | AY2: a-tvradio | AZ2: a-telecom | BA2: a-softwaredev | BB2: a-fin | BC2: a-realestate | BD2: a-legalaccounting | BE2: a-architect | BF2: a-otrprofessionals | BG2: a-intellectualprop | BH2: a-othadmsvc | BI2: a-svcsecurity | BJ2: a-admpub | BK2: a-edug | BL2: a-edung | BM2: a-healthg | BN2: a-healthng | BO2: a-recreation | BP2: a-organizations | BQ2: a-domest | BR2: c-cereal | BS2: c-corn | BT2: c-cotton | BU2: c-sugarcane | BV2: c-soy | BW2: c-othagrtemp | BX2: c-orange | BY2: c-coffee | BZ2: c-othagrpermanent | CA2: c-livestock | CB2: c-milkraw | CC2: c-pigs | CD2: c-poultry | CE2: c-for | CF2: c-fsh | CG2: c-coal | CH2: c-minnmet | CI2: c-petgas | CJ2: c-ironore | CK2: c-nferrmetmin | CL2: c-meatbeef | CM2: c-meatpork | CN2: c-meatpoultry | CO2: c-fshprod | CP2: c-milk | CQ2: c-dairy | CR2: c-sugar | CS2: c-fruitsprod | CT2: c-oilsfats | CU2: c-coffeeprod | CV2: c-riceprod | CW2: c-milling | CX2: c-animalfeed | CY2: c-othfood | CZ2: c-bev | DA2: c-tob | DB2: c-texfibers | DC2: c-fabrics | DD2: c-textiles | DE2: c-wapp | DF2: c-leather | DG2: c-woodprod | DH2: c-cellulose | DI2: c-paper | DJ2: c-printing | DK2: c-aviationfuel | DL2: c-gasalcohol | DM2: c-fuelpetrochemicals | DN2: c-fueloil | DO2: c-diesel | DP2: c-othrefpet | DQ2: c-ethanol | DR2: c-chemicalinorg | DS2: c-fertilizers | DT2: c-chemicalorg | DU2: c-resins | DV2: c-agrochemicals | DW2: c-othchemicals | DX2: c-paints | DY2: c-perfumery | DZ2: c-pharmaceuticals | EA2: c-rubber | EB2: c-plast | EC2: c-cement | ED2: c-cementprod | EE2: c-othminnmetprod | EF2: c-ferroalloys | EG2: c-steeltubes | EH2: c-nferrousmetprod | EI2: c-caststeelnferrousmet | EJ2: c-metprod | EK2: c-electcomponents | EL2: c-machineryoffice | EM2: c-eqcomm | EN2: c-eqoptical | EO2: c-machineryelect | EP2: c-homeappliances | EQ2: c-machineryagr | ER2: c-machinerymin | ES2: c-othmachinery | ET2: c-cars | EU2: c-trucks | EV2: c-autoparts | EW2: c-aircraft | EX2: c-furniture | EY2: c-othmnfc | EZ2: c-repairmachinery | FA2: c-elegas | FB2: c-wat | FC2: c-cns | FD2: c-cnsinfra | FE2: c-cnssvc | FF2: c-trdvehicles | FG2: c-trd | FH2: c-trnsfreight | FI2: c-trnspassenger | FJ2: c-trnswat | FK2: c-trnsair | FL2: c-trnsaux | FM2: c-postal | FN2: c-hotel | FO2: c-rest | FP2: c-books | FQ2: c-tvradio | FR2: c-telecom | FS2: c-softwaredev | FT2: c-fin | FU2: c-realestate | FV2: c-imputedrent | FW2: c-legalaccounting | FX2: c-researchdev | FY2: c-architect | FZ2: c-otrprofessionals | GA2: c-intellectualprop | GB2: c-buildingsvc | GC2: c-othadmsvc | GD2: c-svcsecurity | GE2: c-admpub | GF2: c-socsec | GG2: c-edug | GH2: c-edung | GI2: c-healthg | GJ2: c-healthng | GK2: c-recreation | GL2: c-organizations | GM2: c-mainthhappliances | GN2: c-personalsvc | GO2: c-domest | GP2: marg-d | GQ2: marg-m | GR2: marg-e | GS2: f-lab | GT2: f-cap | GU2: f-land | GV2: f-natres-forfsh | GW2: f-natres-carbonminnmet | GX2: f-natres-petgas | GY2: f-natres-ironore | GZ2: f-natres-nferrmetmin | HA2: hhd | HB2: npish | HC2: ent | HD2: gov | HE2: row | HF2: cssec | HG2: tax-act | HH2: sub-act | HI2: tax-imp | HJ2: tax-ipi | HK2: tax-icms | HL2: tax-com | HM2: tax-dir | HN2: cap-hhd | HO2: cap-npish | HP2: cap-ent | HQ2: cap-gov | HR2: cap-row | HS2: inv-prv | HT2: inv-gov | HU2: dstk | HV2: total
A3: a-agr | BR3: 11034 | BS3: 28441 | BT3: 9737 | BU3: 55067 | BV3: 124932 | BW3: 57953 | BX3: 8963 | BY3: 18151 | BZ3: 25346 | CA3: 4866 | CB3: 2672 | CC3: 536 | CD3: 562 | CE3: 969 | CF3: 433 | CH3: 47 | CL3: 111 | CM3: 28 | CQ3: 137 | CR3: 183 | CS3: 70 | CT3: 13 | CU3: 105 | CV3: 577 | CW3: 2361 | CY3: 18 | CZ3: 202 | DA3: 117 | DB3: 834 | DG3: 15 | DQ3: 25 | FC3: 528 | FD3: 3 | FE3: 1744 | FN3: 27 | FU3: 40 | HV3: 356847
A4: a-livestock | BR4: 329 | BS4: 1645 | BT4: 8 | BU4: 291 | BV4: 3227 | BW4: 2365 | BX4: 67 | BY4: 760 | BZ4: 569 | CA4: 66819 | CB4: 24512 | CC4: 9135 | CD4: 28216 | CE4: 1237 | CF4: 507 | CH4: 204 | CL4: 405 | CM4: 49 | CN4: 27 | CQ4: 1294 | CR4: 63 | CS4: 33 | CT4: 3 | CU4: 52 | CV4: 36 | CW4: 861 | CY4: 25 | CZ4: 256 | DA4: 67 | DB4: 326 | DG4: 21 | FC4: 907 | FD4: 6 | FE4: 3129 | FN4: 109 | FU4: 23 | HV4: 147583
A5: a-forfsh | BR5: 9 | BS5: 57 | BU5: 1 | BV5: 55 | BW5: 132 | BY5: 21 | BZ5: 121 | CA5: 248 | CB5: 74 | CD5: 16 | CE5: 21240 | CF5: 13359 | CH5: 18 | CL5: 4 | CM5: 1 | CO5: 8 | CQ5: 4 | CR5: 4 | CS5: 35 | CT5: 2 | CU5: 2 | CV5: 8 | CW5: 391 | CY5: 3 | CZ5: 7 | DA5: 1 | DB5: 5 | DG5: 4 | FC5: 65 | FE5: 231 | FN5: 12 | FU5: 8 | HV5: 36146
A6: a-carbonminnmet | CG6: 996 | CH6: 16490 | CK6: 7 | CX6: 40 | CY6: 106 | CZ6: 8 | DP6: 40 | DR6: 140 | DS6: 18 | DU6: 6 | DW6: 10 | EC6: 240 | ED6: 88 | EE6: 397 | EF6: 23 | EJ6: 15 | ES6: 10 | EV6: 87 | FG6: 69 | FU6: 35 | FX6: 7 | HV6: 18832
A7: a-petgas | CH7: 62 | CI7: 136890 | DP7: 2022 | EJ7: 22 | ER7: 211 | EZ7: 28 | FD7: 6464 | FU7: 471 | FX7: 24 | HV7: 146194
A8: a-ironore | CJ8: 71286 | CK8: 36 | FG8: 7 | FU8: 6 | FX8: 255 | HV8: 71590
A9: a-nferrmetmin | CH9: 61 | CK9: 15480 | DR9: 20 | DW9: 196 | EB9: 9 | EF9: 118 | EH9: 768 | FX9: 21 | HV9: 16673
A10: a-meatdairy | CL10: 127209 | CM10: 15583 | CN10: 52682 | CO10: 4447 | CP10: 16064 | CQ10: 50639 | CS10: 382 | CT10: 1103 | CX10: 887 | CY10: 1598 | CZ10: 158 | DE10: 19 | DF10: 51 | DT10: 6 | DW10: 123 | DZ10: 31 | EB10: 33 | ES10: 1 | FG10: 886 | FU10: 59 | FX10: 381 | HV10: 272342
A11: a-sugar | CR11: 40822 | CU11: 15 | CV11: 100 | CW11: 16 | CY11: 38 | CZ11: 116 | DQ11: 19657 | DR11: 9 | ES11: 510 | EZ11: 13 | FG11: 1208 | FU11: 115 | FX11: 40 | HV11: 62659
A12: a-othfood | CH12: 67 | CL12: 1048 | CM12: 95 | CN12: 1540 | CO12: 46 | CP12: 15 | CQ12: 1130 | CR12: 492 | CS12: 26799 | CT12: 56805 | CU12: 13263 | CV12: 14348 | CW12: 34807 | CX12: 31821 | CY12: 90013 | CZ12: 2323 | DB12: 9 | DF12: 30 | DP12: 8 | DQ12: 5070 | DR12: 31 | DS12: 592 | DT12: 763 | DU12: 14 | DV12: 33 | DW12: 2009 | DY12: 152 | DZ12: 330 | EA12: 8 | EB12: 36 | EJ12: 37 | ES12: 116 | EY12: 7 | FG12: 5461 | FU12: 824 | FX12: 245 | HV12: 290387
A13: a-bev | CR13: 9 | CS13: 541 | CW13: 69 | CY13: 267 | CZ13: 72017 | DQ13: 108 | DW13: 38 | EJ13: 221 | ES13: 214 | FG13: 1154 | FU13: 228 | FX13: 6 | HV13: 74872
A14: a-tob | DA14: 14799 | ES14: 1 | FG14: 86 | FU14: 7 | FX14: 60 | HV14: 14953
A15: a-textiles | CT15: 6 | DB15: 8826 | DC15: 18151 | DD15: 21202 | DE15: 485 | DF15: 56 | DG15: 12 | DI15: 6 | DJ15: 14 | DR15: 9 | DT15: 9 | DU15: 477 | EA15: 20 | EB15: 369 | EE15: 36 | EG15: 8 | EH15: 14 | EJ15: 38 | EO15: 32 | EQ15: 11 | ER15: 7 | ES15: 5 | EU15: 19 | EV15: 218 | EX15: 22 | EY15: 272 | FG15: 129 | FU15: 346 | FX15: 31 | HV15: 50830
A16: a-wapp | DB16: 19 | DC16: 395 | DD16: 229 | DE16: 62602 | DF16: 324 | DI16: 10 | DU16: 6 | EA16: 7 | EB16: 11 | EJ16: 13 | ES16: 12 | EY16: 101 | FG16: 281 | FU16: 85 | FX16: 69 | HV16: 64164
A17: a-leather | CL17: 720 | DD17: 39 | DE17: 127 | DF17: 42353 | DJ17: 16 | DU17: 16 | DW17: 14 | EA17: 51 | EB17: 109 | EJ17: 7 | ES17: 3 | EV17: 20 | EY17: 16 | FG17: 25 | FU17: 18 | FX17: 289 | HV17: 43823
A18: a-woodprod | CS18: 7 | CW18: 19 | DG18: 27814 | DH18: 9 | DI18: 8 | EG18: 19 | EJ18: 18 | ES18: 8 | EX18: 68 | EY18: 21 | FG18: 53 | FU18: 704 | FX18: 34 | HV18: 28782
A19: a-paper | CW19: 14 | DD19: 16 | DF19: 23 | DG19: 41 | DH19: 26918 | DI19: 61024 | DJ19: 234 | DR19: 10 | DU19: 6 | DW19: 12 | DY19: 338 | EB19: 345 | EH19: 31 | EJ19: 18 | EL19: 13 | EY19: 64 | EZ19: 82 | FG19: 90 | FU19: 1605 | FX19: 241 | HV19: 91125
A20: a-printing | DD20: 10 | DF20: 8 | DI20: 534 | DJ20: 16792 | DX20: 30 | EB20: 32 | EK20: 20 | ES20: 32 | EY20: 327 | FG20: 79 | FU20: 980 | FX20: 34 | HV20: 18878
A21: a-refpet | CI21: 55 | DK21: 11105 | DL21: 98882 | DM21: 5513 | DN21: 15405 | DO21: 113896 | DP21: 128220 | DR21: 93 | DT21: 47 | DW21: 245 | DX21: 6 | ES21: 2 | FG21: 21 | FU21: 272 | HV21: 373762
A22: a-biofuels | CR22: 8269 | CT22: 469 | CW22: 36 | CY22: 16 | CZ22: 168 | DQ22: 38657 | DT22: 39 | DY22: 96 | ES22: 284 | FG22: 154 | FU22: 46 | HV22: 48234
A23: a-chemicalsinorgorg | CH23: 309 | CJ23: 8 | CK23: 22 | CL23: 79 | CS23: 7 | CT23: 115 | CV23: 16 | CW23: 58 | CX23: 36 | CY23: 101 | DB23: 19 | DP23: 2530 | DQ23: 36 | DR23: 26313 | DS23: 40219 | DT23: 38826 | DU23: 36915 | DV23: 160 | DW23: 1910 | DX23: 275 | DY23: 912 | DZ23: 97 | EA23: 81 | EB23: 635 | EE23: 129 | EF23: 44 | EH23: 6 | ES23: 275 | EV23: 16 | EW23: 7 | EY23: 24 | FG23: 601 | FU23: 2367 | FX23: 505 | HV23: 153653
A24: a-othchemicals | CH24: 18 | CR24: 7 | CS24: 38 | CT24: 24 | CW24: 18 | CX24: 17 | CY24: 391 | CZ24: 38 | DD24: 26 | DF24: 89 | DG24: 10 | DI24: 8 | DJ24: 9 | DP24: 223 | DQ24: 42 | DR24: 798 | DS24: 350 | DT24: 1959 | DU24: 1505 | DV24: 30379 | DW24: 22595 | DX24: 15678 | DY24: 630 | DZ24: 270 | EA24: 101 | EB24: 55 | EC24: 10 | EE24: 119 | EF24: 119 | EH24: 25 | EJ24: 58 | ES24: 76 | EU24: 8 | EV24: 38 | EY24: 49 | FG24: 523 | FU24: 1092 | FX24: 833 | HV24: 78228
A25: a-perfumery | CL25: 29 | CT25: 44 | CW25: 49 | CY25: 189 | DD25: 45 | DI25: 292 | DJ25: 231 | DP25: 39 | DQ25: 140 | DR25: 282 | DT25: 414 | DU25: 118 | DV25: 856 | DW25: 286 | DX25: 111 | DY25: 40739 | DZ25: 78 | EB25: 78 | EE25: 8 | EH25: 6 | EJ25: 265 | ES25: 62 | EY25: 617 | FG25: 189 | FU25: 55 | FX25: 338 | HV25: 45560
A26: a-pharmaceuticals | CX26: 106 | CY26: 422 | CZ26: 39 | DR26: 33 | DT26: 192 | DU26: 16 | DV26: 228 | DW26: 27 | DY26: 505 | DZ26: 59999 | EA26: 7 | EB26: 18 | EY26: 1294 | FG26: 174 | FU26: 479 | FX26: 1004 | HV26: 64543
A27: a-rubberplast | CZ27: 195 | DC27: 216 | DD27: 1123 | DF27: 204 | DG27: 34 | DI27: 471 | DJ27: 93 | DR27: 28 | DT27: 76 | DU27: 558 | DW27: 142 | DZ27: 18 | EA27: 27083 | EB27: 69735 | ED27: 28 | EE27: 121 | EG27: 50 | EH27: 129 | EI27: 28 | EJ27: 430 | EM27: 125 | EN27: 12 | EO27: 150 | EP27: 274 | EQ27: 120 | ER27: 7 | ES27: 1041 | EU27: 170 | EV27: 990 | EW27: 109 | EX27: 230 | EY27: 609 | FG27: 416 | FU27: 1834 | FX27: 287 | HV27: 107136
A28: a-minnmetprod | CH28: 920 | CJ28: 6 | CK28: 12 | DC28: 16 | DD28: 67 | DI28: 69 | DP28: 27 | DR28: 193 | DS28: 9 | DT28: 50 | DU28: 37 | DW28: 379 | DX28: 279 | DY28: 18 | DZ28: 222 | EB28: 272 | EC28: 10759 | ED28: 18163 | EE28: 42980 | EG28: 26 | EH28: 16 | EJ28: 65 | EN28: 35 | EO28: 56 | EP28: 39 | EQ28: 45 | ES28: 108 | EU28: 99 | EV28: 244 | EX28: 8 | EY28: 100 | FG28: 406 | FU28: 1100 | FX28: 172 | HV28: 76997
A29: a-steelferroalloys | CJ29: 235 | CK29: 240 | DP29: 35 | DR29: 64 | DT29: 50 | DU29: 180 | DW29: 123 | EB29: 95 | EC29: 370 | EF29: 13578 | EG29: 90231 | EH29: 318 | EJ29: 2728 | EO29: 12 | ER29: 129 | ES29: 396 | EV29: 49 | EW29: 13 | EX29: 6 | FG29: 61 | FU29: 1999 | FX29: 276 | HV29: 111188
A30: a-castmetal | CK30: 43 | DI30: 10 | DR30: 1548 | DW30: 28 | EB30: 28 | EF30: 53 | EG30: 107 | EH30: 46358 | EI30: 5428 | EJ30: 566 | EO30: 354 | EQ30: 89 | ER30: 50 | ES30: 318 | EU30: 21 | EV30: 315 | EW30: 44 | EY30: 81 | EZ30: 11 | FG30: 225 | FU30: 2370 | FX30: 76 | HV30: 58123
A31: a-metprod | CI31: 14 | CK31: 10 | DC31: 6 | DD31: 52 | DF31: 8 | DG31: 74 | DI31: 10 | DJ31: 8 | DR31: 54 | DS31: 12 | DU31: 105 | DW31: 35 | DX31: 10 | DY31: 45 | EA31: 19 | EB31: 486 | ED31: 20 | EE31: 72 | EG31: 3227 | EH31: 662 | EI31: 31 | EJ31: 79689 | EL31: 8 | EM31: 94 | EN31: 53 | EO31: 632 | EP31: 376 | EQ31: 165 | ER31: 99 | ES31: 1182 | EU31: 197 | EV31: 366 | EW31: 496 | EX31: 335 | EY31: 169 | EZ31: 400 | FG31: 616 | FU31: 1210 | FX31: 81 | HV31: 91128
A32: a-machineryoffice | DD32: 59 | DF32: 14 | DI32: 27 | DJ32: 62 | DW32: 30 | EB32: 145 | EG32: 19 | EJ32: 127 | EK32: 5734 | EL32: 19270 | EM32: 48786 | EN32: 7776 | EO32: 1490 | EP32: 592 | EQ32: 29 | ES32: 2528 | EU32: 7 | EV32: 142 | EY32: 522 | EZ32: 170 | FG32: 918 | FU32: 119 | FX32: 1053 | GM32: 823 | HV32: 90442
A33: a-machineryeqelect | DD33: 11 | DJ33: 14 | DR33: 9 | DU33: 27 | DW33: 49 | EA33: 13 | EB33: 222 | EE33: 31 | EG33: 341 | EH33: 546 | EI33: 6 | EJ33: 448 | EK33: 344 | EL33: 93 | EM33: 654 | EN33: 277 | EO33: 45452 | EP33: 17342 | EQ33: 42 | ES33: 1761 | EV33: 532 | EW33: 93 | EX33: 138 | EZ33: 270 | FG33: 486 | FU33: 994 | FX33: 610 | HV33: 70805
A34: a-machineryeqmechanic | CI34: 161 | DD34: 13 | DE34: 9 | DG34: 22 | DI34: 22 | DJ34: 37 | DR34: 7 | DT34: 15 | DU34: 28 | DW34: 26 | DX34: 51 | DY34: 45 | EA34: 170 | EB34: 280 | EE34: 40 | EG34: 707 | EH34: 237 | EI34: 19 | EJ34: 2189 | EK34: 23 | EL34: 783 | EM34: 6 | EN34: 386 | EO34: 1284 | EP34: 317 | EQ34: 27082 | ER34: 16239 | ES34: 60299 | ET34: 7 | EU34: 124 | EV34: 775 | EW34: 110 | EX34: 120 | EY34: 33 | EZ34: 914 | FG34: 753 | FU34: 100 | FX34: 1924 | HV34: 115357
A35: a-carstrucks | DD35: 39 | EB35: 17 | EE35: 39 | EG35: 15 | EJ35: 34 | EO35: 1019 | EQ35: 40 | ER35: 44 | ES35: 176 | ET35: 135739 | EU35: 34416 | EV35: 1196 | EW35: 530 | FF35: 1830 | FU35: 104 | FX35: 1058 | HV35: 176296
A36: a-autoparts | DD36: 65 | DF36: 69 | EA36: 372 | EB36: 213 | EE36: 207 | EG36: 214 | EH36: 117 | EI36: 6 | EJ36: 1534 | EK36: 7 | EM36: 43 | EN36: 481 | EO36: 1114 | EP36: 97 | EQ36: 438 | ER36: 134 | ES36: 2296 | EU36: 679 | EV36: 79016 | EW36: 317 | EX36: 73 | EZ36: 7 | FF36: 269 | FU36: 736 | FX36: 571 | HV36: 89075
A37: a-othvehicles | EB37: 74 | ED37: 6 | EG37: 167 | EJ37: 517 | EO37: 55 | ER37: 66 | ES37: 261 | EV37: 124 | EW37: 38397 | EX37: 42 | EY37: 91 | EZ37: 191 | FG37: 45 | FU37: 156 | FX37: 2004 | HV37: 42196
A38: a-othmnfc | CL38: 9 | DB38: 9 | DC38: 43 | DD38: 325 | DE38: 127 | DF38: 14 | DG38: 170 | DI38: 13 | DJ38: 13 | DP38: 16 | DR38: 21 | DT38: 14 | DU38: 80 | DW38: 49 | DY38: 112 | DZ38: 195 | EA38: 25 | EB38: 630 | ED38: 66 | EE38: 184 | EG38: 10 | EH38: 28 | EI38: 9 | EJ38: 853 | EL38: 8 | EM38: 6 | EN38: 128 | EO38: 37 | EP38: 64 | EQ38: 43 | ES38: 469 | EW38: 163 | EX38: 36799 | EY38: 29474 | EZ38: 24 | FG38: 434 | FU38: 270 | FX38: 104 | HV38: 71038
A39: a-repairmachinery | DC39: 17 | DR39: 16 | EA39: 19 | EG39: 32 | EI39: 7 | EJ39: 352 | EN39: 87 | EO39: 167 | EP39: 9 | ER39: 46 | ES39: 576 | EU39: 14 | EV39: 40 | EW39: 321 | EX39: 29 | EY39: 95 | EZ39: 70306 | FU39: 47 | FX39: 48 | HV39: 72228
A40: a-elegas | ES40: 1 | FA40: 287678 | FG40: 20 | FU40: 4524 | FX40: 278 | HV40: 292501
...

Sheet tradelas
A1: tradelas(c,trdelas)
B2: sigma_Q | C2: sigma_X
A3: c-agr | B3: 2 | C3: 2
A4: c-min | B4: 2 | C4: 2
A5: c-food | B5: 2 | C5: 2
A6: c-refpet | B6: 2 | C6: 2
A7: c-biofuels | B7: 2 | C7: 2
A8: c-maq | B8: 2 | C8: 2
A9: c-othmnfc | B9: 2 | C9: 2
A10: c-othind | B10: 2 | C10: 2
A11: c-trdtrns | B11: 2 | C11: 2
A12: c-admpub | B12: 2 | C12: 2
A13: c-othsvc | B13: 2 | C13: 2

Sheet layout
D1: rdim | E1: cdim
A2: set | B2: ac | C2: sets!a2 | D2: 1 | E2: 0
A3: set | B3: a | C3: sets!b2 | D3: 1 | E3: 0
A4: set | B4: c | C4: sets!c2 | D4: 1 | E4: 0
A5: set | B5: ins | C5: sets!d2 | D5: 1 | E5: 0
A6: par | B6: SAM | C6: SAM!A2 | D6: 1 | E6: 1
A7: par | B7: tradelas | C7: tradelas!A2 | D7: 1 | E7: 1

Sheet agg
A1: a-agr | B1: a-agr | D1: c-cereal | E1: c-agr | G1: marg-d | H1: marg-d | J1: a-agr | K1: c-agr
A2: a-livestock | B2: a-agr | D2: c-corn | E2: c-agr | G2: marg-m | H2: marg-m | J2: a-min | K2: c-min
A3: a-forfsh | B3: a-agr | D3: c-cotton | E3: c-agr | G3: marg-e | H3: marg-e | J3: a-food | K3: c-food
A4: a-carbonminnmet | B4: a-min | D4: c-sugarcane | E4: c-agr | G4: f-lab | H4: lab | J4: a-refpet | K4: c-refpet
A5: a-petgas | B5: a-min | D5: c-soy | E5: c-agr | G5: f-cap | H5: cap | J5: a-biofuels | K5: c-biofuels
A6: a-ironore | B6: a-min | D6: c-othagrtemp | E6: c-agr | G6: f-land | H6: cap | J6: a-maq | K6: c-maq
A7: a-nferrmetmin | B7: a-min | D7: c-orange | E7: c-agr | G7: f-natres-forfsh | H7: cap | J7: a-othmnfc | K7: c-othmnfc
A8: a-meatdairy | B8: a-food | D8: c-coffee | E8: c-agr | G8: f-natres-carbonminnmet | H8: cap | J8: a-othind | K8: c-othind
A9: a-sugar | B9: a-food | D9: c-othagrpermanent | E9: c-agr | G9: f-natres-petgas | H9: cap | J9: a-trdtrns | K9: c-trdtrns
A10: a-othfood | B10: a-food | D10: c-livestock | E10: c-agr | G10: f-natres-ironore | H10: cap | J10: a-admpub | K10: c-admpub
A11: a-bev | B11: a-food | D11: c-milkraw | E11: c-agr | G11: f-natres-nferrmetmin | H11: cap | J11: a-othsvc | K11: c-othsvc
A12: a-tob | B12: a-food | D12: c-pigs | E12: c-agr | G12: f-ext | H12: cap
A13: a-refpet | B13: a-refpet | D13: c-poultry | E13: c-agr | G13: hhd | H13: hhd
A14: a-biofuels | B14: a-biofuels | D14: c-for | E14: c-agr | G14: npish | H14: npish
A15: a-machineryoffice | B15: a-maq | D15: c-fsh | E15: c-agr | G15: ent | H15: ent
A16: a-machineryeqelect | B16: a-maq | D16: c-coal | E16: c-min | G16: gov | H16: gov
A17: a-machineryeqmechanic | B17: a-maq | D17: c-minnmet | E17: c-min | G17: row | H17: row
A18: a-carstrucks | B18: a-maq | D18: c-ironore | E18: c-min | G18: cssec | H18: cssec
A19: a-autoparts | B19: a-maq | D19: c-nferrmetmin | E19: c-min | G19: tax-act | H19: tax-act
A20: a-othvehicles | B20: a-maq | D20: c-meatbeef | E20: c-food | G20: sub-act | H20: sub-act
A21: a-repairmachinery | B21: a-maq | D21: c-meatpork | E21: c-food | G21: tax-ipi | H21: tax-com
A22: a-textiles | B22: a-othmnfc | D22: c-meatpoultry | E22: c-food | G22: tax-icms | H22: tax-com
A23: a-wapp | B23: a-othmnfc | D23: c-fshprod | E23: c-food | G23: tax-com | H23: tax-com
... A35: a-castmetal | B35: a-othmnfc | D35: c-tob | E35: c-food | G35: total | H35: total
A36: a-metprod | B36: a-othmnfc | D36: c-petgas | E36: c-refpet
A37: a-othmnfc | B37: a-othmnfc | D37: c-aviationfuel | E37: c-refpet
A38: a-elegas | B38: a-othind | D38: c-gasalcohol | E38: c-refpet
A39: a-wat | B39: a-othind | D39: c-fuelpetrochemicals | E39: c-refpet
A40: a-cns | B40: a-othind | D40: c-fueloil | E40: c-refpet
A41: a-trdvehicles | B41: a-trdtrns | D41: c-diesel | E41: c-refpet
A42: a-trd | B42: a-trdtrns | D42: c-othrefpet | E42: c-refpet
A43: a-trnsland | B43: a-trdtrns | D43: c-ethanol | E43: c-biofuels
A44: a-trnswat | B44: a-trdtrns | D44: c-machineryoffice | E44: c-maq
A45: a-trnsair | B45: a-trdtrns | D45: c-eqcomm | E45: c-maq
A46: a-trnsauxpostal | B46: a-trdtrns | D46: c-eqoptical | E46: c-maq
A47: a-admpub | B47: a-admpub | D47: c-machineryelect | E47: c-maq
... A68: a-domest | B68: a-othsvc | D68: c-chemicalorg | E68: c-othmnfc
D69: c-resins | E69: c-othmnfc
D70: c-agrochemicals | E70: c-othmnfc
D71: c-othchemicals | E71: c-othmnfc
...

Sheet names
A1: act | E1: com
A2: 191 | B2: Agricultura, inclusive o apoio à agricultura e a pós-colheita | C2: a-agr | E2: 1911 | F2: Arroz, trigo e outros cereais | G2: c-cereal
A3: 192 | B3: Pecuária, inclusive o apoio à pecuária | C3: a-livestock | E3: 1912 | F3: Milho em grão | G3: c-corn
A4: 280 | B4: Produção florestal; pesca e aquicultura | C4: a-forfsh | E4: 1913 | F4: Algodão herbáceo, outras fibras da lav. temporária | G4: c-cotton
A5: 580 | B5: Extração de carvão mineral e de minerais não-metálicos | C5: a-carbonminnmet | E5: 1914 | F5: Cana-de-açúcar | G5: c-sugarcane
A6: 680 | B6: Extração de petróleo e gás, inclusive as atividades de apoio | C6: a-petgas | E6: 1915 | F6: Soja em grão | G6: c-soy
A7: 791 | B7: Extração de minério de ferro, inclusive beneficiamentos e a aglomeração | C7: a-ironore | E7: 1916 | F7: Outros produtos e serviços da lavoura temporária | G7: c-othagrtemp
A8: 792 | B8: Extração de minerais metálicos não-ferrosos, inclusive beneficiamentos | C8: a-nferrmetmin | E8: 1917 | F8: Laranja | G8: c-orange
A9: 1091 | B9: Abate e produtos de carne, inclusive os produtos do laticínio e da pesca | C9: a-meatdairy | E9: 1918 | F9: Café em grão | G9: c-coffee
A10: 1092 | B10: Fabricação e refino de açúcar | C10: a-sugar | E10: 1919 | F10: Outros produtos da lavoura permanente | G10: c-othagrpermanent
A11: 1093 | B11: Outros produtos alimentares | C11: a-othfood | E11: 1920 | F11: Bovinos e outros animais vivos, prods. animal, caça e serv. | G11: c-livestock
A12: 1100 | B12: Fabricação de bebidas | C12: a-bev | E12: 1921 | F12: Leite de vaca e de outros animais | G12: c-milkraw
A13: 1200 | B13: Fabricação de produtos do fumo | C13: a-tob | E13: 1922 | F13: Suínos | G13: c-pigs
... A69: 9700 | B69: Serviços domésticos | C69: a-domest | E69: 24912 | F69: Semi-acabacados, laminados planos, longos e tubos de aço | G69: c-steeltubes
E70: 24921 | F70: Produtos da metalurgia de metais não-ferrosos | G70: c-nferrousmetprod
E71: 24922 | F71: Peças fundidas de aço e de metais não ferrosos | G71: c-caststeelnferrousmet
E72: 25001 | F72: Produtos de metal, excl. máquinas e equipamentos | G72: c-metprod
E73: 26001 | F73: Componentes eletrônicos | G73: c-electcomponents
E74: 26002 | F74: Máquinas para escritório e equip. de informática | G74: c-machineryoffice
E75: 26003 | F75: Material eletrônico e equip. de comunicações | G75: c-eqcomm
E76: 26004 | F76: Equip. de medida, teste e controle, ópticos e eletromédicos | G76: c-eqoptical
E77: 27001 | F77: Máquinas, aparelhos e materiais elétricos | G77: c-machineryelect
E78: 27002 | F78: Eletrodomésticos | G78: c-homeappliances
E79: 28001 | F79: Tratores e outras máquinas agrícolas | G79: c-machineryagr
E80: 28002 | F80: Máquinas para a extração mineral e a construção | G80: c-machinerymin
E81: 28003 | F81: Outras máquinas e equipamentos mecânicos | G81: c-othmachinery
... E129: 97001 | F129: Serviços domésticos | G129: c-domest

Sheet tables_agg
A1: Tabla 1. Producto Bruto Interno (Año base, 2017) | E1: Tabla 2. Cuenta corriente de la balanza de pagos (Año base, 2017) | I1: Tabla 3. Presupuesto del gobierno (Año base, 2017) | M1: Tabla 4. Estructura sectorial (%) (Año base, 2017) | V1: Tabla 5. Intensidad de uso factorial (%) (Año base, 2017) | AA1: Tabla 6. Estructura de la demanda (%) (Año base, 2017) | AJ1: Tabla 7. Estructura de los ingresos de las instituciones (Año base, 2017)
A3: Ítem | B3: Nominal | C3: PBI Share (%) | E3: Ítem | F3: Nominal | G3: PBI Share (%) | I3: Ítem | J3: Nominal | K3: PBI Share (%) | M3: Producto | N3: VA Share | O3: VBP Share | P3: Salario Share | Q3: Expo. Share | R3: Expo/Prod. | S3: Impo. Share | T3: Impo./Dem. | V3: Actividad | W3: Trabajo | X3: Capital | Y3: Total | AA3: Producto | AB3: Consumo Intermedio | AC3: Consumo Privado | AD3: Consumo Público | AE3: Formación Bruta de Capital | AF3: Variación de Existencias | AG3: Exportaciones | AH3: Total Demanda | AJ3: Ítem | AK3: Hogares | AL3: Gobierno | AM3: Resto del mundo
A4: Absorción | B4: =SUM(B5:B8) -> 6460840 | C4: =B4/$B$12 -> 0.99273264 | E4: Exportaciones | F4: =SUM('SAM-agg'!HE71:HE198) -> 824434 | G4: =F4/$B$12 -> 0.12667742 | I4: Impuestos directos | J4: ='SAM-agg'!HM213 -> 539719 | K4: =J4/$B$12 -> 0.082929877 | M4: c-agr | N4: =SUM('SAM-agg'!B$202:D$209)/SUM('SAM-agg'!B$202:BQ$209) -> 0.060414288 | O4: =SUM('SAM-agg'!BR$3:CF$70)/SUM('SAM-agg'!HV$3:HV$70) -> 0.047647115 | P4: =SUM('SAM-agg'!B$202:D$202)/SUM('SAM-agg'!B$202:BQ$202) -> 0.038891381 | Q4: =SUM('SAM-agg'!$HE71:$HE85)/SUM('SAM-agg'!HE$71:HE$198) -> 0.15335248 | R4: =SUM('SAM-agg'!$HE71:$HE85)/SUM('SAM-agg'!$BR$3:$CF$70) -> 0.24046172 | S4: =SUM('SAM-agg'!$BR$214:$CF$214)/SUM('SAM-agg'!BR$214:GO$214) -> 0.01803157 | T4: =SUM('SAM-agg'!$BR$214:$CF$214,'SAM-agg'!$BR$218:$CF$218)/(SUM('SAM-agg'!$BR$3:$CF$70)-SUM('SAM-agg'!HE71:HE85)+SUM('SAM-agg'!$BR$214:$CF$214,'SAM-agg'!$BR$218:$CF$218)+SUM('SAM-agg'!BR$221:CF$221)) -> 0.034575996 | V4: a-agr | W4: =SUM('SAM-agg'!$B$202:$D$202)/SUM('SAM-agg'!$B$202:$D$209) -> 0.33510669 | X4: =SUM('SAM-agg'!$B$203:$D$209)/SUM('SAM-agg'!$B$202:$D$209) -> 0.66489331 | Y4: =SUM(W4:X4) -> 1 | AA4: c-agr | AB4: =SUM('SAM-agg'!B71:BQ85)/SUM('SAM-agg'!$HV71:$HV85) -> 0.51417407 | AC4: =SUM('SAM-agg'!HA71:HA85)/SUM('SAM-agg'!$HV71:$HV85) -> 0.24747374 | AD4: =SUM('SAM-agg'!HD71:HD85)/SUM('SAM-agg'!$HV71:$HV85) -> 7.923684e-05 | AE4: =SUM('SAM-agg'!HN71:HT85)/SUM('SAM-agg'!$HV71:$HV85) -> 0.027995463 | AF4: =SUM('SAM-agg'!HU71:HU85)/SUM('SAM-agg'!$HV71:$HV85) -> 0.013849357 | AG4: =SUM('SAM-agg'!HE71:HE85)/SUM('SAM-agg'!$HV71:$HV85) -> 0.19642813 | AH4: =SUM(AB4:AG4) -> 1 | AJ4: Impuestos netos | AL4: =SUM('SAM-agg'!HG213:HM213)/'SAM-agg'!HV$213 -> 0.63160872
A5: Consumo privado | B5: =SUM('SAM-agg'!HA71:HA198) -> 4153992 | C5: =B5/$B$12 -> 0.63827667 | E5: Transferencias gubernamentales | F5: ='SAM-agg'!HE213 -> 2275.1225 | G5: =F5/$B$12 -> 0.00034958122 | I5: Impuestos a la producción | J5: ='SAM-agg'!HG213 -> 88424 | K5: =J5/$B$12 -> 0.013586684 | M5: c-min | N5: =SUM('SAM-agg'!E$202:H$209)/SUM('SAM-agg'!B$202:BQ$209) -> 0.016352705 | O5: =SUM('SAM-agg'!CG$3:CH$70,'SAM-agg'!CJ$3:CK$70)/SUM('SAM-agg'!HV$3:HV$70) -> 0.0096691446 | P5: =SUM('SAM-agg'!E$202:H$202)/SUM('SAM-agg'!B$202:BQ$202) -> 0.0079023784 | Q5: =SUM('SAM-agg'!$HE86:$HE87,'SAM-agg'!$HE89:$HE90)/SUM('SAM-agg'!HE$71:HE$198) -> 0.089030777 | R5: =SUM('SAM-agg'!$HE86:$HE87,'SAM-agg'!$HE89:$HE90)/SUM('SAM-agg'!$CG$3:$CH$70,'SAM-agg'!$CJ$3:$CK$70) -> 0.68792937 | S5: =SUM('SAM-agg'!$CG$214:$CH$214,'SAM-agg'!$CJ$214:$CK$214)/SUM('SAM-agg'!BR$214:GO$214) -> 0.021997408 | T5: =SUM('SAM-agg'!$CG$214:$CH$214,'SAM-agg'!$CJ$214:$CK$214,'SAM-agg'!$CG$218:$CH$218,'SAM-agg'!$CJ$218:$CK$218)/(SUM('SAM-agg'!$CG$3:$CH$70,'SAM-agg'!$CJ$3:$CK$70)-SUM('SAM-agg'!HE86:HE87,'SAM-agg'!HE89:HE90)+SUM('SAM-agg'!$CG$214:$CH$214,'SAM-agg'!$CJ$214:$CK$214,'SAM-agg'!$CG$218:$CH$218,'SAM-agg'!$CJ$218:$CK$218)+SUM('SAM-agg'!CG$221:CH$221,'SAM-agg'!CJ$221:CK$221)) -> 0.33128205 | V5: a-min | W5: =SUM('SAM-agg'!$E$202:$H$202)/SUM('SAM-agg'!$E$202:$H$209) -> 0.2515577 | X5: =SUM('SAM-agg'!$E$203:$H$209)/SUM('SAM-agg'!$E$202:$H$209) -> 0.7484423 | Y5: =SUM(W5:X5) -> 1 | AA5: c-min | AB5: =SUM('SAM-agg'!B86:BQ87,'SAM-agg'!B89:BQ90)/SUM('SAM-agg'!$HV86:$HV87,'SAM-agg'!$HV89:$HV90) -> 0.47978641 | AC5: =SUM('SAM-agg'!HA86:HA87,'SAM-agg'!HA89:HA90)/SUM('SAM-agg'!$HV86:$HV87,'SAM-agg'!$HV89:$HV90) -> 0 | AD5: =SUM('SAM-agg'!HD86:HD87,'SAM-agg'!HD89:HD90)/SUM('SAM-agg'!$HV86:$HV87,'SAM-agg'!$HV89:$HV90) -> 0 | AE5: =SUM('SAM-agg'!HN86:HT87,'SAM-agg'!HN89:HT90)/SUM('SAM-agg'!$HV86:$HV87,'SAM-agg'!$HV89:$HV90) -> 0 | AF5: =SUM('SAM-agg'!HU86:HU87,'SAM-agg'!HU89:HU90)/SUM('SAM-agg'!$HV86:$HV87,'SAM-agg'!$HV89:$HV90) -> 0.018377854 | AG5: =SUM('SAM-agg'!HE86:HE87,'SAM-agg'!HE89:HE90)/SUM('SAM-agg'!$HV86:$HV87,'SAM-agg'!$HV89:$HV90) -> 0.50183573 | AH5: =SUM(AB5:AG5) -> 1 | AJ5: Transferencias de los hogares | AL5: ='SAM-agg'!HA213/'SAM-agg'!HV$213 -> 0.31011648
A6: Consumo público | B6: =SUM('SAM-agg'!HD71:HD198) -> 1343683 | C6: =B6/$B$12 -> 0.206462 | E6: Ingresos de instituciones sin fines de lucro de los hogares | F6: ='SAM-agg'!HE211 -> 4982.8775 | G6: =F6/$B$12 -> 0.00076563808 | I6: Subsidios a la producción | J6: ='SAM-agg'!HH213 -> -18588 | K6: =J6/$B$12 -> -0.0028561169 | M6: c-biofuels | N6: =SUM('SAM-agg'!U$202:U$209)/SUM('SAM-agg'!B$202:BQ$209) -> 0.0016844151 | O6: =SUM('SAM-agg'!DQ$3:DQ$70)/SUM('SAM-agg'!HV$3:HV$70) -> 0.0058308303 | P6: =SUM('SAM-agg'!U$202:U$202)/SUM('SAM-agg'!B$202:BQ$202) -> 0.0020538703 | Q6: ='SAM-agg'!$HE122/SUM('SAM-agg'!HE$71:HE$198) -> 0.0032761871 | R6: ='SAM-agg'!$HE122/SUM('SAM-agg'!$DQ$3:$DQ$70) -> 0.041978801 | S6: =SUM('SAM-agg'!$DQ$214)/SUM('SAM-agg'!BR$214:GO$214) -> 0.0041627152 | T6: =SUM('SAM-agg'!$DQ$214,'SAM-agg'!$DQ$218)/(SUM('SAM-agg'!$DQ$3:$DQ$70)-SUM('SAM-agg'!HE122)+SUM('SAM-agg'!$DQ$214,'SAM-agg'!$DQ$218+SUM('SAM-agg'!DQ$221))+SUM('SAM-agg'!DQ$221)) -> 0.044699752 | V6: a-biofuels | W6: ='SAM-agg'!$U$202/SUM('SAM-agg'!$U$202:$U$209) -> 0.63473622 | X6: =SUM('SAM-agg'!$U$203:$U$209)/SUM('SAM-agg'!$U$202:$U$209) -> 0.36526378 | Y6: =SUM(W6:X6) -> 1 | AA6: c-biofuels | AB6: =SUM('SAM-agg'!B122:BQ122)/'SAM-agg'!$HV122 -> 0.49482639 | AC6: =SUM('SAM-agg'!HA122:HA122)/'SAM-agg'!$HV122 -> 0.44418348 | AD6: =SUM('SAM-agg'!HD122:HD122)/'SAM-agg'!$HV122 -> 0 | AE6: =SUM('SAM-agg'!HN122:HT122)/'SAM-agg'!$HV122 -> 0 | AF6: =SUM('SAM-agg'!HU122:HU122)/'SAM-agg'!$HV122 -> 0.031755996 | AG6: =SUM('SAM-agg'!HE122:HE122)/'SAM-agg'!$HV122 -> 0.029234133 | AH6: =SUM(AB6:AG6) -> 1 | AJ6: Transferencias del gobierno | AK6: ='SAM-agg'!HD210/'SAM-agg'!HV$210 -> 0.24058482 | AM6: ='SAM-agg'!HD214/'SAM-agg'!HV$214 -> 0.047246542
A7: Formación bruta de capital | B7: =SUM('SAM-agg'!HS71:HT198) -> 958779 | C7: =B7/$B$12 -> 0.14732004 | E7: Ingresos de factores | F7: ='SAM-agg'!HE202 -> 1273 | G7: =F7/$B$12 -> 0.00019560129 | I7: Impuestos al consumo | J7: =SUM('SAM-agg'!HJ213:HL213) -> 881269 | K7: =J7/$B$12 -> 0.13541033 | M7: c-mnfc | N7: =SUM('SAM-agg'!I$202:T$209,'SAM-agg'!V$202:AL$209)/SUM('SAM-agg'!B$202:BQ$209) -> 0.12052624 | O7: =SUM('SAM-agg'!CI$3:CI$70,'SAM-agg'!CL$3:DP$70,'SAM-agg'!DR$3:EZ$70)/SUM('SAM-agg'!HV$3:HV$70) -> 0.27679552 | P7: =SUM('SAM-agg'!I$202:T$202,'SAM-agg'!V$202:AL$202)/SUM('SAM-agg'!B$202:BQ$202) -> 0.12878871 | Q7: =SUM('SAM-agg'!$HE88,'SAM-agg'!$HE91:$HE121,'SAM-agg'!HE123:HE157)/SUM('SAM-agg'!HE$71:HE$198) -> 0.61626886 | R7: =SUM('SAM-agg'!$HE88,'SAM-agg'!$HE91:$HE121,'SAM-agg'!HE123:HE157)/SUM('SAM-agg'!$CI$3:$CI$70,'SAM-agg'!$CL$3:$DP$70,'SAM-agg'!$DR$3:$EZ$70) -> 0.16634238 | S7: =SUM('SAM-agg'!$CI$214,'SAM-agg'!$CL$214:$DP$214,'SAM-agg'!$DR$214:$EZ$214)/SUM('SAM-agg'!BR$214:GO$214) -> 0.68037425 | T7: =SUM('SAM-agg'!$CI$214,'SAM-agg'!$CL$214:$DP$214,'SAM-agg'!$DR$214:$EZ$214,'SAM-agg'!$CI$218,'SAM-agg'!$CL$218:$DP$218,'SAM-agg'!$DR$218:$EZ$218)/(SUM('SAM-agg'!$CI$3:$CI$70,'SAM-agg'!$CL$3:$DP$70,'SAM-agg'!$DR$3:$EZ$70)-SUM('SAM-agg'!HE88,'SAM-agg'!HE91:HE121,'SAM-agg'!HE123:HE157)+SUM('SAM-agg'!$CI$214,'SAM-agg'!$CL$214:$DP$214,'SAM-agg'!$DR$214:$EZ$214,'SAM-agg'!$CI$218,'SAM-agg'!$CL$218:$DP$218,'SAM-agg'!$DR$218:$EZ$218)+SUM('SAM-agg'!CI$221,'SAM-agg'!CL$221:DP$221,'SAM-agg'!DR$221:EZ$221)) -> 0.17204558 | V7: a-mnfc | W7: =SUM('SAM-agg'!$I$202:$T$202,'SAM-agg'!$V$202:$AL$202)/SUM('SAM-agg'!$I$202:$T$209,'SAM-agg'!$V$202:$AL$209) -> 0.55624432 | X7: =SUM('SAM-agg'!$I$203:$T$209,'SAM-agg'!$V$203:$AL$209)/SUM('SAM-agg'!$I$202:$T$209,'SAM-agg'!$V$202:$AL$209) -> 0.44375568 | Y7: =SUM(W7:X7) -> 1 | AA7: c-mnfc | AB7: =SUM('SAM-agg'!B88:BQ88,'SAM-agg'!B90:BQ121,'SAM-agg'!B123:BQ157)/SUM('SAM-agg'!$HV88,'SAM-agg'!$HV90:$HV121,'SAM-agg'!$HV123:$HV157) -> 0.48184241 | AC7: =SUM('SAM-agg'!HA88:HA88,'SAM-agg'!HA90:HA121,'SAM-agg'!HA123:HA157)/SUM('SAM-agg'!$HV88,'SAM-agg'!$HV90:$HV121,'SAM-agg'!$HV123:$HV157) -> 0.34652661 | AD7: =SUM('SAM-agg'!HD88:HD88,'SAM-agg'!HD90:HD121,'SAM-agg'!HD123:HD157)/SUM('SAM-agg'!$HV88,'SAM-agg'!$HV90:$HV121,'SAM-agg'!$HV123:$HV157) -> 0.0048149633 | AE7: =SUM('SAM-agg'!HN88:HT88,'SAM-agg'!HN90:HT121,'SAM-agg'!HN123:HT157)/SUM('SAM-agg'!$HV88,'SAM-agg'!$HV90:$HV121,'SAM-agg'!$HV123:$HV157) -> 0.067663081 | AF7: =SUM('SAM-agg'!HU88:HU88,'SAM-agg'!HU90:HU121,'SAM-agg'!HU123:HU157)/SUM('SAM-agg'!$HV88,'SAM-agg'!$HV90:$HV121,'SAM-agg'!$HV123:$HV157) -> -0.002181652 | AG7: =SUM('SAM-agg'!HE88:HE88,'SAM-agg'!HE90:HE121,'SAM-agg'!HE123:HE157)/SUM('SAM-agg'!$HV88,'SAM-agg'!$HV90:$HV121,'SAM-agg'!$HV123:$HV157) -> 0.10133459 | AH7: =SUM(AB7:AG7) -> 1 | AJ7: Transferencias del resto del mundo | AL7: ='SAM-agg'!HE213/'SAM-agg'!HV$213 -> 0.00094345719
A8: Variación de existencias | B8: =SUM('SAM-agg'!HU71:HU198) -> 4386 | C8: =B8/$B$12 -> 0.00067392558 | E8: Ahorro del resto del mundo | F8: =SUM('SAM-agg'!HE223:HE229) -> 68561 | G8: =F8/$B$12 -> 0.010534658 | I8: Impuestos a las importaciones | J8: ='SAM-agg'!HI213 -> 32284 | K8: =J8/$B$12 -> 0.0049605594 | M8: c-othind | N8: =SUM('SAM-agg'!AM$202:AO$209)/SUM('SAM-agg'!B$202:BQ$209) -> 0.072904521 | O8: =SUM('SAM-agg'!FA$3:FE$70)/SUM('SAM-agg'!HV$3:HV$70) -> 0.083731257 | P8: =SUM('SAM-agg'!AM$202:AO$202)/SUM('SAM-agg'!B$202:BQ$202) -> 0.059842633 | Q8: =SUM('SAM-agg'!$HE158:$HE162)/SUM('SAM-agg'!HE$71:HE$198) -> 0.0034193156 | R8: =SUM('SAM-agg'!$HE158:$HE162)/SUM('SAM-agg'!$FA$3:$FE$70) -> 0.0030510078 | S8: =SUM('SAM-agg'!$FA$214:$FE$214)/SUM('SAM-agg'!BR$214:GO$214) -> 0.0093355483 | T8: =SUM('SAM-agg'!$FA$214:$FE$214,'SAM-agg'!$FA$218:$FE$218)/(SUM('SAM-agg'!$FA$3:$FE$70)-SUM('SAM-agg'!HE158:HE162)+SUM('SAM-agg'!$FA$214:$FE$214,'SAM-agg'!$FA$218:$FE$218)+SUM('SAM-agg'!FA$221:FE$221)) -> 0.0074848601 | V8: a-othind | W8: =SUM('SAM-agg'!$AM$202:$AO$202)/SUM('SAM-agg'!$AM$202:$AO$209) -> 0.42729285 | X8: =SUM('SAM-agg'!$AM$203:$AO$209)/SUM('SAM-agg'!$AM$202:$AO$209) -> 0.57270715 | Y8: =SUM(W8:X8) -> 1 | AA8: c-othind | AB8: =SUM('SAM-agg'!B158:BQ162)/SUM('SAM-agg'!$HV158:$HV162) -> 0.39537652 | AC8: =SUM('SAM-agg'!HA158:HA162)/SUM('SAM-agg'!$HV158:$HV162) -> 0.14011371 | AD8: =SUM('SAM-agg'!HD158:HD162)/SUM('SAM-agg'!$HV158:$HV162) -> 0 | AE8: =SUM('SAM-agg'!HN158:HT162)/SUM('SAM-agg'!$HV158:$HV162) -> 0.46132848 | AF8: =SUM('SAM-agg'!HU158:HU162)/SUM('SAM-agg'!$HV158:$HV162) -> 0.00042612706 | AG8: =SUM('SAM-agg'!HE158:HE162)/SUM('SAM-agg'!$HV158:$HV162) -> 0.0027551656 | AH8: =SUM(AB8:AG8) -> 1 | AJ8: Importaciones | AM8: =SUM('SAM-agg'!BR214:GO214)/'SAM-agg'!HV$214 -> 0.86202395
A9: Cuenta Comercial | B9: =B10-B11 -> 47297 | C9: =B9/$B$12 -> 0.0072673639 | E9: Total Entradas | F9: =SUM(F4:F8) -> 901526 | G9: =F9/$B$12 -> 0.1385229 | I9: Transferencias de los hogares | J9: ='SAM-agg'!HA213 -> 747837.83 | K9: =J9/$B$12 -> 0.11490813 | M9: c-svc | N9: =SUM('SAM-agg'!AP$202:BQ$209)/SUM('SAM-agg'!B$202:BQ$209) -> 0.72811783 | O9: =SUM('SAM-agg'!FF$3:GO$70)/SUM('SAM-agg'!HV$3:HV$70) -> 0.57632613 | P9: =SUM('SAM-agg'!AP$202:BQ$202)/SUM('SAM-agg'!B$202:BQ$202) -> 0.76252102 | Q9: =SUM('SAM-agg'!$HE163:$HE198)/SUM('SAM-agg'!HE$71:HE$198) -> 0.13465238 | R9: =SUM('SAM-agg'!$HE163:$HE198)/SUM('SAM-agg'!$FF$3:$GO$70) -> 0.017455708 | S9: =SUM('SAM-agg'!$FF$214:$GO$214)/SUM('SAM-agg'!BR$214:GO$214) -> 0.26609851 | T9: =SUM('SAM-agg'!$FF$214:$GO$214,'SAM-agg'!$FF$218:$GO$218)/(SUM('SAM-agg'!$FF$3:$GO$70)-SUM('SAM-agg'!HE163:HE198)+SUM('SAM-agg'!$FF$214:$GO$214,'SAM-agg'!$FF$218:$GO$218)+SUM('SAM-agg'!FF$221:GO$221)) -> 0.031140623 | V9: a-svc | W9: =SUM('SAM-agg'!$AP$202:$BQ$202)/SUM('SAM-agg'!$AP$202:$BQ$209) -> 0.54515443 | X9: =SUM('SAM-agg'!$AP$203:$BQ$209)/SUM('SAM-agg'!$AP$202:$BQ$209) -> 0.45484557 | Y9: =SUM(W9:X9) -> 1 | AA9: c-svc | AB9: =(SUM('SAM-agg'!B163:BQ198)+SUM('SAM-agg'!GP163:GR198))/SUM('SAM-agg'!$HV163:$HV198) -> 0.46135058 | AC9: =(SUM('SAM-agg'!HA163:HA198)+SUM('SAM-agg'!HB163:HB198))/SUM('SAM-agg'!$HV163:$HV198) -> 0.31148032 | AD9: =SUM('SAM-agg'!HD163:HD198)/SUM('SAM-agg'!$HV163:$HV198) -> 0.19296487 | AE9: =SUM('SAM-agg'!HN163:HT198)/SUM('SAM-agg'!$HV163:$HV198) -> 0.017947846 | AF9: =SUM('SAM-agg'!HU163:HU198)/SUM('SAM-agg'!$HV163:$HV198) -> 1.5799933e-05 | AG9: =SUM('SAM-agg'!HE163:HE198)/SUM('SAM-agg'!$HV163:$HV198) -> 0.016240576 | AH9: =SUM(AB9:AG9) -> 1 | AJ9: Ingresos de trabajo | AK9: ='SAM-agg'!GS210/'SAM-agg'!HV$210 -> 0.44962115 | AM9: ='SAM-agg'!GS214/'SAM-agg'!HV$214 -> 0.00040486908
A10: Exportaciones | B10: =SUM('SAM-agg'!HE71:HE198) -> 824434 | C10: =B10/$B$12 -> 0.12667742 | E10: Importaciones | F10: =SUM('SAM-agg'!BR214:GO214) -> 777137 | G10: =F10/$B$12 -> 0.11941006 | I10: Transferencias del resto del mundo | J10: ='SAM-agg'!HE213 -> 2275.1225 | K10: =J10/$B$12 -> 0.00034958122 | M10: Total | N10: =SUM(N4:N9) -> 1 | O10: =SUM(O4:O9) -> 1 | P10: =SUM(P4:P9) -> 1 | Q10: =SUM(Q4:Q9) -> 1 | R10: =SUM('SAM-agg'!$HE71:$HE198)/SUM('SAM-agg'!BR3:GO70) -> 0.074712237 | S10: =SUM(S4:S9) -> 1 | T10: =SUM('SAM-agg'!BR214:GO214,'SAM-agg'!BR218:GO218)/(SUM('SAM-agg'!BR3:GO70)-SUM('SAM-agg'!HE71:HE198)+SUM('SAM-agg'!BR214:GO214,'SAM-agg'!BR218:GO218)+SUM('SAM-agg'!BR221:GO221)) -> 0.070949856 | V10: Total | W10: =SUM('SAM-agg'!$B202:$BQ202)/SUM('SAM-agg'!$B$202:$BQ$209) -> 0.52055832 | X10: =SUM('SAM-agg'!$B203:$BQ209)/SUM('SAM-agg'!$B$202:$BQ$209) -> 0.47944168 | Y10: =SUM(W10:X10) -> 1 | AA10: Total | AB10: =(SUM('SAM-agg'!B71:BQ198)+SUM('SAM-agg'!GP71:GR198))/SUM('SAM-agg'!$HV71:$HV198) -> 0.46669935 | AC10: =(SUM('SAM-agg'!HA71:HA198)+SUM('SAM-agg'!HB71:HB198))/SUM('SAM-agg'!$HV71:$HV198) -> 0.30691393 | AD10: =SUM('SAM-agg'!HD71:HD198)/SUM('SAM-agg'!$HV71:$HV198) -> 0.09714615 | AE10: =SUM('SAM-agg'!HN71:HT198)/SUM('SAM-agg'!$HV71:$HV198) -> 0.069318201 | AF10: =SUM('SAM-agg'!HU71:HU198)/SUM('SAM-agg'!$HV71:$HV198) -> 0.00031710085 | AG10: =SUM('SAM-agg'!HE71:HE198)/SUM('SAM-agg'!$HV71:$HV198) -> 0.059605271 | AH10: =SUM(AB10:AG10) -> 1 | AJ10: Ingresos de capital | AK10: =SUM('SAM-agg'!GT210:GZ210)/'SAM-agg'!HV$210 -> 0.1312105 | AL10: =SUM('SAM-agg'!GT213:GZ213)/'SAM-agg'!HV$213 -> 0.049369805
A11: Importaciones | B11: =SUM('SAM-agg'!BR214:GO214) -> 777137 | C11: =B11/$B$12 -> 0.11941006 | E11: Transferencias gubernamentales | F11: ='SAM-agg'!HD214 -> 42593.986 | G11: =F11/$B$12 -> 0.006544728 | I11: Ingresos de factores | J11: =SUM('SAM-agg'!GT213:GZ213) -> 119054 | K11: =J11/$B$12 -> 0.0182931 | AJ11: Ingresos de empresas | AK11: ='SAM-agg'!HC210/'SAM-agg'!HV$210 -> 0.073720194 | AL11: ='SAM-agg'!HC213/'SAM-agg'!HV$213 -> 0.0079615412 | AM11: ='SAM-agg'!HC214/'SAM-agg'!HV$214 -> 0.090324643
A12: PBI (a precio de mercado) | B12: =B4+B9 -> 6508137 | C12: =B12/$B$12 -> 1 | E12: Egresos de factores | F12: ='SAM-agg'!GS214 -> 365 | G12: =F12/$B$12 -> 5.6083638e-05 | I12: Ingresos de empresas | J12: ='SAM-agg'!HC213 -> 19199.05 | K12: =J12/$B$12 -> 0.002950007 | AJ12: Ingresos de jubilaciones | AK12: ='SAM-agg'!HF210/'SAM-agg'!HV$210 -> 0.10486334
A13: Impuestos indirectos netos | B13: =SUM('SAM-agg'!HV216:HV221) -> 983389 | C13: =B13/$B$12 -> 0.15110146 | E13: Egresos de empresas | F13: ='SAM-agg'!HC214 -> 81430.014 | G13: =F13/$B$12 -> 0.012512031 | I13: Total Ingresos | J13: =SUM(J4:J12) -> 2411474 | K13: =J13/$B$12 -> 0.37053215 | AJ13: Total | AK13: =SUM(AK4:AK12) -> 1 | AL13: =SUM(AL4:AL12) -> 1 | AM13: =SUM(AM4:AM12) -> 1
A14: PBI (a costo de factores) | B14: =B12-B13 -> 5524748 | C14: =B14/$B$12 -> 0.84889854 | E14: Total Salidas | F14: =SUM(F10:F13) -> 901526 | G14: =F14/$B$12 -> 0.1385229 | I14: Consumo público | J14: =SUM('SAM-agg'!HD71:HD198) -> 1343683 | K14: =J14/$B$12 -> 0.206462
I15: Transferencias a los hogares | J15: ='SAM-agg'!HD210 -> 1395333.7 | K15: =J15/$B$12 -> 0.21439833
I16: Transferencias al resto del mundo | J16: ='SAM-agg'!HD214 -> 42593.986 | K16: =J16/$B$12 -> 0.006544728
I17: Egresos de instituciones sin fines de lucro de los hogares | J17: ='SAM-agg'!HD211 -> 2492.2963 | K17: =J17/$B$12 -> 0.00038295081
I18: Ahorro del gobierno | J18: ='SAM-agg'!HD226 -> -372629 | K18: =J18/$B$12 -> -0.057255863
I19: Total Egresos | J19: =SUM(J14:J18) -> 2411474 | K19: =J19/$B$12 -> 0.37053215
